{
 "cells": [
  {
   "cell_type": "code",
   "execution_count": 1,
   "metadata": {},
   "outputs": [],
   "source": [
    "import os\n",
    "os.chdir('/rds/general/user/cb1319/home/GEOM3D/Geom3D/')"
   ]
  },
  {
   "cell_type": "code",
   "execution_count": 2,
   "metadata": {},
   "outputs": [
    {
     "name": "stdout",
     "output_type": "stream",
     "text": [
      "config loaded from /rds/general/user/cb1319/home/GEOM3D/Geom3D/training/DimeNetPlusPlus_target_1K_TEST_5e4lr/\n"
     ]
    }
   ],
   "source": [
    "from geom3d.train_DimeNet import *\n",
    "import torch\n",
    "import copy\n",
    "\n",
    "config_dir = os.getcwd()+\"/training/DimeNetPlusPlus_target_1K_TEST_5e4lr/\"\n",
    "config = read_config(config_dir)"
   ]
  },
  {
   "cell_type": "code",
   "execution_count": 3,
   "metadata": {},
   "outputs": [
    {
     "name": "stdout",
     "output_type": "stream",
     "text": [
      "GPU (Quadro RTX 6000) is available.\n"
     ]
    }
   ],
   "source": [
    "# Check if GPU is available\n",
    "if torch.cuda.is_available():\n",
    "    # Get the name of the GPU\n",
    "    gpu_name = torch.cuda.get_device_name(0)  # Assuming you have one GPU; you can change the index if you have multiple GPUs\n",
    "    print(f\"GPU ({gpu_name}) is available.\")\n",
    "else:\n",
    "    print(\"No GPU available. Using CPU.\")"
   ]
  },
  {
   "cell_type": "code",
   "execution_count": 4,
   "metadata": {},
<<<<<<< Updated upstream
   "outputs": [
    {
     "name": "stdout",
     "output_type": "stream",
     "text": [
      "length of dataset: 80000\n"
     ]
    }
   ],
=======
   "outputs": [],
>>>>>>> Stashed changes
   "source": [
    "import importlib\n",
    "from geom3d import train_DimeNet\n",
    "\n",
    "importlib.reload(train_DimeNet)\n",
    "\n",
    "config[\"device\"] = \"cuda:0\" if torch.cuda.is_available() else \"cpu\"\n",
    "    \n",
    "np.random.seed(config[\"seed\"])\n",
    "torch.cuda.manual_seed_all(config[\"seed\"])\n",
<<<<<<< Updated upstream
    "dataset = train_DimeNet.load_data(config)\n",
    "print(f\"length of dataset: {len(dataset)}\")\n"
=======
    "# dataset = train_DimeNet.load_data(config)\n",
    "# print(f\"length of dataset: {len(dataset)}\")\n"
>>>>>>> Stashed changes
   ]
  },
  {
   "cell_type": "code",
   "execution_count": 5,
   "metadata": {},
   "outputs": [
    {
     "name": "stderr",
     "output_type": "stream",
     "text": [
      "Failed to detect the name of this notebook, you can set it manually with the WANDB_NOTEBOOK_NAME environment variable to enable code saving.\n",
      "\u001b[34m\u001b[1mwandb\u001b[0m: Currently logged in as: \u001b[33mcyprienbone\u001b[0m. Use \u001b[1m`wandb login --relogin`\u001b[0m to force relogin\n"
     ]
    },
    {
     "data": {
      "text/plain": [
       "True"
      ]
     },
     "execution_count": 5,
     "metadata": {},
     "output_type": "execute_result"
    }
   ],
   "source": [
    "import wandb\n",
    "wandb.login()"
   ]
  },
  {
   "cell_type": "code",
   "execution_count": 6,
   "metadata": {},
   "outputs": [],
   "source": [
<<<<<<< Updated upstream
    "# stop wandb run\n",
=======
>>>>>>> Stashed changes
    "wandb.finish()"
   ]
  },
  {
   "cell_type": "code",
   "execution_count": 7,
   "metadata": {},
   "outputs": [
    {
     "name": "stdout",
     "output_type": "stream",
     "text": [
<<<<<<< Updated upstream
      "/bin/bash: which: line 1: syntax error: unexpected end of file\n",
      "/bin/bash: error importing function definition for `which'\n",
      "/bin/bash: module: line 1: syntax error: unexpected end of file\n",
      "/bin/bash: error importing function definition for `module'\n",
      "/bin/bash: scl: line 1: syntax error: unexpected end of file\n",
      "/bin/bash: error importing function definition for `scl'\n",
      "/bin/bash: ml: line 1: syntax error: unexpected end of file\n",
      "/bin/bash: error importing function definition for `ml'\n",
      "Tue Nov 28 17:11:02 2023       \n",
      "+---------------------------------------------------------------------------------------+\n",
      "| NVIDIA-SMI 535.54.03              Driver Version: 535.54.03    CUDA Version: 12.2     |\n",
      "|-----------------------------------------+----------------------+----------------------+\n",
      "| GPU  Name                 Persistence-M | Bus-Id        Disp.A | Volatile Uncorr. ECC |\n",
      "| Fan  Temp   Perf          Pwr:Usage/Cap |         Memory-Usage | GPU-Util  Compute M. |\n",
      "|                                         |                      |               MIG M. |\n",
      "|=========================================+======================+======================|\n",
      "|   0  Quadro RTX 6000                On  | 00000000:1B:00.0 Off |                  Off |\n",
      "| 33%   37C    P8              27W / 260W |   9715MiB / 24576MiB |      0%   E. Process |\n",
      "|                                         |                      |                  N/A |\n",
      "+-----------------------------------------+----------------------+----------------------+\n",
      "|   1  Quadro RTX 6000                On  | 00000000:1C:00.0 Off |                  Off |\n",
      "| 33%   36C    P8              19W / 260W |      1MiB / 24576MiB |      0%   E. Process |\n",
      "|                                         |                      |                  N/A |\n",
      "+-----------------------------------------+----------------------+----------------------+\n",
      "|   2  Quadro RTX 6000                On  | 00000000:1D:00.0 Off |                  Off |\n",
      "| 34%   37C    P8              27W / 260W |      1MiB / 24576MiB |      0%   E. Process |\n",
      "|                                         |                      |                  N/A |\n",
      "+-----------------------------------------+----------------------+----------------------+\n",
      "|   3  Quadro RTX 6000                On  | 00000000:1E:00.0 Off |                  Off |\n",
      "| 33%   36C    P8              32W / 260W |      3MiB / 24576MiB |      0%   E. Process |\n",
      "|                                         |                      |                  N/A |\n",
      "+-----------------------------------------+----------------------+----------------------+\n",
      "|   4  Quadro RTX 6000                On  | 00000000:89:00.0 Off |                  Off |\n",
      "| 33%   34C    P8              21W / 260W |    509MiB / 24576MiB |      0%   E. Process |\n",
      "|                                         |                      |                  N/A |\n",
      "+-----------------------------------------+----------------------+----------------------+\n",
      "|   5  Quadro RTX 6000                On  | 00000000:8A:00.0 Off |                  Off |\n",
      "| 34%   36C    P8              23W / 260W |    841MiB / 24576MiB |      0%   E. Process |\n",
      "|                                         |                      |                  N/A |\n",
      "+-----------------------------------------+----------------------+----------------------+\n",
      "|   6  Quadro RTX 6000                On  | 00000000:8B:00.0 Off |                  Off |\n",
      "| 34%   36C    P8              31W / 260W |    221MiB / 24576MiB |      0%   E. Process |\n",
      "|                                         |                      |                  N/A |\n",
      "+-----------------------------------------+----------------------+----------------------+\n",
      "|   7  Quadro RTX 6000                On  | 00000000:8C:00.0 Off |                  Off |\n",
      "| 33%   36C    P8              23W / 260W |      1MiB / 24576MiB |      0%   E. Process |\n",
      "|                                         |                      |                  N/A |\n",
      "+-----------------------------------------+----------------------+----------------------+\n",
      "                                                                                         \n",
      "+---------------------------------------------------------------------------------------+\n",
      "| Processes:                                                                            |\n",
      "|  GPU   GI   CI        PID   Type   Process name                            GPU Memory |\n",
      "|        ID   ID                                                             Usage      |\n",
      "|=======================================================================================|\n",
      "|    0   N/A  N/A   3404748      C   ...home/anaconda3/envs/pips/bin/python     9712MiB |\n",
      "|    4   N/A  N/A   3413922      C   ...me/anaconda3/envs/Geom3D/bin/python      506MiB |\n",
      "|    5   N/A  N/A   3417483      C   ...e/anaconda3/envs/deepimu/bin/python      838MiB |\n",
      "|    6   N/A  N/A   3431125      C   python                                      218MiB |\n",
      "+---------------------------------------------------------------------------------------+\n"
     ]
    }
   ],
   "source": [
    "# free cuda memory\n",
    "torch.cuda.empty_cache()\n",
    "\n",
    "# stop ongoing processes\n",
    "\n",
    "!nvidia-smi"
   ]
  },
  {
   "cell_type": "code",
   "execution_count": 8,
   "metadata": {},
   "outputs": [
    {
     "name": "stdout",
     "output_type": "stream",
     "text": [
      "config loaded from /rds/general/user/cb1319/home/GEOM3D/Geom3D/training/DimeNetPlusPlus_target_1K_TEST_5e4lr/\n",
      "train_idx:  [47044 44295 74783 ... 77925 18116 14762]\n",
      "valid_idx:  [39698 66692  7139 ... 52300 56176  3346]\n",
      "test_idx:  [61260 28261 49228 ... 76820   860 15795]\n",
      "Value of self.graph_pred_linear: None\n"
=======
      "config loaded from /rds/general/user/cb1319/home/GEOM3D/Geom3D/training/DimeNetPlusPlus_target_1K_TEST_5e4lr/\n",
      "train_idx:  [361  73 374 155 104 394 377 124  68 450   9 194 406  84 371 388 495  30\n",
      " 316 408 490 491 280 356  76 461 497 211 101 334 475 336 440 173   2 333\n",
      " 409  70 209  63 384  93 485 185  33  77   0  11 415  22  72 182 131 410\n",
      " 193  55 148  18 204  78 494 262 323 483  79  39 451  46 238 391 352 341\n",
      " 277 290 317 304 268  69 455 465 154  82 477 172 321  90 180 414 312 278\n",
      " 381 472 362 324 431 347  86  75 438  15 249 433  19 322 332  56 301 229\n",
      " 331 132 137 423 335  25 464 281 247 237 117  42 220 176 320 153 231 227\n",
      " 417 203 126 329  31 113 470 271 140  57 192  24  17 265  66 208 479  94\n",
      " 253 266  23 222 261 426   5 116  45  16 462 357   3 218 405  60 110 318\n",
      " 428  29 437 471  26   7 453 108  37 157 489 118 114 175 373 181 144 369\n",
      " 390 195 404 275 454 141 365  67 210 168 493 375 400 272 109 248 145  92\n",
      " 152 367 467  83 245 165 163 199 228  74 478 358 250 119 310 299 255 354\n",
      " 399 225 353 234 382 274  36 196 139 364 244 439 286  59 111  89 436   6\n",
      " 360 346 338 158 150 177 393 184 449  10 380 103  81  38 314 167 469 296\n",
      " 474 198 297 416 146 392 147 447 287 123 368  96 143 239 442  97 407 122\n",
      " 183 202 246 305 298 351 386 395 284 125 302 223 418 219 129 420 289 444\n",
      " 376 291 355 294 396 340 112 179 307 432 487 481 422 233 311 164 136 197\n",
      " 258 232 115 120 349 224 402 397 127 285 411 107 370 325 133 452  44 460\n",
      "  65 283  85 242 186 383 159  12  35  28 170 142 398 342 221  95  51 240\n",
      " 484 378 178  41 498 421 206 282 254 412   4 256 448 100 226 429 213 171\n",
      "  98 292 215  61  47  32 267 327 200 446  27 424 230 260 288 162 425 138\n",
      "  62 135 128 476   8 326 463  64 300  14 156  40 379 468 403 216 279 434\n",
      " 430 337 236 207]\n",
      "valid_idx:  [212 295 457 251 488 486 303 350 269 201 161  43 217 401 190 309 259 105\n",
      "  53 389   1 441 482  49 419  80 205  34 263 427 366  91 339 473  52 345\n",
      " 264 241  13 315  88 387 273 166 328 492 134 306 480 319]\n",
      "test_idx:  [243  54 363  50 456 174 445 189 496 187 169  58  48 344 235 252  21 313\n",
      " 459 160 276 443 191 385 293 413 343 257 308 149 130 151 359  99 372  87\n",
      " 458 330 214 466 121 499  20 188  71 106 270 348 435 102]\n"
>>>>>>> Stashed changes
     ]
    },
    {
     "data": {
      "text/html": [
       "Tracking run with wandb version 0.16.0"
      ],
      "text/plain": [
       "<IPython.core.display.HTML object>"
      ]
     },
     "metadata": {},
     "output_type": "display_data"
    },
    {
     "data": {
      "text/html": [
<<<<<<< Updated upstream
       "Run data is saved locally in <code>./wandb/run-20231128_171133-8mm92vbe</code>"
=======
       "Run data is saved locally in <code>/rds/general/user/cb1319/home/GEOM3D/Geom3D/training/wandb/run-20231130_140252-0d1v8caw</code>"
>>>>>>> Stashed changes
      ],
      "text/plain": [
       "<IPython.core.display.HTML object>"
      ]
     },
     "metadata": {},
     "output_type": "display_data"
    },
    {
     "data": {
      "text/html": [
<<<<<<< Updated upstream
       "Syncing run <strong><a href='https://wandb.ai/cyprienbone/Geom3D/runs/8mm92vbe' target=\"_blank\">DimeNetPlusPlus_target_1K_TEST_5e4lr</a></strong> to <a href='https://wandb.ai/cyprienbone/Geom3D' target=\"_blank\">Weights & Biases</a> (<a href='https://wandb.me/run' target=\"_blank\">docs</a>)<br/>"
=======
       "Syncing run <strong><a href='https://wandb.ai/cyprienbone/Geom3D/runs/0d1v8caw' target=\"_blank\">leafy-tree-15</a></strong> to <a href='https://wandb.ai/cyprienbone/Geom3D' target=\"_blank\">Weights & Biases</a> (<a href='https://wandb.me/run' target=\"_blank\">docs</a>)<br/>"
>>>>>>> Stashed changes
      ],
      "text/plain": [
       "<IPython.core.display.HTML object>"
      ]
     },
     "metadata": {},
     "output_type": "display_data"
    },
    {
     "data": {
      "text/html": [
       " View project at <a href='https://wandb.ai/cyprienbone/Geom3D' target=\"_blank\">https://wandb.ai/cyprienbone/Geom3D</a>"
      ],
      "text/plain": [
       "<IPython.core.display.HTML object>"
      ]
     },
     "metadata": {},
     "output_type": "display_data"
    },
    {
     "data": {
      "text/html": [
<<<<<<< Updated upstream
       " View run at <a href='https://wandb.ai/cyprienbone/Geom3D/runs/8mm92vbe' target=\"_blank\">https://wandb.ai/cyprienbone/Geom3D/runs/8mm92vbe</a>"
=======
       " View run at <a href='https://wandb.ai/cyprienbone/Geom3D/runs/0d1v8caw' target=\"_blank\">https://wandb.ai/cyprienbone/Geom3D/runs/0d1v8caw</a>"
>>>>>>> Stashed changes
      ],
      "text/plain": [
       "<IPython.core.display.HTML object>"
      ]
     },
     "metadata": {},
     "output_type": "display_data"
    },
    {
<<<<<<< Updated upstream
     "name": "stderr",
     "output_type": "stream",
     "text": [
=======
     "name": "stdout",
     "output_type": "stream",
     "text": [
      "Value of self.graph_pred_linear: None\n"
     ]
    },
    {
     "name": "stderr",
     "output_type": "stream",
     "text": [
      "/rds/general/user/cb1319/home/anaconda3/envs/Geom3D/lib/python3.11/site-packages/lightning/pytorch/loggers/wandb.py:389: There is a wandb run already in progress and newly created instances of `WandbLogger` will reuse this run. If this is not desired, call `wandb.finish()` before instantiating `WandbLogger`.\n",
>>>>>>> Stashed changes
      "GPU available: True (cuda), used: True\n",
      "TPU available: False, using: 0 TPU cores\n",
      "IPU available: False, using: 0 IPUs\n",
      "HPU available: False, using: 0 HPUs\n",
      "`Trainer(val_check_interval=1.0)` was configured so validation will run at the end of the training epoch..\n",
<<<<<<< Updated upstream
      "LOCAL_RANK: 0 - CUDA_VISIBLE_DEVICES: [3]\n",
=======
      "/rds/general/user/cb1319/home/anaconda3/envs/Geom3D/lib/python3.11/site-packages/lightning/pytorch/callbacks/model_checkpoint.py:634: Checkpoint directory /rds/general/user/cb1319/home/GEOM3D/Geom3D/training/DimeNetPlusPlus_target_1K_TEST_5e4lr exists and is not empty.\n",
      "LOCAL_RANK: 0 - CUDA_VISIBLE_DEVICES: [1]\n",
>>>>>>> Stashed changes
      "\n",
      "  | Name             | Type            | Params\n",
      "-----------------------------------------------------\n",
      "0 | molecule_3D_repr | DimeNetPlusPlus | 328 K \n",
      "-----------------------------------------------------\n",
      "328 K     Trainable params\n",
      "6         Non-trainable params\n",
      "328 K     Total params\n",
      "1.316     Total estimated model params size (MB)\n"
     ]
    },
    {
     "data": {
      "application/vnd.jupyter.widget-view+json": {
<<<<<<< Updated upstream
       "model_id": "c1559dd71bac4effa2938a8cde5ce734",
=======
       "model_id": "f256385c63f4428b91ca0bbd9621a90a",
>>>>>>> Stashed changes
       "version_major": 2,
       "version_minor": 0
      },
      "text/plain": [
       "Sanity Checking: |          | 0/? [00:00<?, ?it/s]"
      ]
     },
     "metadata": {},
     "output_type": "display_data"
    },
    {
     "name": "stderr",
     "output_type": "stream",
     "text": [
      "/rds/general/user/cb1319/home/anaconda3/envs/Geom3D/lib/python3.11/site-packages/lightning/pytorch/trainer/connectors/data_connector.py:492: Your `val_dataloader`'s sampler has shuffling enabled, it is strongly recommended that you turn shuffling off for val/test dataloaders.\n",
      "/rds/general/user/cb1319/home/anaconda3/envs/Geom3D/lib/python3.11/site-packages/lightning/pytorch/trainer/connectors/data_connector.py:441: The 'val_dataloader' does not have many workers which may be a bottleneck. Consider increasing the value of the `num_workers` argument` to `num_workers=31` in the `DataLoader` to improve performance.\n",
<<<<<<< Updated upstream
      "/rds/general/user/cb1319/home/anaconda3/envs/Geom3D/lib/python3.11/site-packages/lightning/pytorch/utilities/data.py:77: Trying to infer the `batch_size` from an ambiguous collection. The batch size we found is 7741. To avoid any miscalculations, use `self.log(..., batch_size=batch_size)`.\n",
      "/rds/general/user/cb1319/home/anaconda3/envs/Geom3D/lib/python3.11/site-packages/lightning/pytorch/utilities/data.py:77: Trying to infer the `batch_size` from an ambiguous collection. The batch size we found is 7573. To avoid any miscalculations, use `self.log(..., batch_size=batch_size)`.\n",
=======
      "/rds/general/user/cb1319/home/anaconda3/envs/Geom3D/lib/python3.11/site-packages/lightning/pytorch/utilities/data.py:77: Trying to infer the `batch_size` from an ambiguous collection. The batch size we found is 6223. To avoid any miscalculations, use `self.log(..., batch_size=batch_size)`.\n",
>>>>>>> Stashed changes
      "/rds/general/user/cb1319/home/anaconda3/envs/Geom3D/lib/python3.11/site-packages/lightning/pytorch/trainer/connectors/data_connector.py:441: The 'train_dataloader' does not have many workers which may be a bottleneck. Consider increasing the value of the `num_workers` argument` to `num_workers=31` in the `DataLoader` to improve performance.\n"
     ]
    },
    {
     "data": {
      "application/vnd.jupyter.widget-view+json": {
<<<<<<< Updated upstream
       "model_id": "5961f3d5fc504d00b037101aad721280",
=======
       "model_id": "2d7a29f12b1047c29d8502b8d536d0b0",
>>>>>>> Stashed changes
       "version_major": 2,
       "version_minor": 0
      },
      "text/plain": [
       "Training: |          | 0/? [00:00<?, ?it/s]"
      ]
     },
     "metadata": {},
     "output_type": "display_data"
    },
    {
     "data": {
      "application/vnd.jupyter.widget-view+json": {
<<<<<<< Updated upstream
       "model_id": "853c4ae2fed54291b6d64a89fa811c87",
=======
       "model_id": "b4865c7929d04116a65b4e4864eda816",
       "version_major": 2,
       "version_minor": 0
      },
      "text/plain": [
       "Validation: |          | 0/? [00:00<?, ?it/s]"
      ]
     },
     "metadata": {},
     "output_type": "display_data"
    },
    {
     "data": {
      "application/vnd.jupyter.widget-view+json": {
       "model_id": "26d838ddbdc74598940ab7ea3d7c33b3",
       "version_major": 2,
       "version_minor": 0
      },
      "text/plain": [
       "Validation: |          | 0/? [00:00<?, ?it/s]"
      ]
     },
     "metadata": {},
     "output_type": "display_data"
    },
    {
     "data": {
      "application/vnd.jupyter.widget-view+json": {
       "model_id": "a736ab7223244fbd89b690b9159d4ca6",
       "version_major": 2,
       "version_minor": 0
      },
      "text/plain": [
       "Validation: |          | 0/? [00:00<?, ?it/s]"
      ]
     },
     "metadata": {},
     "output_type": "display_data"
    },
    {
     "data": {
      "application/vnd.jupyter.widget-view+json": {
       "model_id": "90a4d1f90c0b491c97bbbb66c9f7cf5c",
       "version_major": 2,
       "version_minor": 0
      },
      "text/plain": [
       "Validation: |          | 0/? [00:00<?, ?it/s]"
      ]
     },
     "metadata": {},
     "output_type": "display_data"
    },
    {
     "data": {
      "application/vnd.jupyter.widget-view+json": {
       "model_id": "d927f52054ad4305a03552cc96902aae",
>>>>>>> Stashed changes
       "version_major": 2,
       "version_minor": 0
      },
      "text/plain": [
       "Validation: |          | 0/? [00:00<?, ?it/s]"
      ]
     },
     "metadata": {},
     "output_type": "display_data"
    },
    {
     "name": "stderr",
     "output_type": "stream",
     "text": [
<<<<<<< Updated upstream
      "/rds/general/user/cb1319/home/anaconda3/envs/Geom3D/lib/python3.11/site-packages/lightning/pytorch/utilities/data.py:77: Trying to infer the `batch_size` from an ambiguous collection. The batch size we found is 7745. To avoid any miscalculations, use `self.log(..., batch_size=batch_size)`.\n",
      "/rds/general/user/cb1319/home/anaconda3/envs/Geom3D/lib/python3.11/site-packages/lightning/pytorch/utilities/data.py:77: Trying to infer the `batch_size` from an ambiguous collection. The batch size we found is 8088. To avoid any miscalculations, use `self.log(..., batch_size=batch_size)`.\n",
      "/rds/general/user/cb1319/home/anaconda3/envs/Geom3D/lib/python3.11/site-packages/lightning/pytorch/utilities/data.py:77: Trying to infer the `batch_size` from an ambiguous collection. The batch size we found is 7660. To avoid any miscalculations, use `self.log(..., batch_size=batch_size)`.\n",
      "/rds/general/user/cb1319/home/anaconda3/envs/Geom3D/lib/python3.11/site-packages/lightning/pytorch/utilities/data.py:77: Trying to infer the `batch_size` from an ambiguous collection. The batch size we found is 7795. To avoid any miscalculations, use `self.log(..., batch_size=batch_size)`.\n",
      "/rds/general/user/cb1319/home/anaconda3/envs/Geom3D/lib/python3.11/site-packages/lightning/pytorch/utilities/data.py:77: Trying to infer the `batch_size` from an ambiguous collection. The batch size we found is 7930. To avoid any miscalculations, use `self.log(..., batch_size=batch_size)`.\n",
      "/rds/general/user/cb1319/home/anaconda3/envs/Geom3D/lib/python3.11/site-packages/lightning/pytorch/utilities/data.py:77: Trying to infer the `batch_size` from an ambiguous collection. The batch size we found is 7974. To avoid any miscalculations, use `self.log(..., batch_size=batch_size)`.\n",
      "/rds/general/user/cb1319/home/anaconda3/envs/Geom3D/lib/python3.11/site-packages/lightning/pytorch/utilities/data.py:77: Trying to infer the `batch_size` from an ambiguous collection. The batch size we found is 7981. To avoid any miscalculations, use `self.log(..., batch_size=batch_size)`.\n",
      "/rds/general/user/cb1319/home/anaconda3/envs/Geom3D/lib/python3.11/site-packages/lightning/pytorch/utilities/data.py:77: Trying to infer the `batch_size` from an ambiguous collection. The batch size we found is 8043. To avoid any miscalculations, use `self.log(..., batch_size=batch_size)`.\n",
      "/rds/general/user/cb1319/home/anaconda3/envs/Geom3D/lib/python3.11/site-packages/lightning/pytorch/utilities/data.py:77: Trying to infer the `batch_size` from an ambiguous collection. The batch size we found is 8112. To avoid any miscalculations, use `self.log(..., batch_size=batch_size)`.\n",
      "/rds/general/user/cb1319/home/anaconda3/envs/Geom3D/lib/python3.11/site-packages/lightning/pytorch/utilities/data.py:77: Trying to infer the `batch_size` from an ambiguous collection. The batch size we found is 7587. To avoid any miscalculations, use `self.log(..., batch_size=batch_size)`.\n",
      "/rds/general/user/cb1319/home/anaconda3/envs/Geom3D/lib/python3.11/site-packages/lightning/pytorch/utilities/data.py:77: Trying to infer the `batch_size` from an ambiguous collection. The batch size we found is 7820. To avoid any miscalculations, use `self.log(..., batch_size=batch_size)`.\n",
      "/rds/general/user/cb1319/home/anaconda3/envs/Geom3D/lib/python3.11/site-packages/lightning/pytorch/utilities/data.py:77: Trying to infer the `batch_size` from an ambiguous collection. The batch size we found is 8158. To avoid any miscalculations, use `self.log(..., batch_size=batch_size)`.\n",
      "/rds/general/user/cb1319/home/anaconda3/envs/Geom3D/lib/python3.11/site-packages/lightning/pytorch/utilities/data.py:77: Trying to infer the `batch_size` from an ambiguous collection. The batch size we found is 7838. To avoid any miscalculations, use `self.log(..., batch_size=batch_size)`.\n",
      "/rds/general/user/cb1319/home/anaconda3/envs/Geom3D/lib/python3.11/site-packages/lightning/pytorch/utilities/data.py:77: Trying to infer the `batch_size` from an ambiguous collection. The batch size we found is 7665. To avoid any miscalculations, use `self.log(..., batch_size=batch_size)`.\n",
      "/rds/general/user/cb1319/home/anaconda3/envs/Geom3D/lib/python3.11/site-packages/lightning/pytorch/utilities/data.py:77: Trying to infer the `batch_size` from an ambiguous collection. The batch size we found is 7646. To avoid any miscalculations, use `self.log(..., batch_size=batch_size)`.\n",
      "/rds/general/user/cb1319/home/anaconda3/envs/Geom3D/lib/python3.11/site-packages/lightning/pytorch/utilities/data.py:77: Trying to infer the `batch_size` from an ambiguous collection. The batch size we found is 8085. To avoid any miscalculations, use `self.log(..., batch_size=batch_size)`.\n",
      "/rds/general/user/cb1319/home/anaconda3/envs/Geom3D/lib/python3.11/site-packages/lightning/pytorch/utilities/data.py:77: Trying to infer the `batch_size` from an ambiguous collection. The batch size we found is 7707. To avoid any miscalculations, use `self.log(..., batch_size=batch_size)`.\n",
      "/rds/general/user/cb1319/home/anaconda3/envs/Geom3D/lib/python3.11/site-packages/lightning/pytorch/utilities/data.py:77: Trying to infer the `batch_size` from an ambiguous collection. The batch size we found is 7529. To avoid any miscalculations, use `self.log(..., batch_size=batch_size)`.\n",
      "/rds/general/user/cb1319/home/anaconda3/envs/Geom3D/lib/python3.11/site-packages/lightning/pytorch/utilities/data.py:77: Trying to infer the `batch_size` from an ambiguous collection. The batch size we found is 7999. To avoid any miscalculations, use `self.log(..., batch_size=batch_size)`.\n",
      "/rds/general/user/cb1319/home/anaconda3/envs/Geom3D/lib/python3.11/site-packages/lightning/pytorch/utilities/data.py:77: Trying to infer the `batch_size` from an ambiguous collection. The batch size we found is 7737. To avoid any miscalculations, use `self.log(..., batch_size=batch_size)`.\n",
      "/rds/general/user/cb1319/home/anaconda3/envs/Geom3D/lib/python3.11/site-packages/lightning/pytorch/utilities/data.py:77: Trying to infer the `batch_size` from an ambiguous collection. The batch size we found is 7527. To avoid any miscalculations, use `self.log(..., batch_size=batch_size)`.\n",
      "/rds/general/user/cb1319/home/anaconda3/envs/Geom3D/lib/python3.11/site-packages/lightning/pytorch/utilities/data.py:77: Trying to infer the `batch_size` from an ambiguous collection. The batch size we found is 7935. To avoid any miscalculations, use `self.log(..., batch_size=batch_size)`.\n",
      "/rds/general/user/cb1319/home/anaconda3/envs/Geom3D/lib/python3.11/site-packages/lightning/pytorch/utilities/data.py:77: Trying to infer the `batch_size` from an ambiguous collection. The batch size we found is 7767. To avoid any miscalculations, use `self.log(..., batch_size=batch_size)`.\n",
      "/rds/general/user/cb1319/home/anaconda3/envs/Geom3D/lib/python3.11/site-packages/lightning/pytorch/utilities/data.py:77: Trying to infer the `batch_size` from an ambiguous collection. The batch size we found is 7922. To avoid any miscalculations, use `self.log(..., batch_size=batch_size)`.\n",
      "/rds/general/user/cb1319/home/anaconda3/envs/Geom3D/lib/python3.11/site-packages/lightning/pytorch/utilities/data.py:77: Trying to infer the `batch_size` from an ambiguous collection. The batch size we found is 7487. To avoid any miscalculations, use `self.log(..., batch_size=batch_size)`.\n",
      "/rds/general/user/cb1319/home/anaconda3/envs/Geom3D/lib/python3.11/site-packages/lightning/pytorch/utilities/data.py:77: Trying to infer the `batch_size` from an ambiguous collection. The batch size we found is 8186. To avoid any miscalculations, use `self.log(..., batch_size=batch_size)`.\n",
      "/rds/general/user/cb1319/home/anaconda3/envs/Geom3D/lib/python3.11/site-packages/lightning/pytorch/utilities/data.py:77: Trying to infer the `batch_size` from an ambiguous collection. The batch size we found is 8092. To avoid any miscalculations, use `self.log(..., batch_size=batch_size)`.\n",
      "/rds/general/user/cb1319/home/anaconda3/envs/Geom3D/lib/python3.11/site-packages/lightning/pytorch/utilities/data.py:77: Trying to infer the `batch_size` from an ambiguous collection. The batch size we found is 7585. To avoid any miscalculations, use `self.log(..., batch_size=batch_size)`.\n",
      "/rds/general/user/cb1319/home/anaconda3/envs/Geom3D/lib/python3.11/site-packages/lightning/pytorch/utilities/data.py:77: Trying to infer the `batch_size` from an ambiguous collection. The batch size we found is 7808. To avoid any miscalculations, use `self.log(..., batch_size=batch_size)`.\n",
      "/rds/general/user/cb1319/home/anaconda3/envs/Geom3D/lib/python3.11/site-packages/lightning/pytorch/utilities/data.py:77: Trying to infer the `batch_size` from an ambiguous collection. The batch size we found is 7972. To avoid any miscalculations, use `self.log(..., batch_size=batch_size)`.\n",
      "/rds/general/user/cb1319/home/anaconda3/envs/Geom3D/lib/python3.11/site-packages/lightning/pytorch/utilities/data.py:77: Trying to infer the `batch_size` from an ambiguous collection. The batch size we found is 7735. To avoid any miscalculations, use `self.log(..., batch_size=batch_size)`.\n",
      "/rds/general/user/cb1319/home/anaconda3/envs/Geom3D/lib/python3.11/site-packages/lightning/pytorch/utilities/data.py:77: Trying to infer the `batch_size` from an ambiguous collection. The batch size we found is 7887. To avoid any miscalculations, use `self.log(..., batch_size=batch_size)`.\n",
      "/rds/general/user/cb1319/home/anaconda3/envs/Geom3D/lib/python3.11/site-packages/lightning/pytorch/utilities/data.py:77: Trying to infer the `batch_size` from an ambiguous collection. The batch size we found is 8023. To avoid any miscalculations, use `self.log(..., batch_size=batch_size)`.\n",
      "/rds/general/user/cb1319/home/anaconda3/envs/Geom3D/lib/python3.11/site-packages/lightning/pytorch/utilities/data.py:77: Trying to infer the `batch_size` from an ambiguous collection. The batch size we found is 7865. To avoid any miscalculations, use `self.log(..., batch_size=batch_size)`.\n",
      "/rds/general/user/cb1319/home/anaconda3/envs/Geom3D/lib/python3.11/site-packages/lightning/pytorch/utilities/data.py:77: Trying to infer the `batch_size` from an ambiguous collection. The batch size we found is 7680. To avoid any miscalculations, use `self.log(..., batch_size=batch_size)`.\n",
      "/rds/general/user/cb1319/home/anaconda3/envs/Geom3D/lib/python3.11/site-packages/lightning/pytorch/utilities/data.py:77: Trying to infer the `batch_size` from an ambiguous collection. The batch size we found is 7736. To avoid any miscalculations, use `self.log(..., batch_size=batch_size)`.\n",
      "/rds/general/user/cb1319/home/anaconda3/envs/Geom3D/lib/python3.11/site-packages/lightning/pytorch/utilities/data.py:77: Trying to infer the `batch_size` from an ambiguous collection. The batch size we found is 8009. To avoid any miscalculations, use `self.log(..., batch_size=batch_size)`.\n",
      "/rds/general/user/cb1319/home/anaconda3/envs/Geom3D/lib/python3.11/site-packages/lightning/pytorch/utilities/data.py:77: Trying to infer the `batch_size` from an ambiguous collection. The batch size we found is 7763. To avoid any miscalculations, use `self.log(..., batch_size=batch_size)`.\n",
      "/rds/general/user/cb1319/home/anaconda3/envs/Geom3D/lib/python3.11/site-packages/lightning/pytorch/utilities/data.py:77: Trying to infer the `batch_size` from an ambiguous collection. The batch size we found is 8048. To avoid any miscalculations, use `self.log(..., batch_size=batch_size)`.\n",
      "/rds/general/user/cb1319/home/anaconda3/envs/Geom3D/lib/python3.11/site-packages/lightning/pytorch/utilities/data.py:77: Trying to infer the `batch_size` from an ambiguous collection. The batch size we found is 7742. To avoid any miscalculations, use `self.log(..., batch_size=batch_size)`.\n",
      "/rds/general/user/cb1319/home/anaconda3/envs/Geom3D/lib/python3.11/site-packages/lightning/pytorch/utilities/data.py:77: Trying to infer the `batch_size` from an ambiguous collection. The batch size we found is 7914. To avoid any miscalculations, use `self.log(..., batch_size=batch_size)`.\n",
      "/rds/general/user/cb1319/home/anaconda3/envs/Geom3D/lib/python3.11/site-packages/lightning/pytorch/utilities/data.py:77: Trying to infer the `batch_size` from an ambiguous collection. The batch size we found is 7633. To avoid any miscalculations, use `self.log(..., batch_size=batch_size)`.\n",
      "/rds/general/user/cb1319/home/anaconda3/envs/Geom3D/lib/python3.11/site-packages/lightning/pytorch/utilities/data.py:77: Trying to infer the `batch_size` from an ambiguous collection. The batch size we found is 8075. To avoid any miscalculations, use `self.log(..., batch_size=batch_size)`.\n",
      "/rds/general/user/cb1319/home/anaconda3/envs/Geom3D/lib/python3.11/site-packages/lightning/pytorch/utilities/data.py:77: Trying to infer the `batch_size` from an ambiguous collection. The batch size we found is 7649. To avoid any miscalculations, use `self.log(..., batch_size=batch_size)`.\n",
      "/rds/general/user/cb1319/home/anaconda3/envs/Geom3D/lib/python3.11/site-packages/lightning/pytorch/utilities/data.py:77: Trying to infer the `batch_size` from an ambiguous collection. The batch size we found is 7817. To avoid any miscalculations, use `self.log(..., batch_size=batch_size)`.\n",
      "/rds/general/user/cb1319/home/anaconda3/envs/Geom3D/lib/python3.11/site-packages/lightning/pytorch/utilities/data.py:77: Trying to infer the `batch_size` from an ambiguous collection. The batch size we found is 7826. To avoid any miscalculations, use `self.log(..., batch_size=batch_size)`.\n",
      "/rds/general/user/cb1319/home/anaconda3/envs/Geom3D/lib/python3.11/site-packages/lightning/pytorch/utilities/data.py:77: Trying to infer the `batch_size` from an ambiguous collection. The batch size we found is 8019. To avoid any miscalculations, use `self.log(..., batch_size=batch_size)`.\n",
      "/rds/general/user/cb1319/home/anaconda3/envs/Geom3D/lib/python3.11/site-packages/lightning/pytorch/utilities/data.py:77: Trying to infer the `batch_size` from an ambiguous collection. The batch size we found is 7967. To avoid any miscalculations, use `self.log(..., batch_size=batch_size)`.\n",
      "/rds/general/user/cb1319/home/anaconda3/envs/Geom3D/lib/python3.11/site-packages/lightning/pytorch/utilities/data.py:77: Trying to infer the `batch_size` from an ambiguous collection. The batch size we found is 7612. To avoid any miscalculations, use `self.log(..., batch_size=batch_size)`.\n",
      "/rds/general/user/cb1319/home/anaconda3/envs/Geom3D/lib/python3.11/site-packages/lightning/pytorch/utilities/data.py:77: Trying to infer the `batch_size` from an ambiguous collection. The batch size we found is 7903. To avoid any miscalculations, use `self.log(..., batch_size=batch_size)`.\n",
      "/rds/general/user/cb1319/home/anaconda3/envs/Geom3D/lib/python3.11/site-packages/lightning/pytorch/utilities/data.py:77: Trying to infer the `batch_size` from an ambiguous collection. The batch size we found is 7815. To avoid any miscalculations, use `self.log(..., batch_size=batch_size)`.\n",
      "/rds/general/user/cb1319/home/anaconda3/envs/Geom3D/lib/python3.11/site-packages/lightning/pytorch/utilities/data.py:77: Trying to infer the `batch_size` from an ambiguous collection. The batch size we found is 7812. To avoid any miscalculations, use `self.log(..., batch_size=batch_size)`.\n",
      "/rds/general/user/cb1319/home/anaconda3/envs/Geom3D/lib/python3.11/site-packages/lightning/pytorch/utilities/data.py:77: Trying to infer the `batch_size` from an ambiguous collection. The batch size we found is 8144. To avoid any miscalculations, use `self.log(..., batch_size=batch_size)`.\n",
      "/rds/general/user/cb1319/home/anaconda3/envs/Geom3D/lib/python3.11/site-packages/lightning/pytorch/utilities/data.py:77: Trying to infer the `batch_size` from an ambiguous collection. The batch size we found is 7568. To avoid any miscalculations, use `self.log(..., batch_size=batch_size)`.\n",
      "/rds/general/user/cb1319/home/anaconda3/envs/Geom3D/lib/python3.11/site-packages/lightning/pytorch/utilities/data.py:77: Trying to infer the `batch_size` from an ambiguous collection. The batch size we found is 7753. To avoid any miscalculations, use `self.log(..., batch_size=batch_size)`.\n",
      "/rds/general/user/cb1319/home/anaconda3/envs/Geom3D/lib/python3.11/site-packages/lightning/pytorch/utilities/data.py:77: Trying to infer the `batch_size` from an ambiguous collection. The batch size we found is 8026. To avoid any miscalculations, use `self.log(..., batch_size=batch_size)`.\n",
      "/rds/general/user/cb1319/home/anaconda3/envs/Geom3D/lib/python3.11/site-packages/lightning/pytorch/utilities/data.py:77: Trying to infer the `batch_size` from an ambiguous collection. The batch size we found is 7845. To avoid any miscalculations, use `self.log(..., batch_size=batch_size)`.\n",
      "/rds/general/user/cb1319/home/anaconda3/envs/Geom3D/lib/python3.11/site-packages/lightning/pytorch/utilities/data.py:77: Trying to infer the `batch_size` from an ambiguous collection. The batch size we found is 7623. To avoid any miscalculations, use `self.log(..., batch_size=batch_size)`.\n",
      "/rds/general/user/cb1319/home/anaconda3/envs/Geom3D/lib/python3.11/site-packages/lightning/pytorch/utilities/data.py:77: Trying to infer the `batch_size` from an ambiguous collection. The batch size we found is 7931. To avoid any miscalculations, use `self.log(..., batch_size=batch_size)`.\n",
      "/rds/general/user/cb1319/home/anaconda3/envs/Geom3D/lib/python3.11/site-packages/lightning/pytorch/utilities/data.py:77: Trying to infer the `batch_size` from an ambiguous collection. The batch size we found is 7924. To avoid any miscalculations, use `self.log(..., batch_size=batch_size)`.\n",
      "/rds/general/user/cb1319/home/anaconda3/envs/Geom3D/lib/python3.11/site-packages/lightning/pytorch/utilities/data.py:77: Trying to infer the `batch_size` from an ambiguous collection. The batch size we found is 7738. To avoid any miscalculations, use `self.log(..., batch_size=batch_size)`.\n",
      "/rds/general/user/cb1319/home/anaconda3/envs/Geom3D/lib/python3.11/site-packages/lightning/pytorch/utilities/data.py:77: Trying to infer the `batch_size` from an ambiguous collection. The batch size we found is 7691. To avoid any miscalculations, use `self.log(..., batch_size=batch_size)`.\n",
      "/rds/general/user/cb1319/home/anaconda3/envs/Geom3D/lib/python3.11/site-packages/lightning/pytorch/utilities/data.py:77: Trying to infer the `batch_size` from an ambiguous collection. The batch size we found is 7744. To avoid any miscalculations, use `self.log(..., batch_size=batch_size)`.\n",
      "/rds/general/user/cb1319/home/anaconda3/envs/Geom3D/lib/python3.11/site-packages/lightning/pytorch/utilities/data.py:77: Trying to infer the `batch_size` from an ambiguous collection. The batch size we found is 7954. To avoid any miscalculations, use `self.log(..., batch_size=batch_size)`.\n",
      "/rds/general/user/cb1319/home/anaconda3/envs/Geom3D/lib/python3.11/site-packages/lightning/pytorch/utilities/data.py:77: Trying to infer the `batch_size` from an ambiguous collection. The batch size we found is 7861. To avoid any miscalculations, use `self.log(..., batch_size=batch_size)`.\n",
      "/rds/general/user/cb1319/home/anaconda3/envs/Geom3D/lib/python3.11/site-packages/lightning/pytorch/utilities/data.py:77: Trying to infer the `batch_size` from an ambiguous collection. The batch size we found is 7926. To avoid any miscalculations, use `self.log(..., batch_size=batch_size)`.\n",
      "/rds/general/user/cb1319/home/anaconda3/envs/Geom3D/lib/python3.11/site-packages/lightning/pytorch/utilities/data.py:77: Trying to infer the `batch_size` from an ambiguous collection. The batch size we found is 7539. To avoid any miscalculations, use `self.log(..., batch_size=batch_size)`.\n",
      "/rds/general/user/cb1319/home/anaconda3/envs/Geom3D/lib/python3.11/site-packages/lightning/pytorch/utilities/data.py:77: Trying to infer the `batch_size` from an ambiguous collection. The batch size we found is 7520. To avoid any miscalculations, use `self.log(..., batch_size=batch_size)`.\n",
      "/rds/general/user/cb1319/home/anaconda3/envs/Geom3D/lib/python3.11/site-packages/lightning/pytorch/utilities/data.py:77: Trying to infer the `batch_size` from an ambiguous collection. The batch size we found is 7605. To avoid any miscalculations, use `self.log(..., batch_size=batch_size)`.\n",
      "/rds/general/user/cb1319/home/anaconda3/envs/Geom3D/lib/python3.11/site-packages/lightning/pytorch/utilities/data.py:77: Trying to infer the `batch_size` from an ambiguous collection. The batch size we found is 7656. To avoid any miscalculations, use `self.log(..., batch_size=batch_size)`.\n",
      "/rds/general/user/cb1319/home/anaconda3/envs/Geom3D/lib/python3.11/site-packages/lightning/pytorch/utilities/data.py:77: Trying to infer the `batch_size` from an ambiguous collection. The batch size we found is 7643. To avoid any miscalculations, use `self.log(..., batch_size=batch_size)`.\n",
      "/rds/general/user/cb1319/home/anaconda3/envs/Geom3D/lib/python3.11/site-packages/lightning/pytorch/utilities/data.py:77: Trying to infer the `batch_size` from an ambiguous collection. The batch size we found is 7832. To avoid any miscalculations, use `self.log(..., batch_size=batch_size)`.\n",
      "/rds/general/user/cb1319/home/anaconda3/envs/Geom3D/lib/python3.11/site-packages/lightning/pytorch/utilities/data.py:77: Trying to infer the `batch_size` from an ambiguous collection. The batch size we found is 8127. To avoid any miscalculations, use `self.log(..., batch_size=batch_size)`.\n",
      "/rds/general/user/cb1319/home/anaconda3/envs/Geom3D/lib/python3.11/site-packages/lightning/pytorch/utilities/data.py:77: Trying to infer the `batch_size` from an ambiguous collection. The batch size we found is 7912. To avoid any miscalculations, use `self.log(..., batch_size=batch_size)`.\n",
      "/rds/general/user/cb1319/home/anaconda3/envs/Geom3D/lib/python3.11/site-packages/lightning/pytorch/utilities/data.py:77: Trying to infer the `batch_size` from an ambiguous collection. The batch size we found is 7769. To avoid any miscalculations, use `self.log(..., batch_size=batch_size)`.\n",
      "/rds/general/user/cb1319/home/anaconda3/envs/Geom3D/lib/python3.11/site-packages/lightning/pytorch/utilities/data.py:77: Trying to infer the `batch_size` from an ambiguous collection. The batch size we found is 8030. To avoid any miscalculations, use `self.log(..., batch_size=batch_size)`.\n",
      "/rds/general/user/cb1319/home/anaconda3/envs/Geom3D/lib/python3.11/site-packages/lightning/pytorch/utilities/data.py:77: Trying to infer the `batch_size` from an ambiguous collection. The batch size we found is 7928. To avoid any miscalculations, use `self.log(..., batch_size=batch_size)`.\n",
      "/rds/general/user/cb1319/home/anaconda3/envs/Geom3D/lib/python3.11/site-packages/lightning/pytorch/utilities/data.py:77: Trying to infer the `batch_size` from an ambiguous collection. The batch size we found is 7552. To avoid any miscalculations, use `self.log(..., batch_size=batch_size)`.\n",
      "/rds/general/user/cb1319/home/anaconda3/envs/Geom3D/lib/python3.11/site-packages/lightning/pytorch/utilities/data.py:77: Trying to infer the `batch_size` from an ambiguous collection. The batch size we found is 7939. To avoid any miscalculations, use `self.log(..., batch_size=batch_size)`.\n",
      "/rds/general/user/cb1319/home/anaconda3/envs/Geom3D/lib/python3.11/site-packages/lightning/pytorch/utilities/data.py:77: Trying to infer the `batch_size` from an ambiguous collection. The batch size we found is 7739. To avoid any miscalculations, use `self.log(..., batch_size=batch_size)`.\n",
      "/rds/general/user/cb1319/home/anaconda3/envs/Geom3D/lib/python3.11/site-packages/lightning/pytorch/utilities/data.py:77: Trying to infer the `batch_size` from an ambiguous collection. The batch size we found is 7764. To avoid any miscalculations, use `self.log(..., batch_size=batch_size)`.\n",
      "/rds/general/user/cb1319/home/anaconda3/envs/Geom3D/lib/python3.11/site-packages/lightning/pytorch/utilities/data.py:77: Trying to infer the `batch_size` from an ambiguous collection. The batch size we found is 7797. To avoid any miscalculations, use `self.log(..., batch_size=batch_size)`.\n",
      "/rds/general/user/cb1319/home/anaconda3/envs/Geom3D/lib/python3.11/site-packages/lightning/pytorch/utilities/data.py:77: Trying to infer the `batch_size` from an ambiguous collection. The batch size we found is 7956. To avoid any miscalculations, use `self.log(..., batch_size=batch_size)`.\n",
      "/rds/general/user/cb1319/home/anaconda3/envs/Geom3D/lib/python3.11/site-packages/lightning/pytorch/utilities/data.py:77: Trying to infer the `batch_size` from an ambiguous collection. The batch size we found is 7989. To avoid any miscalculations, use `self.log(..., batch_size=batch_size)`.\n",
      "/rds/general/user/cb1319/home/anaconda3/envs/Geom3D/lib/python3.11/site-packages/lightning/pytorch/utilities/data.py:77: Trying to infer the `batch_size` from an ambiguous collection. The batch size we found is 7852. To avoid any miscalculations, use `self.log(..., batch_size=batch_size)`.\n",
      "/rds/general/user/cb1319/home/anaconda3/envs/Geom3D/lib/python3.11/site-packages/lightning/pytorch/utilities/data.py:77: Trying to infer the `batch_size` from an ambiguous collection. The batch size we found is 7843. To avoid any miscalculations, use `self.log(..., batch_size=batch_size)`.\n",
      "/rds/general/user/cb1319/home/anaconda3/envs/Geom3D/lib/python3.11/site-packages/lightning/pytorch/utilities/data.py:77: Trying to infer the `batch_size` from an ambiguous collection. The batch size we found is 7634. To avoid any miscalculations, use `self.log(..., batch_size=batch_size)`.\n",
      "/rds/general/user/cb1319/home/anaconda3/envs/Geom3D/lib/python3.11/site-packages/lightning/pytorch/utilities/data.py:77: Trying to infer the `batch_size` from an ambiguous collection. The batch size we found is 7547. To avoid any miscalculations, use `self.log(..., batch_size=batch_size)`.\n",
      "/rds/general/user/cb1319/home/anaconda3/envs/Geom3D/lib/python3.11/site-packages/lightning/pytorch/utilities/data.py:77: Trying to infer the `batch_size` from an ambiguous collection. The batch size we found is 7918. To avoid any miscalculations, use `self.log(..., batch_size=batch_size)`.\n",
      "/rds/general/user/cb1319/home/anaconda3/envs/Geom3D/lib/python3.11/site-packages/lightning/pytorch/utilities/data.py:77: Trying to infer the `batch_size` from an ambiguous collection. The batch size we found is 7619. To avoid any miscalculations, use `self.log(..., batch_size=batch_size)`.\n",
      "/rds/general/user/cb1319/home/anaconda3/envs/Geom3D/lib/python3.11/site-packages/lightning/pytorch/utilities/data.py:77: Trying to infer the `batch_size` from an ambiguous collection. The batch size we found is 7835. To avoid any miscalculations, use `self.log(..., batch_size=batch_size)`.\n",
      "/rds/general/user/cb1319/home/anaconda3/envs/Geom3D/lib/python3.11/site-packages/lightning/pytorch/utilities/data.py:77: Trying to infer the `batch_size` from an ambiguous collection. The batch size we found is 7775. To avoid any miscalculations, use `self.log(..., batch_size=batch_size)`.\n",
      "/rds/general/user/cb1319/home/anaconda3/envs/Geom3D/lib/python3.11/site-packages/lightning/pytorch/utilities/data.py:77: Trying to infer the `batch_size` from an ambiguous collection. The batch size we found is 7785. To avoid any miscalculations, use `self.log(..., batch_size=batch_size)`.\n",
      "/rds/general/user/cb1319/home/anaconda3/envs/Geom3D/lib/python3.11/site-packages/lightning/pytorch/utilities/data.py:77: Trying to infer the `batch_size` from an ambiguous collection. The batch size we found is 7695. To avoid any miscalculations, use `self.log(..., batch_size=batch_size)`.\n",
      "/rds/general/user/cb1319/home/anaconda3/envs/Geom3D/lib/python3.11/site-packages/lightning/pytorch/utilities/data.py:77: Trying to infer the `batch_size` from an ambiguous collection. The batch size we found is 7531. To avoid any miscalculations, use `self.log(..., batch_size=batch_size)`.\n",
      "/rds/general/user/cb1319/home/anaconda3/envs/Geom3D/lib/python3.11/site-packages/lightning/pytorch/utilities/data.py:77: Trying to infer the `batch_size` from an ambiguous collection. The batch size we found is 7829. To avoid any miscalculations, use `self.log(..., batch_size=batch_size)`.\n",
      "/rds/general/user/cb1319/home/anaconda3/envs/Geom3D/lib/python3.11/site-packages/lightning/pytorch/utilities/data.py:77: Trying to infer the `batch_size` from an ambiguous collection. The batch size we found is 7777. To avoid any miscalculations, use `self.log(..., batch_size=batch_size)`.\n",
      "/rds/general/user/cb1319/home/anaconda3/envs/Geom3D/lib/python3.11/site-packages/lightning/pytorch/utilities/data.py:77: Trying to infer the `batch_size` from an ambiguous collection. The batch size we found is 7755. To avoid any miscalculations, use `self.log(..., batch_size=batch_size)`.\n",
      "/rds/general/user/cb1319/home/anaconda3/envs/Geom3D/lib/python3.11/site-packages/lightning/pytorch/utilities/data.py:77: Trying to infer the `batch_size` from an ambiguous collection. The batch size we found is 7497. To avoid any miscalculations, use `self.log(..., batch_size=batch_size)`.\n",
      "/rds/general/user/cb1319/home/anaconda3/envs/Geom3D/lib/python3.11/site-packages/lightning/pytorch/utilities/data.py:77: Trying to infer the `batch_size` from an ambiguous collection. The batch size we found is 7901. To avoid any miscalculations, use `self.log(..., batch_size=batch_size)`.\n",
      "/rds/general/user/cb1319/home/anaconda3/envs/Geom3D/lib/python3.11/site-packages/lightning/pytorch/utilities/data.py:77: Trying to infer the `batch_size` from an ambiguous collection. The batch size we found is 7768. To avoid any miscalculations, use `self.log(..., batch_size=batch_size)`.\n",
      "/rds/general/user/cb1319/home/anaconda3/envs/Geom3D/lib/python3.11/site-packages/lightning/pytorch/utilities/data.py:77: Trying to infer the `batch_size` from an ambiguous collection. The batch size we found is 7783. To avoid any miscalculations, use `self.log(..., batch_size=batch_size)`.\n",
      "/rds/general/user/cb1319/home/anaconda3/envs/Geom3D/lib/python3.11/site-packages/lightning/pytorch/utilities/data.py:77: Trying to infer the `batch_size` from an ambiguous collection. The batch size we found is 7538. To avoid any miscalculations, use `self.log(..., batch_size=batch_size)`.\n",
      "/rds/general/user/cb1319/home/anaconda3/envs/Geom3D/lib/python3.11/site-packages/lightning/pytorch/utilities/data.py:77: Trying to infer the `batch_size` from an ambiguous collection. The batch size we found is 7481. To avoid any miscalculations, use `self.log(..., batch_size=batch_size)`.\n",
      "/rds/general/user/cb1319/home/anaconda3/envs/Geom3D/lib/python3.11/site-packages/lightning/pytorch/utilities/data.py:77: Trying to infer the `batch_size` from an ambiguous collection. The batch size we found is 7911. To avoid any miscalculations, use `self.log(..., batch_size=batch_size)`.\n",
      "/rds/general/user/cb1319/home/anaconda3/envs/Geom3D/lib/python3.11/site-packages/lightning/pytorch/utilities/data.py:77: Trying to infer the `batch_size` from an ambiguous collection. The batch size we found is 7734. To avoid any miscalculations, use `self.log(..., batch_size=batch_size)`.\n",
      "/rds/general/user/cb1319/home/anaconda3/envs/Geom3D/lib/python3.11/site-packages/lightning/pytorch/utilities/data.py:77: Trying to infer the `batch_size` from an ambiguous collection. The batch size we found is 7762. To avoid any miscalculations, use `self.log(..., batch_size=batch_size)`.\n",
      "/rds/general/user/cb1319/home/anaconda3/envs/Geom3D/lib/python3.11/site-packages/lightning/pytorch/utilities/data.py:77: Trying to infer the `batch_size` from an ambiguous collection. The batch size we found is 7800. To avoid any miscalculations, use `self.log(..., batch_size=batch_size)`.\n",
      "/rds/general/user/cb1319/home/anaconda3/envs/Geom3D/lib/python3.11/site-packages/lightning/pytorch/utilities/data.py:77: Trying to infer the `batch_size` from an ambiguous collection. The batch size we found is 7626. To avoid any miscalculations, use `self.log(..., batch_size=batch_size)`.\n",
      "/rds/general/user/cb1319/home/anaconda3/envs/Geom3D/lib/python3.11/site-packages/lightning/pytorch/utilities/data.py:77: Trying to infer the `batch_size` from an ambiguous collection. The batch size we found is 7574. To avoid any miscalculations, use `self.log(..., batch_size=batch_size)`.\n",
      "/rds/general/user/cb1319/home/anaconda3/envs/Geom3D/lib/python3.11/site-packages/lightning/pytorch/utilities/data.py:77: Trying to infer the `batch_size` from an ambiguous collection. The batch size we found is 7973. To avoid any miscalculations, use `self.log(..., batch_size=batch_size)`.\n",
      "/rds/general/user/cb1319/home/anaconda3/envs/Geom3D/lib/python3.11/site-packages/lightning/pytorch/utilities/data.py:77: Trying to infer the `batch_size` from an ambiguous collection. The batch size we found is 7451. To avoid any miscalculations, use `self.log(..., batch_size=batch_size)`.\n"
=======
      "`Trainer.fit` stopped: `max_epochs=5` reached.\n"
>>>>>>> Stashed changes
     ]
    },
    {
     "data": {
      "application/vnd.jupyter.widget-view+json": {
<<<<<<< Updated upstream
       "model_id": "947adeba9f3e45b49c3868530626d35a",
=======
       "model_id": "e13bc0de3f9d4558aaf45527c42ebab9",
>>>>>>> Stashed changes
       "version_major": 2,
       "version_minor": 0
      },
      "text/plain": [
<<<<<<< Updated upstream
       "Validation: |          | 0/? [00:00<?, ?it/s]"
=======
       "VBox(children=(Label(value='15.758 MB of 15.758 MB uploaded\\r'), FloatProgress(value=1.0, max=1.0)))"
>>>>>>> Stashed changes
      ]
     },
     "metadata": {},
     "output_type": "display_data"
    },
    {
     "name": "stderr",
     "output_type": "stream",
     "text": [
<<<<<<< Updated upstream
      "/rds/general/user/cb1319/home/anaconda3/envs/Geom3D/lib/python3.11/site-packages/lightning/pytorch/utilities/data.py:77: Trying to infer the `batch_size` from an ambiguous collection. The batch size we found is 8083. To avoid any miscalculations, use `self.log(..., batch_size=batch_size)`.\n",
      "/rds/general/user/cb1319/home/anaconda3/envs/Geom3D/lib/python3.11/site-packages/lightning/pytorch/utilities/data.py:77: Trying to infer the `batch_size` from an ambiguous collection. The batch size we found is 8052. To avoid any miscalculations, use `self.log(..., batch_size=batch_size)`.\n",
      "/rds/general/user/cb1319/home/anaconda3/envs/Geom3D/lib/python3.11/site-packages/lightning/pytorch/utilities/data.py:77: Trying to infer the `batch_size` from an ambiguous collection. The batch size we found is 8109. To avoid any miscalculations, use `self.log(..., batch_size=batch_size)`.\n",
      "/rds/general/user/cb1319/home/anaconda3/envs/Geom3D/lib/python3.11/site-packages/lightning/pytorch/utilities/data.py:77: Trying to infer the `batch_size` from an ambiguous collection. The batch size we found is 7564. To avoid any miscalculations, use `self.log(..., batch_size=batch_size)`.\n",
      "/rds/general/user/cb1319/home/anaconda3/envs/Geom3D/lib/python3.11/site-packages/lightning/pytorch/utilities/data.py:77: Trying to infer the `batch_size` from an ambiguous collection. The batch size we found is 7642. To avoid any miscalculations, use `self.log(..., batch_size=batch_size)`.\n",
      "/rds/general/user/cb1319/home/anaconda3/envs/Geom3D/lib/python3.11/site-packages/lightning/pytorch/utilities/data.py:77: Trying to infer the `batch_size` from an ambiguous collection. The batch size we found is 7776. To avoid any miscalculations, use `self.log(..., batch_size=batch_size)`.\n",
      "/rds/general/user/cb1319/home/anaconda3/envs/Geom3D/lib/python3.11/site-packages/lightning/pytorch/utilities/data.py:77: Trying to infer the `batch_size` from an ambiguous collection. The batch size we found is 7757. To avoid any miscalculations, use `self.log(..., batch_size=batch_size)`.\n",
      "/rds/general/user/cb1319/home/anaconda3/envs/Geom3D/lib/python3.11/site-packages/lightning/pytorch/utilities/data.py:77: Trying to infer the `batch_size` from an ambiguous collection. The batch size we found is 7842. To avoid any miscalculations, use `self.log(..., batch_size=batch_size)`.\n",
      "/rds/general/user/cb1319/home/anaconda3/envs/Geom3D/lib/python3.11/site-packages/lightning/pytorch/utilities/data.py:77: Trying to infer the `batch_size` from an ambiguous collection. The batch size we found is 7909. To avoid any miscalculations, use `self.log(..., batch_size=batch_size)`.\n",
      "/rds/general/user/cb1319/home/anaconda3/envs/Geom3D/lib/python3.11/site-packages/lightning/pytorch/utilities/data.py:77: Trying to infer the `batch_size` from an ambiguous collection. The batch size we found is 8070. To avoid any miscalculations, use `self.log(..., batch_size=batch_size)`.\n",
      "/rds/general/user/cb1319/home/anaconda3/envs/Geom3D/lib/python3.11/site-packages/lightning/pytorch/utilities/data.py:77: Trying to infer the `batch_size` from an ambiguous collection. The batch size we found is 7907. To avoid any miscalculations, use `self.log(..., batch_size=batch_size)`.\n",
      "/rds/general/user/cb1319/home/anaconda3/envs/Geom3D/lib/python3.11/site-packages/lightning/pytorch/utilities/data.py:77: Trying to infer the `batch_size` from an ambiguous collection. The batch size we found is 7825. To avoid any miscalculations, use `self.log(..., batch_size=batch_size)`.\n",
      "/rds/general/user/cb1319/home/anaconda3/envs/Geom3D/lib/python3.11/site-packages/lightning/pytorch/utilities/data.py:77: Trying to infer the `batch_size` from an ambiguous collection. The batch size we found is 7653. To avoid any miscalculations, use `self.log(..., batch_size=batch_size)`.\n",
      "/rds/general/user/cb1319/home/anaconda3/envs/Geom3D/lib/python3.11/site-packages/lightning/pytorch/utilities/data.py:77: Trying to infer the `batch_size` from an ambiguous collection. The batch size we found is 7891. To avoid any miscalculations, use `self.log(..., batch_size=batch_size)`.\n",
      "/rds/general/user/cb1319/home/anaconda3/envs/Geom3D/lib/python3.11/site-packages/lightning/pytorch/utilities/data.py:77: Trying to infer the `batch_size` from an ambiguous collection. The batch size we found is 7458. To avoid any miscalculations, use `self.log(..., batch_size=batch_size)`.\n",
      "/rds/general/user/cb1319/home/anaconda3/envs/Geom3D/lib/python3.11/site-packages/lightning/pytorch/utilities/data.py:77: Trying to infer the `batch_size` from an ambiguous collection. The batch size we found is 7770. To avoid any miscalculations, use `self.log(..., batch_size=batch_size)`.\n",
      "/rds/general/user/cb1319/home/anaconda3/envs/Geom3D/lib/python3.11/site-packages/lightning/pytorch/utilities/data.py:77: Trying to infer the `batch_size` from an ambiguous collection. The batch size we found is 7702. To avoid any miscalculations, use `self.log(..., batch_size=batch_size)`.\n",
      "/rds/general/user/cb1319/home/anaconda3/envs/Geom3D/lib/python3.11/site-packages/lightning/pytorch/utilities/data.py:77: Trying to infer the `batch_size` from an ambiguous collection. The batch size we found is 7968. To avoid any miscalculations, use `self.log(..., batch_size=batch_size)`.\n",
      "/rds/general/user/cb1319/home/anaconda3/envs/Geom3D/lib/python3.11/site-packages/lightning/pytorch/utilities/data.py:77: Trying to infer the `batch_size` from an ambiguous collection. The batch size we found is 7948. To avoid any miscalculations, use `self.log(..., batch_size=batch_size)`.\n",
      "/rds/general/user/cb1319/home/anaconda3/envs/Geom3D/lib/python3.11/site-packages/lightning/pytorch/utilities/data.py:77: Trying to infer the `batch_size` from an ambiguous collection. The batch size we found is 7854. To avoid any miscalculations, use `self.log(..., batch_size=batch_size)`.\n",
      "/rds/general/user/cb1319/home/anaconda3/envs/Geom3D/lib/python3.11/site-packages/lightning/pytorch/utilities/data.py:77: Trying to infer the `batch_size` from an ambiguous collection. The batch size we found is 7645. To avoid any miscalculations, use `self.log(..., batch_size=batch_size)`.\n",
      "/rds/general/user/cb1319/home/anaconda3/envs/Geom3D/lib/python3.11/site-packages/lightning/pytorch/utilities/data.py:77: Trying to infer the `batch_size` from an ambiguous collection. The batch size we found is 7844. To avoid any miscalculations, use `self.log(..., batch_size=batch_size)`.\n",
      "/rds/general/user/cb1319/home/anaconda3/envs/Geom3D/lib/python3.11/site-packages/lightning/pytorch/utilities/data.py:77: Trying to infer the `batch_size` from an ambiguous collection. The batch size we found is 7560. To avoid any miscalculations, use `self.log(..., batch_size=batch_size)`.\n",
      "/rds/general/user/cb1319/home/anaconda3/envs/Geom3D/lib/python3.11/site-packages/lightning/pytorch/utilities/data.py:77: Trying to infer the `batch_size` from an ambiguous collection. The batch size we found is 7929. To avoid any miscalculations, use `self.log(..., batch_size=batch_size)`.\n",
      "/rds/general/user/cb1319/home/anaconda3/envs/Geom3D/lib/python3.11/site-packages/lightning/pytorch/utilities/data.py:77: Trying to infer the `batch_size` from an ambiguous collection. The batch size we found is 7759. To avoid any miscalculations, use `self.log(..., batch_size=batch_size)`.\n",
      "/rds/general/user/cb1319/home/anaconda3/envs/Geom3D/lib/python3.11/site-packages/lightning/pytorch/utilities/data.py:77: Trying to infer the `batch_size` from an ambiguous collection. The batch size we found is 7692. To avoid any miscalculations, use `self.log(..., batch_size=batch_size)`.\n",
      "/rds/general/user/cb1319/home/anaconda3/envs/Geom3D/lib/python3.11/site-packages/lightning/pytorch/utilities/data.py:77: Trying to infer the `batch_size` from an ambiguous collection. The batch size we found is 8102. To avoid any miscalculations, use `self.log(..., batch_size=batch_size)`.\n",
      "/rds/general/user/cb1319/home/anaconda3/envs/Geom3D/lib/python3.11/site-packages/lightning/pytorch/utilities/data.py:77: Trying to infer the `batch_size` from an ambiguous collection. The batch size we found is 7639. To avoid any miscalculations, use `self.log(..., batch_size=batch_size)`.\n",
      "/rds/general/user/cb1319/home/anaconda3/envs/Geom3D/lib/python3.11/site-packages/lightning/pytorch/utilities/data.py:77: Trying to infer the `batch_size` from an ambiguous collection. The batch size we found is 7814. To avoid any miscalculations, use `self.log(..., batch_size=batch_size)`.\n",
      "/rds/general/user/cb1319/home/anaconda3/envs/Geom3D/lib/python3.11/site-packages/lightning/pytorch/utilities/data.py:77: Trying to infer the `batch_size` from an ambiguous collection. The batch size we found is 7727. To avoid any miscalculations, use `self.log(..., batch_size=batch_size)`.\n",
      "/rds/general/user/cb1319/home/anaconda3/envs/Geom3D/lib/python3.11/site-packages/lightning/pytorch/utilities/data.py:77: Trying to infer the `batch_size` from an ambiguous collection. The batch size we found is 7756. To avoid any miscalculations, use `self.log(..., batch_size=batch_size)`.\n",
      "/rds/general/user/cb1319/home/anaconda3/envs/Geom3D/lib/python3.11/site-packages/lightning/pytorch/utilities/data.py:77: Trying to infer the `batch_size` from an ambiguous collection. The batch size we found is 7943. To avoid any miscalculations, use `self.log(..., batch_size=batch_size)`.\n",
      "/rds/general/user/cb1319/home/anaconda3/envs/Geom3D/lib/python3.11/site-packages/lightning/pytorch/utilities/data.py:77: Trying to infer the `batch_size` from an ambiguous collection. The batch size we found is 7915. To avoid any miscalculations, use `self.log(..., batch_size=batch_size)`.\n",
      "/rds/general/user/cb1319/home/anaconda3/envs/Geom3D/lib/python3.11/site-packages/lightning/pytorch/utilities/data.py:77: Trying to infer the `batch_size` from an ambiguous collection. The batch size we found is 7444. To avoid any miscalculations, use `self.log(..., batch_size=batch_size)`.\n",
      "/rds/general/user/cb1319/home/anaconda3/envs/Geom3D/lib/python3.11/site-packages/lightning/pytorch/utilities/data.py:77: Trying to infer the `batch_size` from an ambiguous collection. The batch size we found is 7640. To avoid any miscalculations, use `self.log(..., batch_size=batch_size)`.\n",
      "/rds/general/user/cb1319/home/anaconda3/envs/Geom3D/lib/python3.11/site-packages/lightning/pytorch/utilities/data.py:77: Trying to infer the `batch_size` from an ambiguous collection. The batch size we found is 7566. To avoid any miscalculations, use `self.log(..., batch_size=batch_size)`.\n",
      "/rds/general/user/cb1319/home/anaconda3/envs/Geom3D/lib/python3.11/site-packages/lightning/pytorch/utilities/data.py:77: Trying to infer the `batch_size` from an ambiguous collection. The batch size we found is 7878. To avoid any miscalculations, use `self.log(..., batch_size=batch_size)`.\n",
      "/rds/general/user/cb1319/home/anaconda3/envs/Geom3D/lib/python3.11/site-packages/lightning/pytorch/utilities/data.py:77: Trying to infer the `batch_size` from an ambiguous collection. The batch size we found is 7709. To avoid any miscalculations, use `self.log(..., batch_size=batch_size)`.\n",
      "/rds/general/user/cb1319/home/anaconda3/envs/Geom3D/lib/python3.11/site-packages/lightning/pytorch/utilities/data.py:77: Trying to infer the `batch_size` from an ambiguous collection. The batch size we found is 8197. To avoid any miscalculations, use `self.log(..., batch_size=batch_size)`.\n",
      "/rds/general/user/cb1319/home/anaconda3/envs/Geom3D/lib/python3.11/site-packages/lightning/pytorch/utilities/data.py:77: Trying to infer the `batch_size` from an ambiguous collection. The batch size we found is 7718. To avoid any miscalculations, use `self.log(..., batch_size=batch_size)`.\n",
      "/rds/general/user/cb1319/home/anaconda3/envs/Geom3D/lib/python3.11/site-packages/lightning/pytorch/utilities/data.py:77: Trying to infer the `batch_size` from an ambiguous collection. The batch size we found is 7927. To avoid any miscalculations, use `self.log(..., batch_size=batch_size)`.\n",
      "/rds/general/user/cb1319/home/anaconda3/envs/Geom3D/lib/python3.11/site-packages/lightning/pytorch/utilities/data.py:77: Trying to infer the `batch_size` from an ambiguous collection. The batch size we found is 8224. To avoid any miscalculations, use `self.log(..., batch_size=batch_size)`.\n",
      "/rds/general/user/cb1319/home/anaconda3/envs/Geom3D/lib/python3.11/site-packages/lightning/pytorch/utilities/data.py:77: Trying to infer the `batch_size` from an ambiguous collection. The batch size we found is 8324. To avoid any miscalculations, use `self.log(..., batch_size=batch_size)`.\n",
      "/rds/general/user/cb1319/home/anaconda3/envs/Geom3D/lib/python3.11/site-packages/lightning/pytorch/utilities/data.py:77: Trying to infer the `batch_size` from an ambiguous collection. The batch size we found is 7831. To avoid any miscalculations, use `self.log(..., batch_size=batch_size)`.\n",
      "/rds/general/user/cb1319/home/anaconda3/envs/Geom3D/lib/python3.11/site-packages/lightning/pytorch/utilities/data.py:77: Trying to infer the `batch_size` from an ambiguous collection. The batch size we found is 7851. To avoid any miscalculations, use `self.log(..., batch_size=batch_size)`.\n",
      "/rds/general/user/cb1319/home/anaconda3/envs/Geom3D/lib/python3.11/site-packages/lightning/pytorch/utilities/data.py:77: Trying to infer the `batch_size` from an ambiguous collection. The batch size we found is 7886. To avoid any miscalculations, use `self.log(..., batch_size=batch_size)`.\n",
      "/rds/general/user/cb1319/home/anaconda3/envs/Geom3D/lib/python3.11/site-packages/lightning/pytorch/utilities/data.py:77: Trying to infer the `batch_size` from an ambiguous collection. The batch size we found is 7873. To avoid any miscalculations, use `self.log(..., batch_size=batch_size)`.\n",
      "/rds/general/user/cb1319/home/anaconda3/envs/Geom3D/lib/python3.11/site-packages/lightning/pytorch/utilities/data.py:77: Trying to infer the `batch_size` from an ambiguous collection. The batch size we found is 7919. To avoid any miscalculations, use `self.log(..., batch_size=batch_size)`.\n",
      "/rds/general/user/cb1319/home/anaconda3/envs/Geom3D/lib/python3.11/site-packages/lightning/pytorch/utilities/data.py:77: Trying to infer the `batch_size` from an ambiguous collection. The batch size we found is 7610. To avoid any miscalculations, use `self.log(..., batch_size=batch_size)`.\n",
      "/rds/general/user/cb1319/home/anaconda3/envs/Geom3D/lib/python3.11/site-packages/lightning/pytorch/utilities/data.py:77: Trying to infer the `batch_size` from an ambiguous collection. The batch size we found is 7883. To avoid any miscalculations, use `self.log(..., batch_size=batch_size)`.\n",
      "/rds/general/user/cb1319/home/anaconda3/envs/Geom3D/lib/python3.11/site-packages/lightning/pytorch/utilities/data.py:77: Trying to infer the `batch_size` from an ambiguous collection. The batch size we found is 7890. To avoid any miscalculations, use `self.log(..., batch_size=batch_size)`.\n",
      "/rds/general/user/cb1319/home/anaconda3/envs/Geom3D/lib/python3.11/site-packages/lightning/pytorch/utilities/data.py:77: Trying to infer the `batch_size` from an ambiguous collection. The batch size we found is 7906. To avoid any miscalculations, use `self.log(..., batch_size=batch_size)`.\n",
      "/rds/general/user/cb1319/home/anaconda3/envs/Geom3D/lib/python3.11/site-packages/lightning/pytorch/utilities/data.py:77: Trying to infer the `batch_size` from an ambiguous collection. The batch size we found is 7550. To avoid any miscalculations, use `self.log(..., batch_size=batch_size)`.\n",
      "/rds/general/user/cb1319/home/anaconda3/envs/Geom3D/lib/python3.11/site-packages/lightning/pytorch/utilities/data.py:77: Trying to infer the `batch_size` from an ambiguous collection. The batch size we found is 7781. To avoid any miscalculations, use `self.log(..., batch_size=batch_size)`.\n",
      "/rds/general/user/cb1319/home/anaconda3/envs/Geom3D/lib/python3.11/site-packages/lightning/pytorch/utilities/data.py:77: Trying to infer the `batch_size` from an ambiguous collection. The batch size we found is 7522. To avoid any miscalculations, use `self.log(..., batch_size=batch_size)`.\n",
      "/rds/general/user/cb1319/home/anaconda3/envs/Geom3D/lib/python3.11/site-packages/lightning/pytorch/utilities/data.py:77: Trying to infer the `batch_size` from an ambiguous collection. The batch size we found is 7638. To avoid any miscalculations, use `self.log(..., batch_size=batch_size)`.\n",
      "/rds/general/user/cb1319/home/anaconda3/envs/Geom3D/lib/python3.11/site-packages/lightning/pytorch/utilities/data.py:77: Trying to infer the `batch_size` from an ambiguous collection. The batch size we found is 7760. To avoid any miscalculations, use `self.log(..., batch_size=batch_size)`.\n",
      "/rds/general/user/cb1319/home/anaconda3/envs/Geom3D/lib/python3.11/site-packages/lightning/pytorch/utilities/data.py:77: Trying to infer the `batch_size` from an ambiguous collection. The batch size we found is 7938. To avoid any miscalculations, use `self.log(..., batch_size=batch_size)`.\n",
      "/rds/general/user/cb1319/home/anaconda3/envs/Geom3D/lib/python3.11/site-packages/lightning/pytorch/utilities/data.py:77: Trying to infer the `batch_size` from an ambiguous collection. The batch size we found is 8267. To avoid any miscalculations, use `self.log(..., batch_size=batch_size)`.\n",
      "/rds/general/user/cb1319/home/anaconda3/envs/Geom3D/lib/python3.11/site-packages/lightning/pytorch/utilities/data.py:77: Trying to infer the `batch_size` from an ambiguous collection. The batch size we found is 7699. To avoid any miscalculations, use `self.log(..., batch_size=batch_size)`.\n",
      "/rds/general/user/cb1319/home/anaconda3/envs/Geom3D/lib/python3.11/site-packages/lightning/pytorch/utilities/data.py:77: Trying to infer the `batch_size` from an ambiguous collection. The batch size we found is 7856. To avoid any miscalculations, use `self.log(..., batch_size=batch_size)`.\n",
      "/rds/general/user/cb1319/home/anaconda3/envs/Geom3D/lib/python3.11/site-packages/lightning/pytorch/utilities/data.py:77: Trying to infer the `batch_size` from an ambiguous collection. The batch size we found is 7908. To avoid any miscalculations, use `self.log(..., batch_size=batch_size)`.\n",
      "/rds/general/user/cb1319/home/anaconda3/envs/Geom3D/lib/python3.11/site-packages/lightning/pytorch/utilities/data.py:77: Trying to infer the `batch_size` from an ambiguous collection. The batch size we found is 7889. To avoid any miscalculations, use `self.log(..., batch_size=batch_size)`.\n",
      "/rds/general/user/cb1319/home/anaconda3/envs/Geom3D/lib/python3.11/site-packages/lightning/pytorch/utilities/data.py:77: Trying to infer the `batch_size` from an ambiguous collection. The batch size we found is 8161. To avoid any miscalculations, use `self.log(..., batch_size=batch_size)`.\n",
      "/rds/general/user/cb1319/home/anaconda3/envs/Geom3D/lib/python3.11/site-packages/lightning/pytorch/utilities/data.py:77: Trying to infer the `batch_size` from an ambiguous collection. The batch size we found is 7723. To avoid any miscalculations, use `self.log(..., batch_size=batch_size)`.\n",
      "/rds/general/user/cb1319/home/anaconda3/envs/Geom3D/lib/python3.11/site-packages/lightning/pytorch/utilities/data.py:77: Trying to infer the `batch_size` from an ambiguous collection. The batch size we found is 8123. To avoid any miscalculations, use `self.log(..., batch_size=batch_size)`.\n",
      "/rds/general/user/cb1319/home/anaconda3/envs/Geom3D/lib/python3.11/site-packages/lightning/pytorch/utilities/data.py:77: Trying to infer the `batch_size` from an ambiguous collection. The batch size we found is 8374. To avoid any miscalculations, use `self.log(..., batch_size=batch_size)`.\n",
      "/rds/general/user/cb1319/home/anaconda3/envs/Geom3D/lib/python3.11/site-packages/lightning/pytorch/utilities/data.py:77: Trying to infer the `batch_size` from an ambiguous collection. The batch size we found is 7677. To avoid any miscalculations, use `self.log(..., batch_size=batch_size)`.\n",
      "/rds/general/user/cb1319/home/anaconda3/envs/Geom3D/lib/python3.11/site-packages/lightning/pytorch/utilities/data.py:77: Trying to infer the `batch_size` from an ambiguous collection. The batch size we found is 7725. To avoid any miscalculations, use `self.log(..., batch_size=batch_size)`.\n",
      "/rds/general/user/cb1319/home/anaconda3/envs/Geom3D/lib/python3.11/site-packages/lightning/pytorch/utilities/data.py:77: Trying to infer the `batch_size` from an ambiguous collection. The batch size we found is 7790. To avoid any miscalculations, use `self.log(..., batch_size=batch_size)`.\n",
      "/rds/general/user/cb1319/home/anaconda3/envs/Geom3D/lib/python3.11/site-packages/lightning/pytorch/utilities/data.py:77: Trying to infer the `batch_size` from an ambiguous collection. The batch size we found is 7601. To avoid any miscalculations, use `self.log(..., batch_size=batch_size)`.\n",
      "/rds/general/user/cb1319/home/anaconda3/envs/Geom3D/lib/python3.11/site-packages/lightning/pytorch/utilities/data.py:77: Trying to infer the `batch_size` from an ambiguous collection. The batch size we found is 7398. To avoid any miscalculations, use `self.log(..., batch_size=batch_size)`.\n",
      "/rds/general/user/cb1319/home/anaconda3/envs/Geom3D/lib/python3.11/site-packages/lightning/pytorch/utilities/data.py:77: Trying to infer the `batch_size` from an ambiguous collection. The batch size we found is 7516. To avoid any miscalculations, use `self.log(..., batch_size=batch_size)`.\n",
      "/rds/general/user/cb1319/home/anaconda3/envs/Geom3D/lib/python3.11/site-packages/lightning/pytorch/utilities/data.py:77: Trying to infer the `batch_size` from an ambiguous collection. The batch size we found is 7962. To avoid any miscalculations, use `self.log(..., batch_size=batch_size)`.\n",
      "/rds/general/user/cb1319/home/anaconda3/envs/Geom3D/lib/python3.11/site-packages/lightning/pytorch/utilities/data.py:77: Trying to infer the `batch_size` from an ambiguous collection. The batch size we found is 7490. To avoid any miscalculations, use `self.log(..., batch_size=batch_size)`.\n",
      "/rds/general/user/cb1319/home/anaconda3/envs/Geom3D/lib/python3.11/site-packages/lightning/pytorch/utilities/data.py:77: Trying to infer the `batch_size` from an ambiguous collection. The batch size we found is 7925. To avoid any miscalculations, use `self.log(..., batch_size=batch_size)`.\n",
      "/rds/general/user/cb1319/home/anaconda3/envs/Geom3D/lib/python3.11/site-packages/lightning/pytorch/utilities/data.py:77: Trying to infer the `batch_size` from an ambiguous collection. The batch size we found is 7525. To avoid any miscalculations, use `self.log(..., batch_size=batch_size)`.\n",
      "/rds/general/user/cb1319/home/anaconda3/envs/Geom3D/lib/python3.11/site-packages/lightning/pytorch/utilities/data.py:77: Trying to infer the `batch_size` from an ambiguous collection. The batch size we found is 7663. To avoid any miscalculations, use `self.log(..., batch_size=batch_size)`.\n",
      "/rds/general/user/cb1319/home/anaconda3/envs/Geom3D/lib/python3.11/site-packages/lightning/pytorch/utilities/data.py:77: Trying to infer the `batch_size` from an ambiguous collection. The batch size we found is 7511. To avoid any miscalculations, use `self.log(..., batch_size=batch_size)`.\n",
      "/rds/general/user/cb1319/home/anaconda3/envs/Geom3D/lib/python3.11/site-packages/lightning/pytorch/utilities/data.py:77: Trying to infer the `batch_size` from an ambiguous collection. The batch size we found is 7704. To avoid any miscalculations, use `self.log(..., batch_size=batch_size)`.\n",
      "/rds/general/user/cb1319/home/anaconda3/envs/Geom3D/lib/python3.11/site-packages/lightning/pytorch/utilities/data.py:77: Trying to infer the `batch_size` from an ambiguous collection. The batch size we found is 7923. To avoid any miscalculations, use `self.log(..., batch_size=batch_size)`.\n",
      "/rds/general/user/cb1319/home/anaconda3/envs/Geom3D/lib/python3.11/site-packages/lightning/pytorch/utilities/data.py:77: Trying to infer the `batch_size` from an ambiguous collection. The batch size we found is 7681. To avoid any miscalculations, use `self.log(..., batch_size=batch_size)`.\n",
      "/rds/general/user/cb1319/home/anaconda3/envs/Geom3D/lib/python3.11/site-packages/lightning/pytorch/utilities/data.py:77: Trying to infer the `batch_size` from an ambiguous collection. The batch size we found is 7920. To avoid any miscalculations, use `self.log(..., batch_size=batch_size)`.\n",
      "/rds/general/user/cb1319/home/anaconda3/envs/Geom3D/lib/python3.11/site-packages/lightning/pytorch/utilities/data.py:77: Trying to infer the `batch_size` from an ambiguous collection. The batch size we found is 7356. To avoid any miscalculations, use `self.log(..., batch_size=batch_size)`.\n",
      "/rds/general/user/cb1319/home/anaconda3/envs/Geom3D/lib/python3.11/site-packages/lightning/pytorch/utilities/data.py:77: Trying to infer the `batch_size` from an ambiguous collection. The batch size we found is 7604. To avoid any miscalculations, use `self.log(..., batch_size=batch_size)`.\n",
      "/rds/general/user/cb1319/home/anaconda3/envs/Geom3D/lib/python3.11/site-packages/lightning/pytorch/utilities/data.py:77: Trying to infer the `batch_size` from an ambiguous collection. The batch size we found is 7740. To avoid any miscalculations, use `self.log(..., batch_size=batch_size)`.\n",
      "/rds/general/user/cb1319/home/anaconda3/envs/Geom3D/lib/python3.11/site-packages/lightning/pytorch/utilities/data.py:77: Trying to infer the `batch_size` from an ambiguous collection. The batch size we found is 8147. To avoid any miscalculations, use `self.log(..., batch_size=batch_size)`.\n",
      "/rds/general/user/cb1319/home/anaconda3/envs/Geom3D/lib/python3.11/site-packages/lightning/pytorch/utilities/data.py:77: Trying to infer the `batch_size` from an ambiguous collection. The batch size we found is 7450. To avoid any miscalculations, use `self.log(..., batch_size=batch_size)`.\n",
      "/rds/general/user/cb1319/home/anaconda3/envs/Geom3D/lib/python3.11/site-packages/lightning/pytorch/utilities/data.py:77: Trying to infer the `batch_size` from an ambiguous collection. The batch size we found is 7833. To avoid any miscalculations, use `self.log(..., batch_size=batch_size)`.\n",
      "/rds/general/user/cb1319/home/anaconda3/envs/Geom3D/lib/python3.11/site-packages/lightning/pytorch/utilities/data.py:77: Trying to infer the `batch_size` from an ambiguous collection. The batch size we found is 7963. To avoid any miscalculations, use `self.log(..., batch_size=batch_size)`.\n",
      "/rds/general/user/cb1319/home/anaconda3/envs/Geom3D/lib/python3.11/site-packages/lightning/pytorch/utilities/data.py:77: Trying to infer the `batch_size` from an ambiguous collection. The batch size we found is 7822. To avoid any miscalculations, use `self.log(..., batch_size=batch_size)`.\n",
      "/rds/general/user/cb1319/home/anaconda3/envs/Geom3D/lib/python3.11/site-packages/lightning/pytorch/utilities/data.py:77: Trying to infer the `batch_size` from an ambiguous collection. The batch size we found is 7786. To avoid any miscalculations, use `self.log(..., batch_size=batch_size)`.\n",
      "/rds/general/user/cb1319/home/anaconda3/envs/Geom3D/lib/python3.11/site-packages/lightning/pytorch/utilities/data.py:77: Trying to infer the `batch_size` from an ambiguous collection. The batch size we found is 7794. To avoid any miscalculations, use `self.log(..., batch_size=batch_size)`.\n",
      "/rds/general/user/cb1319/home/anaconda3/envs/Geom3D/lib/python3.11/site-packages/lightning/pytorch/utilities/data.py:77: Trying to infer the `batch_size` from an ambiguous collection. The batch size we found is 7654. To avoid any miscalculations, use `self.log(..., batch_size=batch_size)`.\n"
     ]
    },
    {
     "data": {
      "application/vnd.jupyter.widget-view+json": {
       "model_id": "780ee516c6ac48b5ba3b7af25e0acd4e",
       "version_major": 2,
       "version_minor": 0
      },
      "text/plain": [
       "Validation: |          | 0/? [00:00<?, ?it/s]"
      ]
     },
     "metadata": {},
     "output_type": "display_data"
    },
    {
     "name": "stderr",
     "output_type": "stream",
     "text": [
      "/rds/general/user/cb1319/home/anaconda3/envs/Geom3D/lib/python3.11/site-packages/lightning/pytorch/utilities/data.py:77: Trying to infer the `batch_size` from an ambiguous collection. The batch size we found is 7500. To avoid any miscalculations, use `self.log(..., batch_size=batch_size)`.\n",
      "/rds/general/user/cb1319/home/anaconda3/envs/Geom3D/lib/python3.11/site-packages/lightning/pytorch/utilities/data.py:77: Trying to infer the `batch_size` from an ambiguous collection. The batch size we found is 7895. To avoid any miscalculations, use `self.log(..., batch_size=batch_size)`.\n",
      "/rds/general/user/cb1319/home/anaconda3/envs/Geom3D/lib/python3.11/site-packages/lightning/pytorch/utilities/data.py:77: Trying to infer the `batch_size` from an ambiguous collection. The batch size we found is 7932. To avoid any miscalculations, use `self.log(..., batch_size=batch_size)`.\n",
      "/rds/general/user/cb1319/home/anaconda3/envs/Geom3D/lib/python3.11/site-packages/lightning/pytorch/utilities/data.py:77: Trying to infer the `batch_size` from an ambiguous collection. The batch size we found is 8100. To avoid any miscalculations, use `self.log(..., batch_size=batch_size)`.\n",
      "/rds/general/user/cb1319/home/anaconda3/envs/Geom3D/lib/python3.11/site-packages/lightning/pytorch/utilities/data.py:77: Trying to infer the `batch_size` from an ambiguous collection. The batch size we found is 7871. To avoid any miscalculations, use `self.log(..., batch_size=batch_size)`.\n",
      "/rds/general/user/cb1319/home/anaconda3/envs/Geom3D/lib/python3.11/site-packages/lightning/pytorch/utilities/data.py:77: Trying to infer the `batch_size` from an ambiguous collection. The batch size we found is 7791. To avoid any miscalculations, use `self.log(..., batch_size=batch_size)`.\n",
      "/rds/general/user/cb1319/home/anaconda3/envs/Geom3D/lib/python3.11/site-packages/lightning/pytorch/utilities/data.py:77: Trying to infer the `batch_size` from an ambiguous collection. The batch size we found is 7949. To avoid any miscalculations, use `self.log(..., batch_size=batch_size)`.\n",
      "/rds/general/user/cb1319/home/anaconda3/envs/Geom3D/lib/python3.11/site-packages/lightning/pytorch/utilities/data.py:77: Trying to infer the `batch_size` from an ambiguous collection. The batch size we found is 7693. To avoid any miscalculations, use `self.log(..., batch_size=batch_size)`.\n",
      "/rds/general/user/cb1319/home/anaconda3/envs/Geom3D/lib/python3.11/site-packages/lightning/pytorch/utilities/data.py:77: Trying to infer the `batch_size` from an ambiguous collection. The batch size we found is 7729. To avoid any miscalculations, use `self.log(..., batch_size=batch_size)`.\n",
      "/rds/general/user/cb1319/home/anaconda3/envs/Geom3D/lib/python3.11/site-packages/lightning/pytorch/utilities/data.py:77: Trying to infer the `batch_size` from an ambiguous collection. The batch size we found is 7864. To avoid any miscalculations, use `self.log(..., batch_size=batch_size)`.\n",
      "/rds/general/user/cb1319/home/anaconda3/envs/Geom3D/lib/python3.11/site-packages/lightning/pytorch/utilities/data.py:77: Trying to infer the `batch_size` from an ambiguous collection. The batch size we found is 7553. To avoid any miscalculations, use `self.log(..., batch_size=batch_size)`.\n",
      "/rds/general/user/cb1319/home/anaconda3/envs/Geom3D/lib/python3.11/site-packages/lightning/pytorch/utilities/data.py:77: Trying to infer the `batch_size` from an ambiguous collection. The batch size we found is 7343. To avoid any miscalculations, use `self.log(..., batch_size=batch_size)`.\n",
      "/rds/general/user/cb1319/home/anaconda3/envs/Geom3D/lib/python3.11/site-packages/lightning/pytorch/utilities/data.py:77: Trying to infer the `batch_size` from an ambiguous collection. The batch size we found is 7478. To avoid any miscalculations, use `self.log(..., batch_size=batch_size)`.\n",
      "/rds/general/user/cb1319/home/anaconda3/envs/Geom3D/lib/python3.11/site-packages/lightning/pytorch/utilities/data.py:77: Trying to infer the `batch_size` from an ambiguous collection. The batch size we found is 8005. To avoid any miscalculations, use `self.log(..., batch_size=batch_size)`.\n",
      "/rds/general/user/cb1319/home/anaconda3/envs/Geom3D/lib/python3.11/site-packages/lightning/pytorch/utilities/data.py:77: Trying to infer the `batch_size` from an ambiguous collection. The batch size we found is 7571. To avoid any miscalculations, use `self.log(..., batch_size=batch_size)`.\n",
      "/rds/general/user/cb1319/home/anaconda3/envs/Geom3D/lib/python3.11/site-packages/lightning/pytorch/utilities/data.py:77: Trying to infer the `batch_size` from an ambiguous collection. The batch size we found is 7475. To avoid any miscalculations, use `self.log(..., batch_size=batch_size)`.\n",
      "/rds/general/user/cb1319/home/anaconda3/envs/Geom3D/lib/python3.11/site-packages/lightning/pytorch/utilities/data.py:77: Trying to infer the `batch_size` from an ambiguous collection. The batch size we found is 7810. To avoid any miscalculations, use `self.log(..., batch_size=batch_size)`.\n",
      "/rds/general/user/cb1319/home/anaconda3/envs/Geom3D/lib/python3.11/site-packages/lightning/pytorch/utilities/data.py:77: Trying to infer the `batch_size` from an ambiguous collection. The batch size we found is 7616. To avoid any miscalculations, use `self.log(..., batch_size=batch_size)`.\n",
      "/rds/general/user/cb1319/home/anaconda3/envs/Geom3D/lib/python3.11/site-packages/lightning/pytorch/utilities/data.py:77: Trying to infer the `batch_size` from an ambiguous collection. The batch size we found is 7582. To avoid any miscalculations, use `self.log(..., batch_size=batch_size)`.\n",
      "/rds/general/user/cb1319/home/anaconda3/envs/Geom3D/lib/python3.11/site-packages/lightning/pytorch/utilities/data.py:77: Trying to infer the `batch_size` from an ambiguous collection. The batch size we found is 7700. To avoid any miscalculations, use `self.log(..., batch_size=batch_size)`.\n",
      "/rds/general/user/cb1319/home/anaconda3/envs/Geom3D/lib/python3.11/site-packages/lightning/pytorch/utilities/data.py:77: Trying to infer the `batch_size` from an ambiguous collection. The batch size we found is 8014. To avoid any miscalculations, use `self.log(..., batch_size=batch_size)`.\n",
      "/rds/general/user/cb1319/home/anaconda3/envs/Geom3D/lib/python3.11/site-packages/lightning/pytorch/utilities/data.py:77: Trying to infer the `batch_size` from an ambiguous collection. The batch size we found is 8040. To avoid any miscalculations, use `self.log(..., batch_size=batch_size)`.\n",
      "/rds/general/user/cb1319/home/anaconda3/envs/Geom3D/lib/python3.11/site-packages/lightning/pytorch/utilities/data.py:77: Trying to infer the `batch_size` from an ambiguous collection. The batch size we found is 7701. To avoid any miscalculations, use `self.log(..., batch_size=batch_size)`.\n",
      "/rds/general/user/cb1319/home/anaconda3/envs/Geom3D/lib/python3.11/site-packages/lightning/pytorch/utilities/data.py:77: Trying to infer the `batch_size` from an ambiguous collection. The batch size we found is 7862. To avoid any miscalculations, use `self.log(..., batch_size=batch_size)`.\n",
      "/rds/general/user/cb1319/home/anaconda3/envs/Geom3D/lib/python3.11/site-packages/lightning/pytorch/utilities/data.py:77: Trying to infer the `batch_size` from an ambiguous collection. The batch size we found is 8053. To avoid any miscalculations, use `self.log(..., batch_size=batch_size)`.\n",
      "/rds/general/user/cb1319/home/anaconda3/envs/Geom3D/lib/python3.11/site-packages/lightning/pytorch/utilities/data.py:77: Trying to infer the `batch_size` from an ambiguous collection. The batch size we found is 7766. To avoid any miscalculations, use `self.log(..., batch_size=batch_size)`.\n",
      "/rds/general/user/cb1319/home/anaconda3/envs/Geom3D/lib/python3.11/site-packages/lightning/pytorch/utilities/data.py:77: Trying to infer the `batch_size` from an ambiguous collection. The batch size we found is 7778. To avoid any miscalculations, use `self.log(..., batch_size=batch_size)`.\n",
      "/rds/general/user/cb1319/home/anaconda3/envs/Geom3D/lib/python3.11/site-packages/lightning/pytorch/utilities/data.py:77: Trying to infer the `batch_size` from an ambiguous collection. The batch size we found is 7876. To avoid any miscalculations, use `self.log(..., batch_size=batch_size)`.\n",
      "/rds/general/user/cb1319/home/anaconda3/envs/Geom3D/lib/python3.11/site-packages/lightning/pytorch/utilities/data.py:77: Trying to infer the `batch_size` from an ambiguous collection. The batch size we found is 8121. To avoid any miscalculations, use `self.log(..., batch_size=batch_size)`.\n",
      "/rds/general/user/cb1319/home/anaconda3/envs/Geom3D/lib/python3.11/site-packages/lightning/pytorch/utilities/data.py:77: Trying to infer the `batch_size` from an ambiguous collection. The batch size we found is 7748. To avoid any miscalculations, use `self.log(..., batch_size=batch_size)`.\n",
      "/rds/general/user/cb1319/home/anaconda3/envs/Geom3D/lib/python3.11/site-packages/lightning/pytorch/utilities/data.py:77: Trying to infer the `batch_size` from an ambiguous collection. The batch size we found is 7666. To avoid any miscalculations, use `self.log(..., batch_size=batch_size)`.\n",
      "/rds/general/user/cb1319/home/anaconda3/envs/Geom3D/lib/python3.11/site-packages/lightning/pytorch/utilities/data.py:77: Trying to infer the `batch_size` from an ambiguous collection. The batch size we found is 7809. To avoid any miscalculations, use `self.log(..., batch_size=batch_size)`.\n",
      "/rds/general/user/cb1319/home/anaconda3/envs/Geom3D/lib/python3.11/site-packages/lightning/pytorch/utilities/data.py:77: Trying to infer the `batch_size` from an ambiguous collection. The batch size we found is 7858. To avoid any miscalculations, use `self.log(..., batch_size=batch_size)`.\n",
      "/rds/general/user/cb1319/home/anaconda3/envs/Geom3D/lib/python3.11/site-packages/lightning/pytorch/utilities/data.py:77: Trying to infer the `batch_size` from an ambiguous collection. The batch size we found is 7859. To avoid any miscalculations, use `self.log(..., batch_size=batch_size)`.\n",
      "/rds/general/user/cb1319/home/anaconda3/envs/Geom3D/lib/python3.11/site-packages/lightning/pytorch/utilities/data.py:77: Trying to infer the `batch_size` from an ambiguous collection. The batch size we found is 7798. To avoid any miscalculations, use `self.log(..., batch_size=batch_size)`.\n",
      "/rds/general/user/cb1319/home/anaconda3/envs/Geom3D/lib/python3.11/site-packages/lightning/pytorch/utilities/data.py:77: Trying to infer the `batch_size` from an ambiguous collection. The batch size we found is 7904. To avoid any miscalculations, use `self.log(..., batch_size=batch_size)`.\n",
      "/rds/general/user/cb1319/home/anaconda3/envs/Geom3D/lib/python3.11/site-packages/lightning/pytorch/utilities/data.py:77: Trying to infer the `batch_size` from an ambiguous collection. The batch size we found is 8018. To avoid any miscalculations, use `self.log(..., batch_size=batch_size)`.\n",
      "/rds/general/user/cb1319/home/anaconda3/envs/Geom3D/lib/python3.11/site-packages/lightning/pytorch/utilities/data.py:77: Trying to infer the `batch_size` from an ambiguous collection. The batch size we found is 7618. To avoid any miscalculations, use `self.log(..., batch_size=batch_size)`.\n",
      "/rds/general/user/cb1319/home/anaconda3/envs/Geom3D/lib/python3.11/site-packages/lightning/pytorch/utilities/data.py:77: Trying to infer the `batch_size` from an ambiguous collection. The batch size we found is 7675. To avoid any miscalculations, use `self.log(..., batch_size=batch_size)`.\n",
      "/rds/general/user/cb1319/home/anaconda3/envs/Geom3D/lib/python3.11/site-packages/lightning/pytorch/utilities/data.py:77: Trying to infer the `batch_size` from an ambiguous collection. The batch size we found is 8222. To avoid any miscalculations, use `self.log(..., batch_size=batch_size)`.\n",
      "/rds/general/user/cb1319/home/anaconda3/envs/Geom3D/lib/python3.11/site-packages/lightning/pytorch/utilities/data.py:77: Trying to infer the `batch_size` from an ambiguous collection. The batch size we found is 8006. To avoid any miscalculations, use `self.log(..., batch_size=batch_size)`.\n",
      "/rds/general/user/cb1319/home/anaconda3/envs/Geom3D/lib/python3.11/site-packages/lightning/pytorch/utilities/data.py:77: Trying to infer the `batch_size` from an ambiguous collection. The batch size we found is 7902. To avoid any miscalculations, use `self.log(..., batch_size=batch_size)`.\n",
      "/rds/general/user/cb1319/home/anaconda3/envs/Geom3D/lib/python3.11/site-packages/lightning/pytorch/utilities/data.py:77: Trying to infer the `batch_size` from an ambiguous collection. The batch size we found is 7719. To avoid any miscalculations, use `self.log(..., batch_size=batch_size)`.\n",
      "/rds/general/user/cb1319/home/anaconda3/envs/Geom3D/lib/python3.11/site-packages/lightning/pytorch/utilities/data.py:77: Trying to infer the `batch_size` from an ambiguous collection. The batch size we found is 8001. To avoid any miscalculations, use `self.log(..., batch_size=batch_size)`.\n",
      "/rds/general/user/cb1319/home/anaconda3/envs/Geom3D/lib/python3.11/site-packages/lightning/pytorch/utilities/data.py:77: Trying to infer the `batch_size` from an ambiguous collection. The batch size we found is 7807. To avoid any miscalculations, use `self.log(..., batch_size=batch_size)`.\n",
      "/rds/general/user/cb1319/home/anaconda3/envs/Geom3D/lib/python3.11/site-packages/lightning/pytorch/utilities/data.py:77: Trying to infer the `batch_size` from an ambiguous collection. The batch size we found is 7437. To avoid any miscalculations, use `self.log(..., batch_size=batch_size)`.\n",
      "/rds/general/user/cb1319/home/anaconda3/envs/Geom3D/lib/python3.11/site-packages/lightning/pytorch/utilities/data.py:77: Trying to infer the `batch_size` from an ambiguous collection. The batch size we found is 7714. To avoid any miscalculations, use `self.log(..., batch_size=batch_size)`.\n",
      "/rds/general/user/cb1319/home/anaconda3/envs/Geom3D/lib/python3.11/site-packages/lightning/pytorch/utilities/data.py:77: Trying to infer the `batch_size` from an ambiguous collection. The batch size we found is 7787. To avoid any miscalculations, use `self.log(..., batch_size=batch_size)`.\n",
      "/rds/general/user/cb1319/home/anaconda3/envs/Geom3D/lib/python3.11/site-packages/lightning/pytorch/utilities/data.py:77: Trying to infer the `batch_size` from an ambiguous collection. The batch size we found is 7730. To avoid any miscalculations, use `self.log(..., batch_size=batch_size)`.\n",
      "/rds/general/user/cb1319/home/anaconda3/envs/Geom3D/lib/python3.11/site-packages/lightning/pytorch/utilities/data.py:77: Trying to infer the `batch_size` from an ambiguous collection. The batch size we found is 7905. To avoid any miscalculations, use `self.log(..., batch_size=batch_size)`.\n",
      "/rds/general/user/cb1319/home/anaconda3/envs/Geom3D/lib/python3.11/site-packages/lightning/pytorch/utilities/data.py:77: Trying to infer the `batch_size` from an ambiguous collection. The batch size we found is 7979. To avoid any miscalculations, use `self.log(..., batch_size=batch_size)`.\n",
      "/rds/general/user/cb1319/home/anaconda3/envs/Geom3D/lib/python3.11/site-packages/lightning/pytorch/utilities/data.py:77: Trying to infer the `batch_size` from an ambiguous collection. The batch size we found is 7836. To avoid any miscalculations, use `self.log(..., batch_size=batch_size)`.\n",
      "/rds/general/user/cb1319/home/anaconda3/envs/Geom3D/lib/python3.11/site-packages/lightning/pytorch/utilities/data.py:77: Trying to infer the `batch_size` from an ambiguous collection. The batch size we found is 8073. To avoid any miscalculations, use `self.log(..., batch_size=batch_size)`.\n",
      "/rds/general/user/cb1319/home/anaconda3/envs/Geom3D/lib/python3.11/site-packages/lightning/pytorch/utilities/data.py:77: Trying to infer the `batch_size` from an ambiguous collection. The batch size we found is 7884. To avoid any miscalculations, use `self.log(..., batch_size=batch_size)`.\n",
      "/rds/general/user/cb1319/home/anaconda3/envs/Geom3D/lib/python3.11/site-packages/lightning/pytorch/utilities/data.py:77: Trying to infer the `batch_size` from an ambiguous collection. The batch size we found is 7855. To avoid any miscalculations, use `self.log(..., batch_size=batch_size)`.\n",
      "/rds/general/user/cb1319/home/anaconda3/envs/Geom3D/lib/python3.11/site-packages/lightning/pytorch/utilities/data.py:77: Trying to infer the `batch_size` from an ambiguous collection. The batch size we found is 7476. To avoid any miscalculations, use `self.log(..., batch_size=batch_size)`.\n",
      "/rds/general/user/cb1319/home/anaconda3/envs/Geom3D/lib/python3.11/site-packages/lightning/pytorch/utilities/data.py:77: Trying to infer the `batch_size` from an ambiguous collection. The batch size we found is 7857. To avoid any miscalculations, use `self.log(..., batch_size=batch_size)`.\n",
      "/rds/general/user/cb1319/home/anaconda3/envs/Geom3D/lib/python3.11/site-packages/lightning/pytorch/utilities/data.py:77: Trying to infer the `batch_size` from an ambiguous collection. The batch size we found is 7504. To avoid any miscalculations, use `self.log(..., batch_size=batch_size)`.\n",
      "/rds/general/user/cb1319/home/anaconda3/envs/Geom3D/lib/python3.11/site-packages/lightning/pytorch/utilities/data.py:77: Trying to infer the `batch_size` from an ambiguous collection. The batch size we found is 7988. To avoid any miscalculations, use `self.log(..., batch_size=batch_size)`.\n",
      "/rds/general/user/cb1319/home/anaconda3/envs/Geom3D/lib/python3.11/site-packages/lightning/pytorch/utilities/data.py:77: Trying to infer the `batch_size` from an ambiguous collection. The batch size we found is 8212. To avoid any miscalculations, use `self.log(..., batch_size=batch_size)`.\n",
      "/rds/general/user/cb1319/home/anaconda3/envs/Geom3D/lib/python3.11/site-packages/lightning/pytorch/utilities/data.py:77: Trying to infer the `batch_size` from an ambiguous collection. The batch size we found is 7793. To avoid any miscalculations, use `self.log(..., batch_size=batch_size)`.\n",
      "/rds/general/user/cb1319/home/anaconda3/envs/Geom3D/lib/python3.11/site-packages/lightning/pytorch/utilities/data.py:77: Trying to infer the `batch_size` from an ambiguous collection. The batch size we found is 7900. To avoid any miscalculations, use `self.log(..., batch_size=batch_size)`.\n",
      "/rds/general/user/cb1319/home/anaconda3/envs/Geom3D/lib/python3.11/site-packages/lightning/pytorch/utilities/data.py:77: Trying to infer the `batch_size` from an ambiguous collection. The batch size we found is 7802. To avoid any miscalculations, use `self.log(..., batch_size=batch_size)`.\n",
      "/rds/general/user/cb1319/home/anaconda3/envs/Geom3D/lib/python3.11/site-packages/lightning/pytorch/utilities/data.py:77: Trying to infer the `batch_size` from an ambiguous collection. The batch size we found is 7523. To avoid any miscalculations, use `self.log(..., batch_size=batch_size)`.\n",
      "/rds/general/user/cb1319/home/anaconda3/envs/Geom3D/lib/python3.11/site-packages/lightning/pytorch/utilities/data.py:77: Trying to infer the `batch_size` from an ambiguous collection. The batch size we found is 7507. To avoid any miscalculations, use `self.log(..., batch_size=batch_size)`.\n",
      "/rds/general/user/cb1319/home/anaconda3/envs/Geom3D/lib/python3.11/site-packages/lightning/pytorch/utilities/data.py:77: Trying to infer the `batch_size` from an ambiguous collection. The batch size we found is 8273. To avoid any miscalculations, use `self.log(..., batch_size=batch_size)`.\n",
      "/rds/general/user/cb1319/home/anaconda3/envs/Geom3D/lib/python3.11/site-packages/lightning/pytorch/utilities/data.py:77: Trying to infer the `batch_size` from an ambiguous collection. The batch size we found is 7936. To avoid any miscalculations, use `self.log(..., batch_size=batch_size)`.\n",
      "/rds/general/user/cb1319/home/anaconda3/envs/Geom3D/lib/python3.11/site-packages/lightning/pytorch/utilities/data.py:77: Trying to infer the `batch_size` from an ambiguous collection. The batch size we found is 7743. To avoid any miscalculations, use `self.log(..., batch_size=batch_size)`.\n",
      "/rds/general/user/cb1319/home/anaconda3/envs/Geom3D/lib/python3.11/site-packages/lightning/pytorch/utilities/data.py:77: Trying to infer the `batch_size` from an ambiguous collection. The batch size we found is 7751. To avoid any miscalculations, use `self.log(..., batch_size=batch_size)`.\n",
      "/rds/general/user/cb1319/home/anaconda3/envs/Geom3D/lib/python3.11/site-packages/lightning/pytorch/utilities/data.py:77: Trying to infer the `batch_size` from an ambiguous collection. The batch size we found is 7722. To avoid any miscalculations, use `self.log(..., batch_size=batch_size)`.\n",
      "/rds/general/user/cb1319/home/anaconda3/envs/Geom3D/lib/python3.11/site-packages/lightning/pytorch/utilities/data.py:77: Trying to infer the `batch_size` from an ambiguous collection. The batch size we found is 8049. To avoid any miscalculations, use `self.log(..., batch_size=batch_size)`.\n",
      "/rds/general/user/cb1319/home/anaconda3/envs/Geom3D/lib/python3.11/site-packages/lightning/pytorch/utilities/data.py:77: Trying to infer the `batch_size` from an ambiguous collection. The batch size we found is 7607. To avoid any miscalculations, use `self.log(..., batch_size=batch_size)`.\n"
     ]
    },
    {
     "data": {
      "application/vnd.jupyter.widget-view+json": {
       "model_id": "6eb336d9e0a943ccbc2332ee00277bd9",
       "version_major": 2,
       "version_minor": 0
      },
      "text/plain": [
       "Validation: |          | 0/? [00:00<?, ?it/s]"
      ]
     },
     "metadata": {},
     "output_type": "display_data"
    },
    {
     "name": "stderr",
     "output_type": "stream",
     "text": [
      "/rds/general/user/cb1319/home/anaconda3/envs/Geom3D/lib/python3.11/site-packages/lightning/pytorch/utilities/data.py:77: Trying to infer the `batch_size` from an ambiguous collection. The batch size we found is 7710. To avoid any miscalculations, use `self.log(..., batch_size=batch_size)`.\n",
      "/rds/general/user/cb1319/home/anaconda3/envs/Geom3D/lib/python3.11/site-packages/lightning/pytorch/utilities/data.py:77: Trying to infer the `batch_size` from an ambiguous collection. The batch size we found is 7670. To avoid any miscalculations, use `self.log(..., batch_size=batch_size)`.\n",
      "/rds/general/user/cb1319/home/anaconda3/envs/Geom3D/lib/python3.11/site-packages/lightning/pytorch/utilities/data.py:77: Trying to infer the `batch_size` from an ambiguous collection. The batch size we found is 8154. To avoid any miscalculations, use `self.log(..., batch_size=batch_size)`.\n",
      "/rds/general/user/cb1319/home/anaconda3/envs/Geom3D/lib/python3.11/site-packages/lightning/pytorch/utilities/data.py:77: Trying to infer the `batch_size` from an ambiguous collection. The batch size we found is 8011. To avoid any miscalculations, use `self.log(..., batch_size=batch_size)`.\n",
      "/rds/general/user/cb1319/home/anaconda3/envs/Geom3D/lib/python3.11/site-packages/lightning/pytorch/utilities/data.py:77: Trying to infer the `batch_size` from an ambiguous collection. The batch size we found is 7847. To avoid any miscalculations, use `self.log(..., batch_size=batch_size)`.\n",
      "/rds/general/user/cb1319/home/anaconda3/envs/Geom3D/lib/python3.11/site-packages/lightning/pytorch/utilities/data.py:77: Trying to infer the `batch_size` from an ambiguous collection. The batch size we found is 8271. To avoid any miscalculations, use `self.log(..., batch_size=batch_size)`.\n",
      "/rds/general/user/cb1319/home/anaconda3/envs/Geom3D/lib/python3.11/site-packages/lightning/pytorch/utilities/data.py:77: Trying to infer the `batch_size` from an ambiguous collection. The batch size we found is 7752. To avoid any miscalculations, use `self.log(..., batch_size=batch_size)`.\n",
      "/rds/general/user/cb1319/home/anaconda3/envs/Geom3D/lib/python3.11/site-packages/lightning/pytorch/utilities/data.py:77: Trying to infer the `batch_size` from an ambiguous collection. The batch size we found is 7631. To avoid any miscalculations, use `self.log(..., batch_size=batch_size)`.\n",
      "/rds/general/user/cb1319/home/anaconda3/envs/Geom3D/lib/python3.11/site-packages/lightning/pytorch/utilities/data.py:77: Trying to infer the `batch_size` from an ambiguous collection. The batch size we found is 7946. To avoid any miscalculations, use `self.log(..., batch_size=batch_size)`.\n",
      "/rds/general/user/cb1319/home/anaconda3/envs/Geom3D/lib/python3.11/site-packages/lightning/pytorch/utilities/data.py:77: Trying to infer the `batch_size` from an ambiguous collection. The batch size we found is 8035. To avoid any miscalculations, use `self.log(..., batch_size=batch_size)`.\n",
      "/rds/general/user/cb1319/home/anaconda3/envs/Geom3D/lib/python3.11/site-packages/lightning/pytorch/utilities/data.py:77: Trying to infer the `batch_size` from an ambiguous collection. The batch size we found is 7896. To avoid any miscalculations, use `self.log(..., batch_size=batch_size)`.\n",
      "/rds/general/user/cb1319/home/anaconda3/envs/Geom3D/lib/python3.11/site-packages/lightning/pytorch/utilities/data.py:77: Trying to infer the `batch_size` from an ambiguous collection. The batch size we found is 7721. To avoid any miscalculations, use `self.log(..., batch_size=batch_size)`.\n",
      "/rds/general/user/cb1319/home/anaconda3/envs/Geom3D/lib/python3.11/site-packages/lightning/pytorch/utilities/data.py:77: Trying to infer the `batch_size` from an ambiguous collection. The batch size we found is 7454. To avoid any miscalculations, use `self.log(..., batch_size=batch_size)`.\n",
      "/rds/general/user/cb1319/home/anaconda3/envs/Geom3D/lib/python3.11/site-packages/lightning/pytorch/utilities/data.py:77: Trying to infer the `batch_size` from an ambiguous collection. The batch size we found is 7749. To avoid any miscalculations, use `self.log(..., batch_size=batch_size)`.\n",
      "/rds/general/user/cb1319/home/anaconda3/envs/Geom3D/lib/python3.11/site-packages/lightning/pytorch/utilities/data.py:77: Trying to infer the `batch_size` from an ambiguous collection. The batch size we found is 7661. To avoid any miscalculations, use `self.log(..., batch_size=batch_size)`.\n",
      "/rds/general/user/cb1319/home/anaconda3/envs/Geom3D/lib/python3.11/site-packages/lightning/pytorch/utilities/data.py:77: Trying to infer the `batch_size` from an ambiguous collection. The batch size we found is 7659. To avoid any miscalculations, use `self.log(..., batch_size=batch_size)`.\n",
      "/rds/general/user/cb1319/home/anaconda3/envs/Geom3D/lib/python3.11/site-packages/lightning/pytorch/utilities/data.py:77: Trying to infer the `batch_size` from an ambiguous collection. The batch size we found is 7712. To avoid any miscalculations, use `self.log(..., batch_size=batch_size)`.\n",
      "/rds/general/user/cb1319/home/anaconda3/envs/Geom3D/lib/python3.11/site-packages/lightning/pytorch/utilities/data.py:77: Trying to infer the `batch_size` from an ambiguous collection. The batch size we found is 7765. To avoid any miscalculations, use `self.log(..., batch_size=batch_size)`.\n",
      "/rds/general/user/cb1319/home/anaconda3/envs/Geom3D/lib/python3.11/site-packages/lightning/pytorch/utilities/data.py:77: Trying to infer the `batch_size` from an ambiguous collection. The batch size we found is 7554. To avoid any miscalculations, use `self.log(..., batch_size=batch_size)`.\n",
      "/rds/general/user/cb1319/home/anaconda3/envs/Geom3D/lib/python3.11/site-packages/lightning/pytorch/utilities/data.py:77: Trying to infer the `batch_size` from an ambiguous collection. The batch size we found is 7611. To avoid any miscalculations, use `self.log(..., batch_size=batch_size)`.\n",
      "/rds/general/user/cb1319/home/anaconda3/envs/Geom3D/lib/python3.11/site-packages/lightning/pytorch/utilities/data.py:77: Trying to infer the `batch_size` from an ambiguous collection. The batch size we found is 8150. To avoid any miscalculations, use `self.log(..., batch_size=batch_size)`.\n",
      "/rds/general/user/cb1319/home/anaconda3/envs/Geom3D/lib/python3.11/site-packages/lightning/pytorch/utilities/data.py:77: Trying to infer the `batch_size` from an ambiguous collection. The batch size we found is 7562. To avoid any miscalculations, use `self.log(..., batch_size=batch_size)`.\n",
      "/rds/general/user/cb1319/home/anaconda3/envs/Geom3D/lib/python3.11/site-packages/lightning/pytorch/utilities/data.py:77: Trying to infer the `batch_size` from an ambiguous collection. The batch size we found is 7953. To avoid any miscalculations, use `self.log(..., batch_size=batch_size)`.\n",
      "/rds/general/user/cb1319/home/anaconda3/envs/Geom3D/lib/python3.11/site-packages/lightning/pytorch/utilities/data.py:77: Trying to infer the `batch_size` from an ambiguous collection. The batch size we found is 7276. To avoid any miscalculations, use `self.log(..., batch_size=batch_size)`.\n",
      "/rds/general/user/cb1319/home/anaconda3/envs/Geom3D/lib/python3.11/site-packages/lightning/pytorch/utilities/data.py:77: Trying to infer the `batch_size` from an ambiguous collection. The batch size we found is 7950. To avoid any miscalculations, use `self.log(..., batch_size=batch_size)`.\n",
      "/rds/general/user/cb1319/home/anaconda3/envs/Geom3D/lib/python3.11/site-packages/lightning/pytorch/utilities/data.py:77: Trying to infer the `batch_size` from an ambiguous collection. The batch size we found is 7803. To avoid any miscalculations, use `self.log(..., batch_size=batch_size)`.\n",
      "/rds/general/user/cb1319/home/anaconda3/envs/Geom3D/lib/python3.11/site-packages/lightning/pytorch/utilities/data.py:77: Trying to infer the `batch_size` from an ambiguous collection. The batch size we found is 7995. To avoid any miscalculations, use `self.log(..., batch_size=batch_size)`.\n",
      "/rds/general/user/cb1319/home/anaconda3/envs/Geom3D/lib/python3.11/site-packages/lightning/pytorch/utilities/data.py:77: Trying to infer the `batch_size` from an ambiguous collection. The batch size we found is 7423. To avoid any miscalculations, use `self.log(..., batch_size=batch_size)`.\n",
      "/rds/general/user/cb1319/home/anaconda3/envs/Geom3D/lib/python3.11/site-packages/lightning/pytorch/utilities/data.py:77: Trying to infer the `batch_size` from an ambiguous collection. The batch size we found is 7449. To avoid any miscalculations, use `self.log(..., batch_size=batch_size)`.\n",
      "/rds/general/user/cb1319/home/anaconda3/envs/Geom3D/lib/python3.11/site-packages/lightning/pytorch/utilities/data.py:77: Trying to infer the `batch_size` from an ambiguous collection. The batch size we found is 7824. To avoid any miscalculations, use `self.log(..., batch_size=batch_size)`.\n",
      "/rds/general/user/cb1319/home/anaconda3/envs/Geom3D/lib/python3.11/site-packages/lightning/pytorch/utilities/data.py:77: Trying to infer the `batch_size` from an ambiguous collection. The batch size we found is 7799. To avoid any miscalculations, use `self.log(..., batch_size=batch_size)`.\n",
      "/rds/general/user/cb1319/home/anaconda3/envs/Geom3D/lib/python3.11/site-packages/lightning/pytorch/utilities/data.py:77: Trying to infer the `batch_size` from an ambiguous collection. The batch size we found is 7872. To avoid any miscalculations, use `self.log(..., batch_size=batch_size)`.\n",
      "/rds/general/user/cb1319/home/anaconda3/envs/Geom3D/lib/python3.11/site-packages/lightning/pytorch/utilities/data.py:77: Trying to infer the `batch_size` from an ambiguous collection. The batch size we found is 8229. To avoid any miscalculations, use `self.log(..., batch_size=batch_size)`.\n",
      "/rds/general/user/cb1319/home/anaconda3/envs/Geom3D/lib/python3.11/site-packages/lightning/pytorch/utilities/data.py:77: Trying to infer the `batch_size` from an ambiguous collection. The batch size we found is 7578. To avoid any miscalculations, use `self.log(..., batch_size=batch_size)`.\n",
      "/rds/general/user/cb1319/home/anaconda3/envs/Geom3D/lib/python3.11/site-packages/lightning/pytorch/utilities/data.py:77: Trying to infer the `batch_size` from an ambiguous collection. The batch size we found is 8032. To avoid any miscalculations, use `self.log(..., batch_size=batch_size)`.\n",
      "/rds/general/user/cb1319/home/anaconda3/envs/Geom3D/lib/python3.11/site-packages/lightning/pytorch/utilities/data.py:77: Trying to infer the `batch_size` from an ambiguous collection. The batch size we found is 7548. To avoid any miscalculations, use `self.log(..., batch_size=batch_size)`.\n",
      "/rds/general/user/cb1319/home/anaconda3/envs/Geom3D/lib/python3.11/site-packages/lightning/pytorch/utilities/data.py:77: Trying to infer the `batch_size` from an ambiguous collection. The batch size we found is 7350. To avoid any miscalculations, use `self.log(..., batch_size=batch_size)`.\n",
      "/rds/general/user/cb1319/home/anaconda3/envs/Geom3D/lib/python3.11/site-packages/lightning/pytorch/utilities/data.py:77: Trying to infer the `batch_size` from an ambiguous collection. The batch size we found is 8033. To avoid any miscalculations, use `self.log(..., batch_size=batch_size)`.\n",
      "/rds/general/user/cb1319/home/anaconda3/envs/Geom3D/lib/python3.11/site-packages/lightning/pytorch/utilities/data.py:77: Trying to infer the `batch_size` from an ambiguous collection. The batch size we found is 7676. To avoid any miscalculations, use `self.log(..., batch_size=batch_size)`.\n",
      "/rds/general/user/cb1319/home/anaconda3/envs/Geom3D/lib/python3.11/site-packages/lightning/pytorch/utilities/data.py:77: Trying to infer the `batch_size` from an ambiguous collection. The batch size we found is 7588. To avoid any miscalculations, use `self.log(..., batch_size=batch_size)`.\n",
      "/rds/general/user/cb1319/home/anaconda3/envs/Geom3D/lib/python3.11/site-packages/lightning/pytorch/utilities/data.py:77: Trying to infer the `batch_size` from an ambiguous collection. The batch size we found is 7888. To avoid any miscalculations, use `self.log(..., batch_size=batch_size)`.\n",
      "/rds/general/user/cb1319/home/anaconda3/envs/Geom3D/lib/python3.11/site-packages/lightning/pytorch/utilities/data.py:77: Trying to infer the `batch_size` from an ambiguous collection. The batch size we found is 8131. To avoid any miscalculations, use `self.log(..., batch_size=batch_size)`.\n",
      "/rds/general/user/cb1319/home/anaconda3/envs/Geom3D/lib/python3.11/site-packages/lightning/pytorch/utilities/data.py:77: Trying to infer the `batch_size` from an ambiguous collection. The batch size we found is 7848. To avoid any miscalculations, use `self.log(..., batch_size=batch_size)`.\n",
      "/rds/general/user/cb1319/home/anaconda3/envs/Geom3D/lib/python3.11/site-packages/lightning/pytorch/utilities/data.py:77: Trying to infer the `batch_size` from an ambiguous collection. The batch size we found is 7717. To avoid any miscalculations, use `self.log(..., batch_size=batch_size)`.\n",
      "/rds/general/user/cb1319/home/anaconda3/envs/Geom3D/lib/python3.11/site-packages/lightning/pytorch/utilities/data.py:77: Trying to infer the `batch_size` from an ambiguous collection. The batch size we found is 7846. To avoid any miscalculations, use `self.log(..., batch_size=batch_size)`.\n",
      "/rds/general/user/cb1319/home/anaconda3/envs/Geom3D/lib/python3.11/site-packages/lightning/pytorch/utilities/data.py:77: Trying to infer the `batch_size` from an ambiguous collection. The batch size we found is 8022. To avoid any miscalculations, use `self.log(..., batch_size=batch_size)`.\n",
      "/rds/general/user/cb1319/home/anaconda3/envs/Geom3D/lib/python3.11/site-packages/lightning/pytorch/utilities/data.py:77: Trying to infer the `batch_size` from an ambiguous collection. The batch size we found is 7644. To avoid any miscalculations, use `self.log(..., batch_size=batch_size)`.\n",
      "/rds/general/user/cb1319/home/anaconda3/envs/Geom3D/lib/python3.11/site-packages/lightning/pytorch/utilities/data.py:77: Trying to infer the `batch_size` from an ambiguous collection. The batch size we found is 7971. To avoid any miscalculations, use `self.log(..., batch_size=batch_size)`.\n",
      "/rds/general/user/cb1319/home/anaconda3/envs/Geom3D/lib/python3.11/site-packages/lightning/pytorch/utilities/data.py:77: Trying to infer the `batch_size` from an ambiguous collection. The batch size we found is 7379. To avoid any miscalculations, use `self.log(..., batch_size=batch_size)`.\n",
      "/rds/general/user/cb1319/home/anaconda3/envs/Geom3D/lib/python3.11/site-packages/lightning/pytorch/utilities/data.py:77: Trying to infer the `batch_size` from an ambiguous collection. The batch size we found is 8015. To avoid any miscalculations, use `self.log(..., batch_size=batch_size)`.\n",
      "/rds/general/user/cb1319/home/anaconda3/envs/Geom3D/lib/python3.11/site-packages/lightning/pytorch/utilities/data.py:77: Trying to infer the `batch_size` from an ambiguous collection. The batch size we found is 8077. To avoid any miscalculations, use `self.log(..., batch_size=batch_size)`.\n",
      "/rds/general/user/cb1319/home/anaconda3/envs/Geom3D/lib/python3.11/site-packages/lightning/pytorch/utilities/data.py:77: Trying to infer the `batch_size` from an ambiguous collection. The batch size we found is 8133. To avoid any miscalculations, use `self.log(..., batch_size=batch_size)`.\n",
      "/rds/general/user/cb1319/home/anaconda3/envs/Geom3D/lib/python3.11/site-packages/lightning/pytorch/utilities/data.py:77: Trying to infer the `batch_size` from an ambiguous collection. The batch size we found is 7992. To avoid any miscalculations, use `self.log(..., batch_size=batch_size)`.\n",
      "/rds/general/user/cb1319/home/anaconda3/envs/Geom3D/lib/python3.11/site-packages/lightning/pytorch/utilities/data.py:77: Trying to infer the `batch_size` from an ambiguous collection. The batch size we found is 7393. To avoid any miscalculations, use `self.log(..., batch_size=batch_size)`.\n",
      "/rds/general/user/cb1319/home/anaconda3/envs/Geom3D/lib/python3.11/site-packages/lightning/pytorch/utilities/data.py:77: Trying to infer the `batch_size` from an ambiguous collection. The batch size we found is 7805. To avoid any miscalculations, use `self.log(..., batch_size=batch_size)`.\n",
      "/rds/general/user/cb1319/home/anaconda3/envs/Geom3D/lib/python3.11/site-packages/lightning/pytorch/utilities/data.py:77: Trying to infer the `batch_size` from an ambiguous collection. The batch size we found is 7697. To avoid any miscalculations, use `self.log(..., batch_size=batch_size)`.\n",
      "/rds/general/user/cb1319/home/anaconda3/envs/Geom3D/lib/python3.11/site-packages/lightning/pytorch/utilities/data.py:77: Trying to infer the `batch_size` from an ambiguous collection. The batch size we found is 7840. To avoid any miscalculations, use `self.log(..., batch_size=batch_size)`.\n",
      "/rds/general/user/cb1319/home/anaconda3/envs/Geom3D/lib/python3.11/site-packages/lightning/pytorch/utilities/data.py:77: Trying to infer the `batch_size` from an ambiguous collection. The batch size we found is 7558. To avoid any miscalculations, use `self.log(..., batch_size=batch_size)`.\n",
      "/rds/general/user/cb1319/home/anaconda3/envs/Geom3D/lib/python3.11/site-packages/lightning/pytorch/utilities/data.py:77: Trying to infer the `batch_size` from an ambiguous collection. The batch size we found is 7615. To avoid any miscalculations, use `self.log(..., batch_size=batch_size)`.\n",
      "/rds/general/user/cb1319/home/anaconda3/envs/Geom3D/lib/python3.11/site-packages/lightning/pytorch/utilities/data.py:77: Trying to infer the `batch_size` from an ambiguous collection. The batch size we found is 8248. To avoid any miscalculations, use `self.log(..., batch_size=batch_size)`.\n",
      "/rds/general/user/cb1319/home/anaconda3/envs/Geom3D/lib/python3.11/site-packages/lightning/pytorch/utilities/data.py:77: Trying to infer the `batch_size` from an ambiguous collection. The batch size we found is 7648. To avoid any miscalculations, use `self.log(..., batch_size=batch_size)`.\n",
      "/rds/general/user/cb1319/home/anaconda3/envs/Geom3D/lib/python3.11/site-packages/lightning/pytorch/utilities/data.py:77: Trying to infer the `batch_size` from an ambiguous collection. The batch size we found is 7830. To avoid any miscalculations, use `self.log(..., batch_size=batch_size)`.\n",
      "/rds/general/user/cb1319/home/anaconda3/envs/Geom3D/lib/python3.11/site-packages/lightning/pytorch/utilities/data.py:77: Trying to infer the `batch_size` from an ambiguous collection. The batch size we found is 7853. To avoid any miscalculations, use `self.log(..., batch_size=batch_size)`.\n",
      "/rds/general/user/cb1319/home/anaconda3/envs/Geom3D/lib/python3.11/site-packages/lightning/pytorch/utilities/data.py:77: Trying to infer the `batch_size` from an ambiguous collection. The batch size we found is 7827. To avoid any miscalculations, use `self.log(..., batch_size=batch_size)`.\n",
      "/rds/general/user/cb1319/home/anaconda3/envs/Geom3D/lib/python3.11/site-packages/lightning/pytorch/utilities/data.py:77: Trying to infer the `batch_size` from an ambiguous collection. The batch size we found is 7682. To avoid any miscalculations, use `self.log(..., batch_size=batch_size)`.\n",
      "/rds/general/user/cb1319/home/anaconda3/envs/Geom3D/lib/python3.11/site-packages/lightning/pytorch/utilities/data.py:77: Trying to infer the `batch_size` from an ambiguous collection. The batch size we found is 8170. To avoid any miscalculations, use `self.log(..., batch_size=batch_size)`.\n",
      "/rds/general/user/cb1319/home/anaconda3/envs/Geom3D/lib/python3.11/site-packages/lightning/pytorch/utilities/data.py:77: Trying to infer the `batch_size` from an ambiguous collection. The batch size we found is 7894. To avoid any miscalculations, use `self.log(..., batch_size=batch_size)`.\n",
      "/rds/general/user/cb1319/home/anaconda3/envs/Geom3D/lib/python3.11/site-packages/lightning/pytorch/utilities/data.py:77: Trying to infer the `batch_size` from an ambiguous collection. The batch size we found is 7627. To avoid any miscalculations, use `self.log(..., batch_size=batch_size)`.\n",
      "/rds/general/user/cb1319/home/anaconda3/envs/Geom3D/lib/python3.11/site-packages/lightning/pytorch/utilities/data.py:77: Trying to infer the `batch_size` from an ambiguous collection. The batch size we found is 7917. To avoid any miscalculations, use `self.log(..., batch_size=batch_size)`.\n",
      "/rds/general/user/cb1319/home/anaconda3/envs/Geom3D/lib/python3.11/site-packages/lightning/pytorch/utilities/data.py:77: Trying to infer the `batch_size` from an ambiguous collection. The batch size we found is 8423. To avoid any miscalculations, use `self.log(..., batch_size=batch_size)`.\n",
      "/rds/general/user/cb1319/home/anaconda3/envs/Geom3D/lib/python3.11/site-packages/lightning/pytorch/utilities/data.py:77: Trying to infer the `batch_size` from an ambiguous collection. The batch size we found is 7754. To avoid any miscalculations, use `self.log(..., batch_size=batch_size)`.\n",
      "/rds/general/user/cb1319/home/anaconda3/envs/Geom3D/lib/python3.11/site-packages/lightning/pytorch/utilities/data.py:77: Trying to infer the `batch_size` from an ambiguous collection. The batch size we found is 7867. To avoid any miscalculations, use `self.log(..., batch_size=batch_size)`.\n"
     ]
    },
    {
     "data": {
      "application/vnd.jupyter.widget-view+json": {
       "model_id": "21461ade23e0494a8c59b26cd66a392a",
       "version_major": 2,
       "version_minor": 0
      },
      "text/plain": [
       "Validation: |          | 0/? [00:00<?, ?it/s]"
      ]
     },
     "metadata": {},
     "output_type": "display_data"
    },
    {
     "name": "stderr",
     "output_type": "stream",
     "text": [
      "/rds/general/user/cb1319/home/anaconda3/envs/Geom3D/lib/python3.11/site-packages/lightning/pytorch/utilities/data.py:77: Trying to infer the `batch_size` from an ambiguous collection. The batch size we found is 7910. To avoid any miscalculations, use `self.log(..., batch_size=batch_size)`.\n",
      "/rds/general/user/cb1319/home/anaconda3/envs/Geom3D/lib/python3.11/site-packages/lightning/pytorch/utilities/data.py:77: Trying to infer the `batch_size` from an ambiguous collection. The batch size we found is 7494. To avoid any miscalculations, use `self.log(..., batch_size=batch_size)`.\n",
      "/rds/general/user/cb1319/home/anaconda3/envs/Geom3D/lib/python3.11/site-packages/lightning/pytorch/utilities/data.py:77: Trying to infer the `batch_size` from an ambiguous collection. The batch size we found is 7464. To avoid any miscalculations, use `self.log(..., batch_size=batch_size)`.\n",
      "/rds/general/user/cb1319/home/anaconda3/envs/Geom3D/lib/python3.11/site-packages/lightning/pytorch/utilities/data.py:77: Trying to infer the `batch_size` from an ambiguous collection. The batch size we found is 7655. To avoid any miscalculations, use `self.log(..., batch_size=batch_size)`.\n",
      "/rds/general/user/cb1319/home/anaconda3/envs/Geom3D/lib/python3.11/site-packages/lightning/pytorch/utilities/data.py:77: Trying to infer the `batch_size` from an ambiguous collection. The batch size we found is 8108. To avoid any miscalculations, use `self.log(..., batch_size=batch_size)`.\n",
      "/rds/general/user/cb1319/home/anaconda3/envs/Geom3D/lib/python3.11/site-packages/lightning/pytorch/utilities/data.py:77: Trying to infer the `batch_size` from an ambiguous collection. The batch size we found is 7724. To avoid any miscalculations, use `self.log(..., batch_size=batch_size)`.\n",
      "/rds/general/user/cb1319/home/anaconda3/envs/Geom3D/lib/python3.11/site-packages/lightning/pytorch/utilities/data.py:77: Trying to infer the `batch_size` from an ambiguous collection. The batch size we found is 7544. To avoid any miscalculations, use `self.log(..., batch_size=batch_size)`.\n",
      "/rds/general/user/cb1319/home/anaconda3/envs/Geom3D/lib/python3.11/site-packages/lightning/pytorch/utilities/data.py:77: Trying to infer the `batch_size` from an ambiguous collection. The batch size we found is 7726. To avoid any miscalculations, use `self.log(..., batch_size=batch_size)`.\n",
      "/rds/general/user/cb1319/home/anaconda3/envs/Geom3D/lib/python3.11/site-packages/lightning/pytorch/utilities/data.py:77: Trying to infer the `batch_size` from an ambiguous collection. The batch size we found is 7964. To avoid any miscalculations, use `self.log(..., batch_size=batch_size)`.\n",
      "/rds/general/user/cb1319/home/anaconda3/envs/Geom3D/lib/python3.11/site-packages/lightning/pytorch/utilities/data.py:77: Trying to infer the `batch_size` from an ambiguous collection. The batch size we found is 8093. To avoid any miscalculations, use `self.log(..., batch_size=batch_size)`.\n",
      "/rds/general/user/cb1319/home/anaconda3/envs/Geom3D/lib/python3.11/site-packages/lightning/pytorch/utilities/data.py:77: Trying to infer the `batch_size` from an ambiguous collection. The batch size we found is 7941. To avoid any miscalculations, use `self.log(..., batch_size=batch_size)`.\n",
      "/rds/general/user/cb1319/home/anaconda3/envs/Geom3D/lib/python3.11/site-packages/lightning/pytorch/utilities/data.py:77: Trying to infer the `batch_size` from an ambiguous collection. The batch size we found is 7804. To avoid any miscalculations, use `self.log(..., batch_size=batch_size)`.\n",
      "/rds/general/user/cb1319/home/anaconda3/envs/Geom3D/lib/python3.11/site-packages/lightning/pytorch/utilities/data.py:77: Trying to infer the `batch_size` from an ambiguous collection. The batch size we found is 7492. To avoid any miscalculations, use `self.log(..., batch_size=batch_size)`.\n",
      "/rds/general/user/cb1319/home/anaconda3/envs/Geom3D/lib/python3.11/site-packages/lightning/pytorch/utilities/data.py:77: Trying to infer the `batch_size` from an ambiguous collection. The batch size we found is 7517. To avoid any miscalculations, use `self.log(..., batch_size=batch_size)`.\n",
      "/rds/general/user/cb1319/home/anaconda3/envs/Geom3D/lib/python3.11/site-packages/lightning/pytorch/utilities/data.py:77: Trying to infer the `batch_size` from an ambiguous collection. The batch size we found is 7747. To avoid any miscalculations, use `self.log(..., batch_size=batch_size)`.\n",
      "/rds/general/user/cb1319/home/anaconda3/envs/Geom3D/lib/python3.11/site-packages/lightning/pytorch/utilities/data.py:77: Trying to infer the `batch_size` from an ambiguous collection. The batch size we found is 8091. To avoid any miscalculations, use `self.log(..., batch_size=batch_size)`.\n",
      "/rds/general/user/cb1319/home/anaconda3/envs/Geom3D/lib/python3.11/site-packages/lightning/pytorch/utilities/data.py:77: Trying to infer the `batch_size` from an ambiguous collection. The batch size we found is 8028. To avoid any miscalculations, use `self.log(..., batch_size=batch_size)`.\n",
      "/rds/general/user/cb1319/home/anaconda3/envs/Geom3D/lib/python3.11/site-packages/lightning/pytorch/utilities/data.py:77: Trying to infer the `batch_size` from an ambiguous collection. The batch size we found is 7955. To avoid any miscalculations, use `self.log(..., batch_size=batch_size)`.\n",
      "/rds/general/user/cb1319/home/anaconda3/envs/Geom3D/lib/python3.11/site-packages/lightning/pytorch/utilities/data.py:77: Trying to infer the `batch_size` from an ambiguous collection. The batch size we found is 7408. To avoid any miscalculations, use `self.log(..., batch_size=batch_size)`.\n",
      "/rds/general/user/cb1319/home/anaconda3/envs/Geom3D/lib/python3.11/site-packages/lightning/pytorch/utilities/data.py:77: Trying to infer the `batch_size` from an ambiguous collection. The batch size we found is 7684. To avoid any miscalculations, use `self.log(..., batch_size=batch_size)`.\n",
      "/rds/general/user/cb1319/home/anaconda3/envs/Geom3D/lib/python3.11/site-packages/lightning/pytorch/utilities/data.py:77: Trying to infer the `batch_size` from an ambiguous collection. The batch size we found is 7583. To avoid any miscalculations, use `self.log(..., batch_size=batch_size)`.\n",
      "/rds/general/user/cb1319/home/anaconda3/envs/Geom3D/lib/python3.11/site-packages/lightning/pytorch/utilities/data.py:77: Trying to infer the `batch_size` from an ambiguous collection. The batch size we found is 7641. To avoid any miscalculations, use `self.log(..., batch_size=batch_size)`.\n",
      "/rds/general/user/cb1319/home/anaconda3/envs/Geom3D/lib/python3.11/site-packages/lightning/pytorch/utilities/data.py:77: Trying to infer the `batch_size` from an ambiguous collection. The batch size we found is 7728. To avoid any miscalculations, use `self.log(..., batch_size=batch_size)`.\n",
      "/rds/general/user/cb1319/home/anaconda3/envs/Geom3D/lib/python3.11/site-packages/lightning/pytorch/utilities/data.py:77: Trying to infer the `batch_size` from an ambiguous collection. The batch size we found is 7570. To avoid any miscalculations, use `self.log(..., batch_size=batch_size)`.\n",
      "/rds/general/user/cb1319/home/anaconda3/envs/Geom3D/lib/python3.11/site-packages/lightning/pytorch/utilities/data.py:77: Trying to infer the `batch_size` from an ambiguous collection. The batch size we found is 7537. To avoid any miscalculations, use `self.log(..., batch_size=batch_size)`.\n",
      "/rds/general/user/cb1319/home/anaconda3/envs/Geom3D/lib/python3.11/site-packages/lightning/pytorch/utilities/data.py:77: Trying to infer the `batch_size` from an ambiguous collection. The batch size we found is 7893. To avoid any miscalculations, use `self.log(..., batch_size=batch_size)`.\n",
      "/rds/general/user/cb1319/home/anaconda3/envs/Geom3D/lib/python3.11/site-packages/lightning/pytorch/utilities/data.py:77: Trying to infer the `batch_size` from an ambiguous collection. The batch size we found is 8142. To avoid any miscalculations, use `self.log(..., batch_size=batch_size)`.\n",
      "/rds/general/user/cb1319/home/anaconda3/envs/Geom3D/lib/python3.11/site-packages/lightning/pytorch/utilities/data.py:77: Trying to infer the `batch_size` from an ambiguous collection. The batch size we found is 8101. To avoid any miscalculations, use `self.log(..., batch_size=batch_size)`.\n",
      "/rds/general/user/cb1319/home/anaconda3/envs/Geom3D/lib/python3.11/site-packages/lightning/pytorch/utilities/data.py:77: Trying to infer the `batch_size` from an ambiguous collection. The batch size we found is 7705. To avoid any miscalculations, use `self.log(..., batch_size=batch_size)`.\n",
      "/rds/general/user/cb1319/home/anaconda3/envs/Geom3D/lib/python3.11/site-packages/lightning/pytorch/utilities/data.py:77: Trying to infer the `batch_size` from an ambiguous collection. The batch size we found is 7828. To avoid any miscalculations, use `self.log(..., batch_size=batch_size)`.\n",
      "/rds/general/user/cb1319/home/anaconda3/envs/Geom3D/lib/python3.11/site-packages/lightning/pytorch/utilities/data.py:77: Trying to infer the `batch_size` from an ambiguous collection. The batch size we found is 8087. To avoid any miscalculations, use `self.log(..., batch_size=batch_size)`.\n",
      "/rds/general/user/cb1319/home/anaconda3/envs/Geom3D/lib/python3.11/site-packages/lightning/pytorch/utilities/data.py:77: Trying to infer the `batch_size` from an ambiguous collection. The batch size we found is 8031. To avoid any miscalculations, use `self.log(..., batch_size=batch_size)`.\n",
      "/rds/general/user/cb1319/home/anaconda3/envs/Geom3D/lib/python3.11/site-packages/lightning/pytorch/utilities/data.py:77: Trying to infer the `batch_size` from an ambiguous collection. The batch size we found is 7780. To avoid any miscalculations, use `self.log(..., batch_size=batch_size)`.\n",
      "/rds/general/user/cb1319/home/anaconda3/envs/Geom3D/lib/python3.11/site-packages/lightning/pytorch/utilities/data.py:77: Trying to infer the `batch_size` from an ambiguous collection. The batch size we found is 7885. To avoid any miscalculations, use `self.log(..., batch_size=batch_size)`.\n",
      "/rds/general/user/cb1319/home/anaconda3/envs/Geom3D/lib/python3.11/site-packages/lightning/pytorch/utilities/data.py:77: Trying to infer the `batch_size` from an ambiguous collection. The batch size we found is 7519. To avoid any miscalculations, use `self.log(..., batch_size=batch_size)`.\n",
      "/rds/general/user/cb1319/home/anaconda3/envs/Geom3D/lib/python3.11/site-packages/lightning/pytorch/utilities/data.py:77: Trying to infer the `batch_size` from an ambiguous collection. The batch size we found is 8029. To avoid any miscalculations, use `self.log(..., batch_size=batch_size)`.\n",
      "/rds/general/user/cb1319/home/anaconda3/envs/Geom3D/lib/python3.11/site-packages/lightning/pytorch/utilities/data.py:77: Trying to infer the `batch_size` from an ambiguous collection. The batch size we found is 7432. To avoid any miscalculations, use `self.log(..., batch_size=batch_size)`.\n",
      "/rds/general/user/cb1319/home/anaconda3/envs/Geom3D/lib/python3.11/site-packages/lightning/pytorch/utilities/data.py:77: Trying to infer the `batch_size` from an ambiguous collection. The batch size we found is 7863. To avoid any miscalculations, use `self.log(..., batch_size=batch_size)`.\n",
      "/rds/general/user/cb1319/home/anaconda3/envs/Geom3D/lib/python3.11/site-packages/lightning/pytorch/utilities/data.py:77: Trying to infer the `batch_size` from an ambiguous collection. The batch size we found is 7674. To avoid any miscalculations, use `self.log(..., batch_size=batch_size)`.\n",
      "/rds/general/user/cb1319/home/anaconda3/envs/Geom3D/lib/python3.11/site-packages/lightning/pytorch/utilities/data.py:77: Trying to infer the `batch_size` from an ambiguous collection. The batch size we found is 7784. To avoid any miscalculations, use `self.log(..., batch_size=batch_size)`.\n",
      "/rds/general/user/cb1319/home/anaconda3/envs/Geom3D/lib/python3.11/site-packages/lightning/pytorch/utilities/data.py:77: Trying to infer the `batch_size` from an ambiguous collection. The batch size we found is 7944. To avoid any miscalculations, use `self.log(..., batch_size=batch_size)`.\n",
      "/rds/general/user/cb1319/home/anaconda3/envs/Geom3D/lib/python3.11/site-packages/lightning/pytorch/utilities/data.py:77: Trying to infer the `batch_size` from an ambiguous collection. The batch size we found is 7761. To avoid any miscalculations, use `self.log(..., batch_size=batch_size)`.\n",
      "/rds/general/user/cb1319/home/anaconda3/envs/Geom3D/lib/python3.11/site-packages/lightning/pytorch/utilities/data.py:77: Trying to infer the `batch_size` from an ambiguous collection. The batch size we found is 7664. To avoid any miscalculations, use `self.log(..., batch_size=batch_size)`.\n",
      "/rds/general/user/cb1319/home/anaconda3/envs/Geom3D/lib/python3.11/site-packages/lightning/pytorch/utilities/data.py:77: Trying to infer the `batch_size` from an ambiguous collection. The batch size we found is 8176. To avoid any miscalculations, use `self.log(..., batch_size=batch_size)`.\n",
      "/rds/general/user/cb1319/home/anaconda3/envs/Geom3D/lib/python3.11/site-packages/lightning/pytorch/utilities/data.py:77: Trying to infer the `batch_size` from an ambiguous collection. The batch size we found is 7658. To avoid any miscalculations, use `self.log(..., batch_size=batch_size)`.\n",
      "/rds/general/user/cb1319/home/anaconda3/envs/Geom3D/lib/python3.11/site-packages/lightning/pytorch/utilities/data.py:77: Trying to infer the `batch_size` from an ambiguous collection. The batch size we found is 8247. To avoid any miscalculations, use `self.log(..., batch_size=batch_size)`.\n",
      "/rds/general/user/cb1319/home/anaconda3/envs/Geom3D/lib/python3.11/site-packages/lightning/pytorch/utilities/data.py:77: Trying to infer the `batch_size` from an ambiguous collection. The batch size we found is 7782. To avoid any miscalculations, use `self.log(..., batch_size=batch_size)`.\n",
      "/rds/general/user/cb1319/home/anaconda3/envs/Geom3D/lib/python3.11/site-packages/lightning/pytorch/utilities/data.py:77: Trying to infer the `batch_size` from an ambiguous collection. The batch size we found is 7898. To avoid any miscalculations, use `self.log(..., batch_size=batch_size)`.\n",
      "/rds/general/user/cb1319/home/anaconda3/envs/Geom3D/lib/python3.11/site-packages/lightning/pytorch/utilities/data.py:77: Trying to infer the `batch_size` from an ambiguous collection. The batch size we found is 8171. To avoid any miscalculations, use `self.log(..., batch_size=batch_size)`.\n",
      "/rds/general/user/cb1319/home/anaconda3/envs/Geom3D/lib/python3.11/site-packages/lightning/pytorch/utilities/data.py:77: Trying to infer the `batch_size` from an ambiguous collection. The batch size we found is 7731. To avoid any miscalculations, use `self.log(..., batch_size=batch_size)`.\n",
      "/rds/general/user/cb1319/home/anaconda3/envs/Geom3D/lib/python3.11/site-packages/lightning/pytorch/utilities/data.py:77: Trying to infer the `batch_size` from an ambiguous collection. The batch size we found is 8010. To avoid any miscalculations, use `self.log(..., batch_size=batch_size)`.\n",
      "/rds/general/user/cb1319/home/anaconda3/envs/Geom3D/lib/python3.11/site-packages/lightning/pytorch/utilities/data.py:77: Trying to infer the `batch_size` from an ambiguous collection. The batch size we found is 7984. To avoid any miscalculations, use `self.log(..., batch_size=batch_size)`.\n",
      "/rds/general/user/cb1319/home/anaconda3/envs/Geom3D/lib/python3.11/site-packages/lightning/pytorch/utilities/data.py:77: Trying to infer the `batch_size` from an ambiguous collection. The batch size we found is 8003. To avoid any miscalculations, use `self.log(..., batch_size=batch_size)`.\n",
      "/rds/general/user/cb1319/home/anaconda3/envs/Geom3D/lib/python3.11/site-packages/lightning/pytorch/utilities/data.py:77: Trying to infer the `batch_size` from an ambiguous collection. The batch size we found is 7416. To avoid any miscalculations, use `self.log(..., batch_size=batch_size)`.\n",
      "/rds/general/user/cb1319/home/anaconda3/envs/Geom3D/lib/python3.11/site-packages/lightning/pytorch/utilities/data.py:77: Trying to infer the `batch_size` from an ambiguous collection. The batch size we found is 7715. To avoid any miscalculations, use `self.log(..., batch_size=batch_size)`.\n",
      "/rds/general/user/cb1319/home/anaconda3/envs/Geom3D/lib/python3.11/site-packages/lightning/pytorch/utilities/data.py:77: Trying to infer the `batch_size` from an ambiguous collection. The batch size we found is 7969. To avoid any miscalculations, use `self.log(..., batch_size=batch_size)`.\n",
      "/rds/general/user/cb1319/home/anaconda3/envs/Geom3D/lib/python3.11/site-packages/lightning/pytorch/utilities/data.py:77: Trying to infer the `batch_size` from an ambiguous collection. The batch size we found is 7875. To avoid any miscalculations, use `self.log(..., batch_size=batch_size)`.\n",
      "/rds/general/user/cb1319/home/anaconda3/envs/Geom3D/lib/python3.11/site-packages/lightning/pytorch/utilities/data.py:77: Trying to infer the `batch_size` from an ambiguous collection. The batch size we found is 8042. To avoid any miscalculations, use `self.log(..., batch_size=batch_size)`.\n",
      "/rds/general/user/cb1319/home/anaconda3/envs/Geom3D/lib/python3.11/site-packages/lightning/pytorch/utilities/data.py:77: Trying to infer the `batch_size` from an ambiguous collection. The batch size we found is 7716. To avoid any miscalculations, use `self.log(..., batch_size=batch_size)`.\n",
      "/rds/general/user/cb1319/home/anaconda3/envs/Geom3D/lib/python3.11/site-packages/lightning/pytorch/utilities/data.py:77: Trying to infer the `batch_size` from an ambiguous collection. The batch size we found is 7921. To avoid any miscalculations, use `self.log(..., batch_size=batch_size)`.\n",
      "/rds/general/user/cb1319/home/anaconda3/envs/Geom3D/lib/python3.11/site-packages/lightning/pytorch/utilities/data.py:77: Trying to infer the `batch_size` from an ambiguous collection. The batch size we found is 7773. To avoid any miscalculations, use `self.log(..., batch_size=batch_size)`.\n",
      "`Trainer.fit` stopped: `max_epochs=5` reached.\n",
=======
>>>>>>> Stashed changes
      "wandb: WARNING Source type is set to 'repo' but some required information is missing from the environment. A job will not be created from this run. See https://docs.wandb.ai/guides/launch/create-job\n"
     ]
    },
    {
     "data": {
<<<<<<< Updated upstream
      "application/vnd.jupyter.widget-view+json": {
       "model_id": "f7a54bee90b24410ba5c04ebabab5add",
       "version_major": 2,
       "version_minor": 0
      },
      "text/plain": [
       "VBox(children=(Label(value='11.820 MB of 11.820 MB uploaded\\r'), FloatProgress(value=1.0, max=1.0)))"
      ]
     },
     "metadata": {},
     "output_type": "display_data"
    },
    {
     "data": {
=======
>>>>>>> Stashed changes
      "text/html": [
       "<style>\n",
       "    table.wandb td:nth-child(1) { padding: 0 10px; text-align: left ; width: auto;} td:nth-child(2) {text-align: left ; width: 100%}\n",
       "    .wandb-row { display: flex; flex-direction: row; flex-wrap: wrap; justify-content: flex-start; width: 100% }\n",
       "    .wandb-col { display: flex; flex-direction: column; flex-basis: 100%; flex: 1; padding: 10px; }\n",
       "    </style>\n",
<<<<<<< Updated upstream
       "<div class=\"wandb-row\"><div class=\"wandb-col\"><h3>Run history:</h3><br/><table class=\"wandb\"><tr><td>epoch</td><td>▁▁▁▁▁▁▁▁▃▃▃▃▃▃▃▃▅▅▅▅▅▅▅▅▆▆▆▆▆▆▆▆████████</td></tr><tr><td>train_loss</td><td>██▇▄▃▃▄▅▂▂▂▃▃▃▃▂▄▂▃▃▂▂▃▂▃▂▂▂▂▃▂▂▂▁▃▁▁▂▂▄</td></tr><tr><td>trainer/global_step</td><td>▁▁▁▁▂▂▂▂▂▃▃▃▃▃▃▄▄▄▄▄▅▅▅▅▅▅▆▆▆▆▆▇▇▇▇▇▇███</td></tr><tr><td>val_loss</td><td>█▃▁▂▄</td></tr></table><br/></div><div class=\"wandb-col\"><h3>Run summary:</h3><br/><table class=\"wandb\"><tr><td>epoch</td><td>4</td></tr><tr><td>train_loss</td><td>1.28815</td></tr><tr><td>trainer/global_step</td><td>4999</td></tr><tr><td>val_loss</td><td>1.15422</td></tr></table><br/></div></div>"
=======
       "<div class=\"wandb-row\"><div class=\"wandb-col\"><h3>Run history:</h3><br/><table class=\"wandb\"><tr><td>epoch</td><td>▁▁▁▁▁▁▁▁▃▃▃▃▃▃▃▃▅▅▅▅▅▅▅▅▆▆▆▆▆▆▆▆████████</td></tr><tr><td>train_loss</td><td>▆▄▂█▂▂▃▃▂▂▂▁▁▁▁▂▂▁▁▁▁▁▁▁▁▁▁▁▁▁▁▁▁▁▁</td></tr><tr><td>trainer/global_step</td><td>▁▁▁▂▂▂▂▂▂▃▃▃▃▃▄▄▄▄▄▅▅▅▅▅▅▆▆▆▆▆▇▇▇▇▇▇████</td></tr><tr><td>val_loss</td><td>█▃▁▁▁</td></tr></table><br/></div><div class=\"wandb-col\"><h3>Run summary:</h3><br/><table class=\"wandb\"><tr><td>epoch</td><td>4</td></tr><tr><td>train_loss</td><td>3.67248</td></tr><tr><td>trainer/global_step</td><td>34</td></tr><tr><td>val_loss</td><td>5.88501</td></tr></table><br/></div></div>"
>>>>>>> Stashed changes
      ],
      "text/plain": [
       "<IPython.core.display.HTML object>"
      ]
     },
     "metadata": {},
     "output_type": "display_data"
    },
    {
     "data": {
      "text/html": [
<<<<<<< Updated upstream
       " View run <strong style=\"color:#cdcd00\">DimeNetPlusPlus_target_1K_TEST_5e4lr</strong> at: <a href='https://wandb.ai/cyprienbone/Geom3D/runs/8mm92vbe' target=\"_blank\">https://wandb.ai/cyprienbone/Geom3D/runs/8mm92vbe</a><br/>Synced 6 W&B file(s), 0 media file(s), 3 artifact file(s) and 0 other file(s)"
=======
       " View run <strong style=\"color:#cdcd00\">leafy-tree-15</strong> at: <a href='https://wandb.ai/cyprienbone/Geom3D/runs/0d1v8caw' target=\"_blank\">https://wandb.ai/cyprienbone/Geom3D/runs/0d1v8caw</a><br/>Synced 6 W&B file(s), 0 media file(s), 4 artifact file(s) and 0 other file(s)"
>>>>>>> Stashed changes
      ],
      "text/plain": [
       "<IPython.core.display.HTML object>"
      ]
     },
     "metadata": {},
     "output_type": "display_data"
    },
    {
     "data": {
      "text/html": [
<<<<<<< Updated upstream
       "Find logs at: <code>./wandb/run-20231128_171133-8mm92vbe/logs</code>"
=======
       "Find logs at: <code>./wandb/run-20231130_140252-0d1v8caw/logs</code>"
>>>>>>> Stashed changes
      ],
      "text/plain": [
       "<IPython.core.display.HTML object>"
      ]
     },
     "metadata": {},
     "output_type": "display_data"
    }
   ],
   "source": [
    "import importlib\n",
    "from geom3d import train_DimeNetPlusPlus\n",
    "\n",
    "importlib.reload(train_DimeNetPlusPlus)\n",
    "train_DimeNetPlusPlus.main(\"/rds/general/user/cb1319/home/GEOM3D/Geom3D/training/DimeNetPlusPlus_target_1K_TEST_5e4lr/\")"
   ]
  },
  {
   "cell_type": "code",
   "execution_count": null,
   "metadata": {},
   "outputs": [],
   "source": [
    "os.getcwd()"
   ]
  },
  {
   "cell_type": "code",
   "execution_count": null,
   "metadata": {},
   "outputs": [],
   "source": [
    "import importlib\n",
    "from geom3d import inference_test\n",
    "\n",
    "config_dir = \"/rds/general/user/cb1319/home/GEOM3D/Geom3D/training/SchNet_target_1K_TEST_5e4lr/\"\n",
    "chkpt_path = \"/rds/general/user/cb1319/home/GEOM3D/Geom3D/training/SchNet_target_1K_TEST_5e4lr/epoch=86-val_loss=0.54-other_metric=0.00.ckpt\"\n",
    "\n",
    "importlib.reload(inference_test)\n",
    "inference_test.plot_training_results(chkpt_path, config_dir)"
   ]
  },
  {
   "cell_type": "code",
   "execution_count": null,
   "metadata": {},
   "outputs": [],
   "source": []
  },
  {
   "cell_type": "code",
   "execution_count": null,
   "metadata": {},
   "outputs": [],
   "source": []
  }
 ],
 "metadata": {
  "kernelspec": {
   "display_name": "Python [conda env:Geom3D]",
   "language": "python",
   "name": "conda-env-Geom3D-py"
<<<<<<< Updated upstream
=======
  },
  "language_info": {
   "codemirror_mode": {
    "name": "ipython",
    "version": 3
   },
   "file_extension": ".py",
   "mimetype": "text/x-python",
   "name": "python",
   "nbconvert_exporter": "python",
   "pygments_lexer": "ipython3",
   "version": "3.11.5"
>>>>>>> Stashed changes
  }
 },
 "nbformat": 4,
 "nbformat_minor": 2
}
