{
 "cells": [
  {
   "cell_type": "code",
   "execution_count": 1,
   "metadata": {},
   "outputs": [],
   "source": [
    "import os\n",
    "os.chdir('/rds/general/user/cb1319/home/GEOM3D/Geom3D/')"
   ]
  },
  {
   "cell_type": "code",
   "execution_count": 2,
   "metadata": {},
   "outputs": [
    {
     "name": "stdout",
     "output_type": "stream",
     "text": [
      "config loaded from /rds/general/user/cb1319/home/GEOM3D/Geom3D/training/DimeNetPlusPlus_target_1K_TEST_5e4lr/\n"
     ]
    }
   ],
   "source": [
    "from geom3d.train_DimeNet import *\n",
    "import torch\n",
    "import copy\n",
    "\n",
    "config_dir = os.getcwd()+\"/training/DimeNetPlusPlus_target_1K_TEST_5e4lr/\"\n",
    "config = read_config(config_dir)"
   ]
  },
  {
   "cell_type": "code",
   "execution_count": 3,
   "metadata": {},
   "outputs": [
    {
     "name": "stdout",
     "output_type": "stream",
     "text": [
      "GPU (Quadro RTX 6000) is available.\n"
     ]
    }
   ],
   "source": [
    "# Check if GPU is available\n",
    "if torch.cuda.is_available():\n",
    "    # Get the name of the GPU\n",
    "    gpu_name = torch.cuda.get_device_name(0)  # Assuming you have one GPU; you can change the index if you have multiple GPUs\n",
    "    print(f\"GPU ({gpu_name}) is available.\")\n",
    "else:\n",
    "    print(\"No GPU available. Using CPU.\")"
   ]
  },
  {
   "cell_type": "code",
   "execution_count": 4,
   "metadata": {},
   "outputs": [
    {
     "name": "stdout",
     "output_type": "stream",
     "text": [
      "length of dataset: 80000\n"
     ]
    }
   ],
   "source": [
    "import importlib\n",
    "from geom3d import train_DimeNet\n",
    "\n",
    "importlib.reload(train_DimeNet)\n",
    "\n",
    "config[\"device\"] = \"cuda:0\" if torch.cuda.is_available() else \"cpu\"\n",
    "    \n",
    "np.random.seed(config[\"seed\"])\n",
    "torch.cuda.manual_seed_all(config[\"seed\"])\n",
    "dataset = train_DimeNet.load_data(config)\n",
    "print(f\"length of dataset: {len(dataset)}\")\n"
   ]
  },
  {
   "cell_type": "code",
   "execution_count": 5,
   "metadata": {},
   "outputs": [
    {
     "name": "stderr",
     "output_type": "stream",
     "text": [
      "Failed to detect the name of this notebook, you can set it manually with the WANDB_NOTEBOOK_NAME environment variable to enable code saving.\n",
      "\u001b[34m\u001b[1mwandb\u001b[0m: Currently logged in as: \u001b[33mcyprienbone\u001b[0m. Use \u001b[1m`wandb login --relogin`\u001b[0m to force relogin\n"
     ]
    },
    {
     "data": {
      "text/plain": [
       "True"
      ]
     },
     "execution_count": 5,
     "metadata": {},
     "output_type": "execute_result"
    }
   ],
   "source": [
    "import wandb\n",
    "wandb.login()"
   ]
  },
  {
   "cell_type": "code",
   "execution_count": 6,
   "metadata": {},
   "outputs": [],
   "source": [
    "# stop wandb run\n",
    "wandb.finish()"
   ]
  },
  {
   "cell_type": "code",
   "execution_count": 7,
   "metadata": {},
   "outputs": [
    {
     "name": "stdout",
     "output_type": "stream",
     "text": [
      "/bin/bash: which: line 1: syntax error: unexpected end of file\n",
      "/bin/bash: error importing function definition for `which'\n",
      "/bin/bash: module: line 1: syntax error: unexpected end of file\n",
      "/bin/bash: error importing function definition for `module'\n",
      "/bin/bash: scl: line 1: syntax error: unexpected end of file\n",
      "/bin/bash: error importing function definition for `scl'\n",
      "/bin/bash: ml: line 1: syntax error: unexpected end of file\n",
      "/bin/bash: error importing function definition for `ml'\n",
      "Tue Nov 28 17:11:02 2023       \n",
      "+---------------------------------------------------------------------------------------+\n",
      "| NVIDIA-SMI 535.54.03              Driver Version: 535.54.03    CUDA Version: 12.2     |\n",
      "|-----------------------------------------+----------------------+----------------------+\n",
      "| GPU  Name                 Persistence-M | Bus-Id        Disp.A | Volatile Uncorr. ECC |\n",
      "| Fan  Temp   Perf          Pwr:Usage/Cap |         Memory-Usage | GPU-Util  Compute M. |\n",
      "|                                         |                      |               MIG M. |\n",
      "|=========================================+======================+======================|\n",
      "|   0  Quadro RTX 6000                On  | 00000000:1B:00.0 Off |                  Off |\n",
      "| 33%   37C    P8              27W / 260W |   9715MiB / 24576MiB |      0%   E. Process |\n",
      "|                                         |                      |                  N/A |\n",
      "+-----------------------------------------+----------------------+----------------------+\n",
      "|   1  Quadro RTX 6000                On  | 00000000:1C:00.0 Off |                  Off |\n",
      "| 33%   36C    P8              19W / 260W |      1MiB / 24576MiB |      0%   E. Process |\n",
      "|                                         |                      |                  N/A |\n",
      "+-----------------------------------------+----------------------+----------------------+\n",
      "|   2  Quadro RTX 6000                On  | 00000000:1D:00.0 Off |                  Off |\n",
      "| 34%   37C    P8              27W / 260W |      1MiB / 24576MiB |      0%   E. Process |\n",
      "|                                         |                      |                  N/A |\n",
      "+-----------------------------------------+----------------------+----------------------+\n",
      "|   3  Quadro RTX 6000                On  | 00000000:1E:00.0 Off |                  Off |\n",
      "| 33%   36C    P8              32W / 260W |      3MiB / 24576MiB |      0%   E. Process |\n",
      "|                                         |                      |                  N/A |\n",
      "+-----------------------------------------+----------------------+----------------------+\n",
      "|   4  Quadro RTX 6000                On  | 00000000:89:00.0 Off |                  Off |\n",
      "| 33%   34C    P8              21W / 260W |    509MiB / 24576MiB |      0%   E. Process |\n",
      "|                                         |                      |                  N/A |\n",
      "+-----------------------------------------+----------------------+----------------------+\n",
      "|   5  Quadro RTX 6000                On  | 00000000:8A:00.0 Off |                  Off |\n",
      "| 34%   36C    P8              23W / 260W |    841MiB / 24576MiB |      0%   E. Process |\n",
      "|                                         |                      |                  N/A |\n",
      "+-----------------------------------------+----------------------+----------------------+\n",
      "|   6  Quadro RTX 6000                On  | 00000000:8B:00.0 Off |                  Off |\n",
      "| 34%   36C    P8              31W / 260W |    221MiB / 24576MiB |      0%   E. Process |\n",
      "|                                         |                      |                  N/A |\n",
      "+-----------------------------------------+----------------------+----------------------+\n",
      "|   7  Quadro RTX 6000                On  | 00000000:8C:00.0 Off |                  Off |\n",
      "| 33%   36C    P8              23W / 260W |      1MiB / 24576MiB |      0%   E. Process |\n",
      "|                                         |                      |                  N/A |\n",
      "+-----------------------------------------+----------------------+----------------------+\n",
      "                                                                                         \n",
      "+---------------------------------------------------------------------------------------+\n",
      "| Processes:                                                                            |\n",
      "|  GPU   GI   CI        PID   Type   Process name                            GPU Memory |\n",
      "|        ID   ID                                                             Usage      |\n",
      "|=======================================================================================|\n",
      "|    0   N/A  N/A   3404748      C   ...home/anaconda3/envs/pips/bin/python     9712MiB |\n",
      "|    4   N/A  N/A   3413922      C   ...me/anaconda3/envs/Geom3D/bin/python      506MiB |\n",
      "|    5   N/A  N/A   3417483      C   ...e/anaconda3/envs/deepimu/bin/python      838MiB |\n",
      "|    6   N/A  N/A   3431125      C   python                                      218MiB |\n",
      "+---------------------------------------------------------------------------------------+\n"
     ]
    }
   ],
   "source": [
    "# free cuda memory\n",
    "torch.cuda.empty_cache()\n",
    "\n",
    "# stop ongoing processes\n",
    "\n",
    "!nvidia-smi"
   ]
  },
  {
   "cell_type": "code",
   "execution_count": 8,
   "metadata": {},
   "outputs": [
    {
     "name": "stdout",
     "output_type": "stream",
     "text": [
      "config loaded from /rds/general/user/cb1319/home/GEOM3D/Geom3D/training/DimeNetPlusPlus_target_1K_TEST_5e4lr/\n",
      "train_idx:  [47044 44295 74783 ... 77925 18116 14762]\n",
      "valid_idx:  [39698 66692  7139 ... 52300 56176  3346]\n",
      "test_idx:  [61260 28261 49228 ... 76820   860 15795]\n",
      "Value of self.graph_pred_linear: None\n"
     ]
    },
    {
     "data": {
      "text/html": [
       "Tracking run with wandb version 0.16.0"
      ],
      "text/plain": [
       "<IPython.core.display.HTML object>"
      ]
     },
     "metadata": {},
     "output_type": "display_data"
    },
    {
     "data": {
      "text/html": [
       "Run data is saved locally in <code>./wandb/run-20231128_171133-8mm92vbe</code>"
      ],
      "text/plain": [
       "<IPython.core.display.HTML object>"
      ]
     },
     "metadata": {},
     "output_type": "display_data"
    },
    {
     "data": {
      "text/html": [
       "Syncing run <strong><a href='https://wandb.ai/cyprienbone/Geom3D/runs/8mm92vbe' target=\"_blank\">DimeNetPlusPlus_target_1K_TEST_5e4lr</a></strong> to <a href='https://wandb.ai/cyprienbone/Geom3D' target=\"_blank\">Weights & Biases</a> (<a href='https://wandb.me/run' target=\"_blank\">docs</a>)<br/>"
      ],
      "text/plain": [
       "<IPython.core.display.HTML object>"
      ]
     },
     "metadata": {},
     "output_type": "display_data"
    },
    {
     "data": {
      "text/html": [
       " View project at <a href='https://wandb.ai/cyprienbone/Geom3D' target=\"_blank\">https://wandb.ai/cyprienbone/Geom3D</a>"
      ],
      "text/plain": [
       "<IPython.core.display.HTML object>"
      ]
     },
     "metadata": {},
     "output_type": "display_data"
    },
    {
     "data": {
      "text/html": [
       " View run at <a href='https://wandb.ai/cyprienbone/Geom3D/runs/8mm92vbe' target=\"_blank\">https://wandb.ai/cyprienbone/Geom3D/runs/8mm92vbe</a>"
      ],
      "text/plain": [
       "<IPython.core.display.HTML object>"
      ]
     },
     "metadata": {},
     "output_type": "display_data"
    },
    {
     "name": "stderr",
     "output_type": "stream",
     "text": [
      "GPU available: True (cuda), used: True\n",
      "TPU available: False, using: 0 TPU cores\n",
      "IPU available: False, using: 0 IPUs\n",
      "HPU available: False, using: 0 HPUs\n",
      "`Trainer(val_check_interval=1.0)` was configured so validation will run at the end of the training epoch..\n",
      "LOCAL_RANK: 0 - CUDA_VISIBLE_DEVICES: [3]\n",
      "\n",
      "  | Name             | Type            | Params\n",
      "-----------------------------------------------------\n",
      "0 | molecule_3D_repr | DimeNetPlusPlus | 328 K \n",
      "-----------------------------------------------------\n",
      "328 K     Trainable params\n",
      "6         Non-trainable params\n",
      "328 K     Total params\n",
      "1.316     Total estimated model params size (MB)\n"
     ]
    },
    {
     "data": {
      "application/vnd.jupyter.widget-view+json": {
       "model_id": "c1559dd71bac4effa2938a8cde5ce734",
       "version_major": 2,
       "version_minor": 0
      },
      "text/plain": [
       "Sanity Checking: |          | 0/? [00:00<?, ?it/s]"
      ]
     },
     "metadata": {},
     "output_type": "display_data"
    },
    {
     "name": "stderr",
     "output_type": "stream",
     "text": [
      "/rds/general/user/cb1319/home/anaconda3/envs/Geom3D/lib/python3.11/site-packages/lightning/pytorch/trainer/connectors/data_connector.py:492: Your `val_dataloader`'s sampler has shuffling enabled, it is strongly recommended that you turn shuffling off for val/test dataloaders.\n",
      "/rds/general/user/cb1319/home/anaconda3/envs/Geom3D/lib/python3.11/site-packages/lightning/pytorch/trainer/connectors/data_connector.py:441: The 'val_dataloader' does not have many workers which may be a bottleneck. Consider increasing the value of the `num_workers` argument` to `num_workers=31` in the `DataLoader` to improve performance.\n",
      "/rds/general/user/cb1319/home/anaconda3/envs/Geom3D/lib/python3.11/site-packages/lightning/pytorch/utilities/data.py:77: Trying to infer the `batch_size` from an ambiguous collection. The batch size we found is 7741. To avoid any miscalculations, use `self.log(..., batch_size=batch_size)`.\n",
      "/rds/general/user/cb1319/home/anaconda3/envs/Geom3D/lib/python3.11/site-packages/lightning/pytorch/utilities/data.py:77: Trying to infer the `batch_size` from an ambiguous collection. The batch size we found is 7573. To avoid any miscalculations, use `self.log(..., batch_size=batch_size)`.\n",
      "/rds/general/user/cb1319/home/anaconda3/envs/Geom3D/lib/python3.11/site-packages/lightning/pytorch/trainer/connectors/data_connector.py:441: The 'train_dataloader' does not have many workers which may be a bottleneck. Consider increasing the value of the `num_workers` argument` to `num_workers=31` in the `DataLoader` to improve performance.\n"
     ]
    },
    {
     "data": {
      "application/vnd.jupyter.widget-view+json": {
       "model_id": "5961f3d5fc504d00b037101aad721280",
       "version_major": 2,
       "version_minor": 0
      },
      "text/plain": [
       "Training: |          | 0/? [00:00<?, ?it/s]"
      ]
     },
     "metadata": {},
     "output_type": "display_data"
    },
    {
     "data": {
      "application/vnd.jupyter.widget-view+json": {
       "model_id": "853c4ae2fed54291b6d64a89fa811c87",
       "version_major": 2,
       "version_minor": 0
      },
      "text/plain": [
       "Validation: |          | 0/? [00:00<?, ?it/s]"
      ]
     },
     "metadata": {},
     "output_type": "display_data"
    },
    {
     "name": "stderr",
     "output_type": "stream",
     "text": [
      "/rds/general/user/cb1319/home/anaconda3/envs/Geom3D/lib/python3.11/site-packages/lightning/pytorch/utilities/data.py:77: Trying to infer the `batch_size` from an ambiguous collection. The batch size we found is 7745. To avoid any miscalculations, use `self.log(..., batch_size=batch_size)`.\n",
      "/rds/general/user/cb1319/home/anaconda3/envs/Geom3D/lib/python3.11/site-packages/lightning/pytorch/utilities/data.py:77: Trying to infer the `batch_size` from an ambiguous collection. The batch size we found is 8088. To avoid any miscalculations, use `self.log(..., batch_size=batch_size)`.\n",
      "/rds/general/user/cb1319/home/anaconda3/envs/Geom3D/lib/python3.11/site-packages/lightning/pytorch/utilities/data.py:77: Trying to infer the `batch_size` from an ambiguous collection. The batch size we found is 7660. To avoid any miscalculations, use `self.log(..., batch_size=batch_size)`.\n",
      "/rds/general/user/cb1319/home/anaconda3/envs/Geom3D/lib/python3.11/site-packages/lightning/pytorch/utilities/data.py:77: Trying to infer the `batch_size` from an ambiguous collection. The batch size we found is 7795. To avoid any miscalculations, use `self.log(..., batch_size=batch_size)`.\n",
      "/rds/general/user/cb1319/home/anaconda3/envs/Geom3D/lib/python3.11/site-packages/lightning/pytorch/utilities/data.py:77: Trying to infer the `batch_size` from an ambiguous collection. The batch size we found is 7930. To avoid any miscalculations, use `self.log(..., batch_size=batch_size)`.\n",
      "/rds/general/user/cb1319/home/anaconda3/envs/Geom3D/lib/python3.11/site-packages/lightning/pytorch/utilities/data.py:77: Trying to infer the `batch_size` from an ambiguous collection. The batch size we found is 7974. To avoid any miscalculations, use `self.log(..., batch_size=batch_size)`.\n",
      "/rds/general/user/cb1319/home/anaconda3/envs/Geom3D/lib/python3.11/site-packages/lightning/pytorch/utilities/data.py:77: Trying to infer the `batch_size` from an ambiguous collection. The batch size we found is 7981. To avoid any miscalculations, use `self.log(..., batch_size=batch_size)`.\n",
      "/rds/general/user/cb1319/home/anaconda3/envs/Geom3D/lib/python3.11/site-packages/lightning/pytorch/utilities/data.py:77: Trying to infer the `batch_size` from an ambiguous collection. The batch size we found is 8043. To avoid any miscalculations, use `self.log(..., batch_size=batch_size)`.\n",
      "/rds/general/user/cb1319/home/anaconda3/envs/Geom3D/lib/python3.11/site-packages/lightning/pytorch/utilities/data.py:77: Trying to infer the `batch_size` from an ambiguous collection. The batch size we found is 8112. To avoid any miscalculations, use `self.log(..., batch_size=batch_size)`.\n",
      "/rds/general/user/cb1319/home/anaconda3/envs/Geom3D/lib/python3.11/site-packages/lightning/pytorch/utilities/data.py:77: Trying to infer the `batch_size` from an ambiguous collection. The batch size we found is 7587. To avoid any miscalculations, use `self.log(..., batch_size=batch_size)`.\n",
      "/rds/general/user/cb1319/home/anaconda3/envs/Geom3D/lib/python3.11/site-packages/lightning/pytorch/utilities/data.py:77: Trying to infer the `batch_size` from an ambiguous collection. The batch size we found is 7820. To avoid any miscalculations, use `self.log(..., batch_size=batch_size)`.\n",
      "/rds/general/user/cb1319/home/anaconda3/envs/Geom3D/lib/python3.11/site-packages/lightning/pytorch/utilities/data.py:77: Trying to infer the `batch_size` from an ambiguous collection. The batch size we found is 8158. To avoid any miscalculations, use `self.log(..., batch_size=batch_size)`.\n",
      "/rds/general/user/cb1319/home/anaconda3/envs/Geom3D/lib/python3.11/site-packages/lightning/pytorch/utilities/data.py:77: Trying to infer the `batch_size` from an ambiguous collection. The batch size we found is 7838. To avoid any miscalculations, use `self.log(..., batch_size=batch_size)`.\n",
      "/rds/general/user/cb1319/home/anaconda3/envs/Geom3D/lib/python3.11/site-packages/lightning/pytorch/utilities/data.py:77: Trying to infer the `batch_size` from an ambiguous collection. The batch size we found is 7665. To avoid any miscalculations, use `self.log(..., batch_size=batch_size)`.\n",
      "/rds/general/user/cb1319/home/anaconda3/envs/Geom3D/lib/python3.11/site-packages/lightning/pytorch/utilities/data.py:77: Trying to infer the `batch_size` from an ambiguous collection. The batch size we found is 7646. To avoid any miscalculations, use `self.log(..., batch_size=batch_size)`.\n",
      "/rds/general/user/cb1319/home/anaconda3/envs/Geom3D/lib/python3.11/site-packages/lightning/pytorch/utilities/data.py:77: Trying to infer the `batch_size` from an ambiguous collection. The batch size we found is 8085. To avoid any miscalculations, use `self.log(..., batch_size=batch_size)`.\n",
      "/rds/general/user/cb1319/home/anaconda3/envs/Geom3D/lib/python3.11/site-packages/lightning/pytorch/utilities/data.py:77: Trying to infer the `batch_size` from an ambiguous collection. The batch size we found is 7707. To avoid any miscalculations, use `self.log(..., batch_size=batch_size)`.\n",
      "/rds/general/user/cb1319/home/anaconda3/envs/Geom3D/lib/python3.11/site-packages/lightning/pytorch/utilities/data.py:77: Trying to infer the `batch_size` from an ambiguous collection. The batch size we found is 7529. To avoid any miscalculations, use `self.log(..., batch_size=batch_size)`.\n",
      "/rds/general/user/cb1319/home/anaconda3/envs/Geom3D/lib/python3.11/site-packages/lightning/pytorch/utilities/data.py:77: Trying to infer the `batch_size` from an ambiguous collection. The batch size we found is 7999. To avoid any miscalculations, use `self.log(..., batch_size=batch_size)`.\n",
      "/rds/general/user/cb1319/home/anaconda3/envs/Geom3D/lib/python3.11/site-packages/lightning/pytorch/utilities/data.py:77: Trying to infer the `batch_size` from an ambiguous collection. The batch size we found is 7737. To avoid any miscalculations, use `self.log(..., batch_size=batch_size)`.\n",
      "/rds/general/user/cb1319/home/anaconda3/envs/Geom3D/lib/python3.11/site-packages/lightning/pytorch/utilities/data.py:77: Trying to infer the `batch_size` from an ambiguous collection. The batch size we found is 7527. To avoid any miscalculations, use `self.log(..., batch_size=batch_size)`.\n",
      "/rds/general/user/cb1319/home/anaconda3/envs/Geom3D/lib/python3.11/site-packages/lightning/pytorch/utilities/data.py:77: Trying to infer the `batch_size` from an ambiguous collection. The batch size we found is 7935. To avoid any miscalculations, use `self.log(..., batch_size=batch_size)`.\n",
      "/rds/general/user/cb1319/home/anaconda3/envs/Geom3D/lib/python3.11/site-packages/lightning/pytorch/utilities/data.py:77: Trying to infer the `batch_size` from an ambiguous collection. The batch size we found is 7767. To avoid any miscalculations, use `self.log(..., batch_size=batch_size)`.\n",
      "/rds/general/user/cb1319/home/anaconda3/envs/Geom3D/lib/python3.11/site-packages/lightning/pytorch/utilities/data.py:77: Trying to infer the `batch_size` from an ambiguous collection. The batch size we found is 7922. To avoid any miscalculations, use `self.log(..., batch_size=batch_size)`.\n",
      "/rds/general/user/cb1319/home/anaconda3/envs/Geom3D/lib/python3.11/site-packages/lightning/pytorch/utilities/data.py:77: Trying to infer the `batch_size` from an ambiguous collection. The batch size we found is 7487. To avoid any miscalculations, use `self.log(..., batch_size=batch_size)`.\n",
      "/rds/general/user/cb1319/home/anaconda3/envs/Geom3D/lib/python3.11/site-packages/lightning/pytorch/utilities/data.py:77: Trying to infer the `batch_size` from an ambiguous collection. The batch size we found is 8186. To avoid any miscalculations, use `self.log(..., batch_size=batch_size)`.\n",
      "/rds/general/user/cb1319/home/anaconda3/envs/Geom3D/lib/python3.11/site-packages/lightning/pytorch/utilities/data.py:77: Trying to infer the `batch_size` from an ambiguous collection. The batch size we found is 8092. To avoid any miscalculations, use `self.log(..., batch_size=batch_size)`.\n",
      "/rds/general/user/cb1319/home/anaconda3/envs/Geom3D/lib/python3.11/site-packages/lightning/pytorch/utilities/data.py:77: Trying to infer the `batch_size` from an ambiguous collection. The batch size we found is 7585. To avoid any miscalculations, use `self.log(..., batch_size=batch_size)`.\n",
      "/rds/general/user/cb1319/home/anaconda3/envs/Geom3D/lib/python3.11/site-packages/lightning/pytorch/utilities/data.py:77: Trying to infer the `batch_size` from an ambiguous collection. The batch size we found is 7808. To avoid any miscalculations, use `self.log(..., batch_size=batch_size)`.\n",
      "/rds/general/user/cb1319/home/anaconda3/envs/Geom3D/lib/python3.11/site-packages/lightning/pytorch/utilities/data.py:77: Trying to infer the `batch_size` from an ambiguous collection. The batch size we found is 7972. To avoid any miscalculations, use `self.log(..., batch_size=batch_size)`.\n",
      "/rds/general/user/cb1319/home/anaconda3/envs/Geom3D/lib/python3.11/site-packages/lightning/pytorch/utilities/data.py:77: Trying to infer the `batch_size` from an ambiguous collection. The batch size we found is 7735. To avoid any miscalculations, use `self.log(..., batch_size=batch_size)`.\n",
      "/rds/general/user/cb1319/home/anaconda3/envs/Geom3D/lib/python3.11/site-packages/lightning/pytorch/utilities/data.py:77: Trying to infer the `batch_size` from an ambiguous collection. The batch size we found is 7887. To avoid any miscalculations, use `self.log(..., batch_size=batch_size)`.\n",
      "/rds/general/user/cb1319/home/anaconda3/envs/Geom3D/lib/python3.11/site-packages/lightning/pytorch/utilities/data.py:77: Trying to infer the `batch_size` from an ambiguous collection. The batch size we found is 8023. To avoid any miscalculations, use `self.log(..., batch_size=batch_size)`.\n",
      "/rds/general/user/cb1319/home/anaconda3/envs/Geom3D/lib/python3.11/site-packages/lightning/pytorch/utilities/data.py:77: Trying to infer the `batch_size` from an ambiguous collection. The batch size we found is 7865. To avoid any miscalculations, use `self.log(..., batch_size=batch_size)`.\n",
      "/rds/general/user/cb1319/home/anaconda3/envs/Geom3D/lib/python3.11/site-packages/lightning/pytorch/utilities/data.py:77: Trying to infer the `batch_size` from an ambiguous collection. The batch size we found is 7680. To avoid any miscalculations, use `self.log(..., batch_size=batch_size)`.\n",
      "/rds/general/user/cb1319/home/anaconda3/envs/Geom3D/lib/python3.11/site-packages/lightning/pytorch/utilities/data.py:77: Trying to infer the `batch_size` from an ambiguous collection. The batch size we found is 7736. To avoid any miscalculations, use `self.log(..., batch_size=batch_size)`.\n",
      "/rds/general/user/cb1319/home/anaconda3/envs/Geom3D/lib/python3.11/site-packages/lightning/pytorch/utilities/data.py:77: Trying to infer the `batch_size` from an ambiguous collection. The batch size we found is 8009. To avoid any miscalculations, use `self.log(..., batch_size=batch_size)`.\n",
      "/rds/general/user/cb1319/home/anaconda3/envs/Geom3D/lib/python3.11/site-packages/lightning/pytorch/utilities/data.py:77: Trying to infer the `batch_size` from an ambiguous collection. The batch size we found is 7763. To avoid any miscalculations, use `self.log(..., batch_size=batch_size)`.\n",
      "/rds/general/user/cb1319/home/anaconda3/envs/Geom3D/lib/python3.11/site-packages/lightning/pytorch/utilities/data.py:77: Trying to infer the `batch_size` from an ambiguous collection. The batch size we found is 8048. To avoid any miscalculations, use `self.log(..., batch_size=batch_size)`.\n",
      "/rds/general/user/cb1319/home/anaconda3/envs/Geom3D/lib/python3.11/site-packages/lightning/pytorch/utilities/data.py:77: Trying to infer the `batch_size` from an ambiguous collection. The batch size we found is 7742. To avoid any miscalculations, use `self.log(..., batch_size=batch_size)`.\n",
      "/rds/general/user/cb1319/home/anaconda3/envs/Geom3D/lib/python3.11/site-packages/lightning/pytorch/utilities/data.py:77: Trying to infer the `batch_size` from an ambiguous collection. The batch size we found is 7914. To avoid any miscalculations, use `self.log(..., batch_size=batch_size)`.\n",
      "/rds/general/user/cb1319/home/anaconda3/envs/Geom3D/lib/python3.11/site-packages/lightning/pytorch/utilities/data.py:77: Trying to infer the `batch_size` from an ambiguous collection. The batch size we found is 7633. To avoid any miscalculations, use `self.log(..., batch_size=batch_size)`.\n",
      "/rds/general/user/cb1319/home/anaconda3/envs/Geom3D/lib/python3.11/site-packages/lightning/pytorch/utilities/data.py:77: Trying to infer the `batch_size` from an ambiguous collection. The batch size we found is 8075. To avoid any miscalculations, use `self.log(..., batch_size=batch_size)`.\n",
      "/rds/general/user/cb1319/home/anaconda3/envs/Geom3D/lib/python3.11/site-packages/lightning/pytorch/utilities/data.py:77: Trying to infer the `batch_size` from an ambiguous collection. The batch size we found is 7649. To avoid any miscalculations, use `self.log(..., batch_size=batch_size)`.\n",
      "/rds/general/user/cb1319/home/anaconda3/envs/Geom3D/lib/python3.11/site-packages/lightning/pytorch/utilities/data.py:77: Trying to infer the `batch_size` from an ambiguous collection. The batch size we found is 7817. To avoid any miscalculations, use `self.log(..., batch_size=batch_size)`.\n",
      "/rds/general/user/cb1319/home/anaconda3/envs/Geom3D/lib/python3.11/site-packages/lightning/pytorch/utilities/data.py:77: Trying to infer the `batch_size` from an ambiguous collection. The batch size we found is 7826. To avoid any miscalculations, use `self.log(..., batch_size=batch_size)`.\n",
      "/rds/general/user/cb1319/home/anaconda3/envs/Geom3D/lib/python3.11/site-packages/lightning/pytorch/utilities/data.py:77: Trying to infer the `batch_size` from an ambiguous collection. The batch size we found is 8019. To avoid any miscalculations, use `self.log(..., batch_size=batch_size)`.\n",
      "/rds/general/user/cb1319/home/anaconda3/envs/Geom3D/lib/python3.11/site-packages/lightning/pytorch/utilities/data.py:77: Trying to infer the `batch_size` from an ambiguous collection. The batch size we found is 7967. To avoid any miscalculations, use `self.log(..., batch_size=batch_size)`.\n",
      "/rds/general/user/cb1319/home/anaconda3/envs/Geom3D/lib/python3.11/site-packages/lightning/pytorch/utilities/data.py:77: Trying to infer the `batch_size` from an ambiguous collection. The batch size we found is 7612. To avoid any miscalculations, use `self.log(..., batch_size=batch_size)`.\n",
      "/rds/general/user/cb1319/home/anaconda3/envs/Geom3D/lib/python3.11/site-packages/lightning/pytorch/utilities/data.py:77: Trying to infer the `batch_size` from an ambiguous collection. The batch size we found is 7903. To avoid any miscalculations, use `self.log(..., batch_size=batch_size)`.\n",
      "/rds/general/user/cb1319/home/anaconda3/envs/Geom3D/lib/python3.11/site-packages/lightning/pytorch/utilities/data.py:77: Trying to infer the `batch_size` from an ambiguous collection. The batch size we found is 7815. To avoid any miscalculations, use `self.log(..., batch_size=batch_size)`.\n",
      "/rds/general/user/cb1319/home/anaconda3/envs/Geom3D/lib/python3.11/site-packages/lightning/pytorch/utilities/data.py:77: Trying to infer the `batch_size` from an ambiguous collection. The batch size we found is 7812. To avoid any miscalculations, use `self.log(..., batch_size=batch_size)`.\n",
      "/rds/general/user/cb1319/home/anaconda3/envs/Geom3D/lib/python3.11/site-packages/lightning/pytorch/utilities/data.py:77: Trying to infer the `batch_size` from an ambiguous collection. The batch size we found is 8144. To avoid any miscalculations, use `self.log(..., batch_size=batch_size)`.\n",
      "/rds/general/user/cb1319/home/anaconda3/envs/Geom3D/lib/python3.11/site-packages/lightning/pytorch/utilities/data.py:77: Trying to infer the `batch_size` from an ambiguous collection. The batch size we found is 7568. To avoid any miscalculations, use `self.log(..., batch_size=batch_size)`.\n",
      "/rds/general/user/cb1319/home/anaconda3/envs/Geom3D/lib/python3.11/site-packages/lightning/pytorch/utilities/data.py:77: Trying to infer the `batch_size` from an ambiguous collection. The batch size we found is 7753. To avoid any miscalculations, use `self.log(..., batch_size=batch_size)`.\n",
      "/rds/general/user/cb1319/home/anaconda3/envs/Geom3D/lib/python3.11/site-packages/lightning/pytorch/utilities/data.py:77: Trying to infer the `batch_size` from an ambiguous collection. The batch size we found is 8026. To avoid any miscalculations, use `self.log(..., batch_size=batch_size)`.\n",
      "/rds/general/user/cb1319/home/anaconda3/envs/Geom3D/lib/python3.11/site-packages/lightning/pytorch/utilities/data.py:77: Trying to infer the `batch_size` from an ambiguous collection. The batch size we found is 7845. To avoid any miscalculations, use `self.log(..., batch_size=batch_size)`.\n",
      "/rds/general/user/cb1319/home/anaconda3/envs/Geom3D/lib/python3.11/site-packages/lightning/pytorch/utilities/data.py:77: Trying to infer the `batch_size` from an ambiguous collection. The batch size we found is 7623. To avoid any miscalculations, use `self.log(..., batch_size=batch_size)`.\n",
      "/rds/general/user/cb1319/home/anaconda3/envs/Geom3D/lib/python3.11/site-packages/lightning/pytorch/utilities/data.py:77: Trying to infer the `batch_size` from an ambiguous collection. The batch size we found is 7931. To avoid any miscalculations, use `self.log(..., batch_size=batch_size)`.\n",
      "/rds/general/user/cb1319/home/anaconda3/envs/Geom3D/lib/python3.11/site-packages/lightning/pytorch/utilities/data.py:77: Trying to infer the `batch_size` from an ambiguous collection. The batch size we found is 7924. To avoid any miscalculations, use `self.log(..., batch_size=batch_size)`.\n",
      "/rds/general/user/cb1319/home/anaconda3/envs/Geom3D/lib/python3.11/site-packages/lightning/pytorch/utilities/data.py:77: Trying to infer the `batch_size` from an ambiguous collection. The batch size we found is 7738. To avoid any miscalculations, use `self.log(..., batch_size=batch_size)`.\n",
      "/rds/general/user/cb1319/home/anaconda3/envs/Geom3D/lib/python3.11/site-packages/lightning/pytorch/utilities/data.py:77: Trying to infer the `batch_size` from an ambiguous collection. The batch size we found is 7691. To avoid any miscalculations, use `self.log(..., batch_size=batch_size)`.\n",
      "/rds/general/user/cb1319/home/anaconda3/envs/Geom3D/lib/python3.11/site-packages/lightning/pytorch/utilities/data.py:77: Trying to infer the `batch_size` from an ambiguous collection. The batch size we found is 7744. To avoid any miscalculations, use `self.log(..., batch_size=batch_size)`.\n",
      "/rds/general/user/cb1319/home/anaconda3/envs/Geom3D/lib/python3.11/site-packages/lightning/pytorch/utilities/data.py:77: Trying to infer the `batch_size` from an ambiguous collection. The batch size we found is 7954. To avoid any miscalculations, use `self.log(..., batch_size=batch_size)`.\n",
      "/rds/general/user/cb1319/home/anaconda3/envs/Geom3D/lib/python3.11/site-packages/lightning/pytorch/utilities/data.py:77: Trying to infer the `batch_size` from an ambiguous collection. The batch size we found is 7861. To avoid any miscalculations, use `self.log(..., batch_size=batch_size)`.\n",
      "/rds/general/user/cb1319/home/anaconda3/envs/Geom3D/lib/python3.11/site-packages/lightning/pytorch/utilities/data.py:77: Trying to infer the `batch_size` from an ambiguous collection. The batch size we found is 7926. To avoid any miscalculations, use `self.log(..., batch_size=batch_size)`.\n",
      "/rds/general/user/cb1319/home/anaconda3/envs/Geom3D/lib/python3.11/site-packages/lightning/pytorch/utilities/data.py:77: Trying to infer the `batch_size` from an ambiguous collection. The batch size we found is 7539. To avoid any miscalculations, use `self.log(..., batch_size=batch_size)`.\n",
      "/rds/general/user/cb1319/home/anaconda3/envs/Geom3D/lib/python3.11/site-packages/lightning/pytorch/utilities/data.py:77: Trying to infer the `batch_size` from an ambiguous collection. The batch size we found is 7520. To avoid any miscalculations, use `self.log(..., batch_size=batch_size)`.\n",
      "/rds/general/user/cb1319/home/anaconda3/envs/Geom3D/lib/python3.11/site-packages/lightning/pytorch/utilities/data.py:77: Trying to infer the `batch_size` from an ambiguous collection. The batch size we found is 7605. To avoid any miscalculations, use `self.log(..., batch_size=batch_size)`.\n",
      "/rds/general/user/cb1319/home/anaconda3/envs/Geom3D/lib/python3.11/site-packages/lightning/pytorch/utilities/data.py:77: Trying to infer the `batch_size` from an ambiguous collection. The batch size we found is 7656. To avoid any miscalculations, use `self.log(..., batch_size=batch_size)`.\n",
      "/rds/general/user/cb1319/home/anaconda3/envs/Geom3D/lib/python3.11/site-packages/lightning/pytorch/utilities/data.py:77: Trying to infer the `batch_size` from an ambiguous collection. The batch size we found is 7643. To avoid any miscalculations, use `self.log(..., batch_size=batch_size)`.\n",
      "/rds/general/user/cb1319/home/anaconda3/envs/Geom3D/lib/python3.11/site-packages/lightning/pytorch/utilities/data.py:77: Trying to infer the `batch_size` from an ambiguous collection. The batch size we found is 7832. To avoid any miscalculations, use `self.log(..., batch_size=batch_size)`.\n",
      "/rds/general/user/cb1319/home/anaconda3/envs/Geom3D/lib/python3.11/site-packages/lightning/pytorch/utilities/data.py:77: Trying to infer the `batch_size` from an ambiguous collection. The batch size we found is 8127. To avoid any miscalculations, use `self.log(..., batch_size=batch_size)`.\n",
      "/rds/general/user/cb1319/home/anaconda3/envs/Geom3D/lib/python3.11/site-packages/lightning/pytorch/utilities/data.py:77: Trying to infer the `batch_size` from an ambiguous collection. The batch size we found is 7912. To avoid any miscalculations, use `self.log(..., batch_size=batch_size)`.\n",
      "/rds/general/user/cb1319/home/anaconda3/envs/Geom3D/lib/python3.11/site-packages/lightning/pytorch/utilities/data.py:77: Trying to infer the `batch_size` from an ambiguous collection. The batch size we found is 7769. To avoid any miscalculations, use `self.log(..., batch_size=batch_size)`.\n",
      "/rds/general/user/cb1319/home/anaconda3/envs/Geom3D/lib/python3.11/site-packages/lightning/pytorch/utilities/data.py:77: Trying to infer the `batch_size` from an ambiguous collection. The batch size we found is 8030. To avoid any miscalculations, use `self.log(..., batch_size=batch_size)`.\n",
      "/rds/general/user/cb1319/home/anaconda3/envs/Geom3D/lib/python3.11/site-packages/lightning/pytorch/utilities/data.py:77: Trying to infer the `batch_size` from an ambiguous collection. The batch size we found is 7928. To avoid any miscalculations, use `self.log(..., batch_size=batch_size)`.\n",
      "/rds/general/user/cb1319/home/anaconda3/envs/Geom3D/lib/python3.11/site-packages/lightning/pytorch/utilities/data.py:77: Trying to infer the `batch_size` from an ambiguous collection. The batch size we found is 7552. To avoid any miscalculations, use `self.log(..., batch_size=batch_size)`.\n",
      "/rds/general/user/cb1319/home/anaconda3/envs/Geom3D/lib/python3.11/site-packages/lightning/pytorch/utilities/data.py:77: Trying to infer the `batch_size` from an ambiguous collection. The batch size we found is 7939. To avoid any miscalculations, use `self.log(..., batch_size=batch_size)`.\n",
      "/rds/general/user/cb1319/home/anaconda3/envs/Geom3D/lib/python3.11/site-packages/lightning/pytorch/utilities/data.py:77: Trying to infer the `batch_size` from an ambiguous collection. The batch size we found is 7739. To avoid any miscalculations, use `self.log(..., batch_size=batch_size)`.\n",
      "/rds/general/user/cb1319/home/anaconda3/envs/Geom3D/lib/python3.11/site-packages/lightning/pytorch/utilities/data.py:77: Trying to infer the `batch_size` from an ambiguous collection. The batch size we found is 7764. To avoid any miscalculations, use `self.log(..., batch_size=batch_size)`.\n",
      "/rds/general/user/cb1319/home/anaconda3/envs/Geom3D/lib/python3.11/site-packages/lightning/pytorch/utilities/data.py:77: Trying to infer the `batch_size` from an ambiguous collection. The batch size we found is 7797. To avoid any miscalculations, use `self.log(..., batch_size=batch_size)`.\n",
      "/rds/general/user/cb1319/home/anaconda3/envs/Geom3D/lib/python3.11/site-packages/lightning/pytorch/utilities/data.py:77: Trying to infer the `batch_size` from an ambiguous collection. The batch size we found is 7956. To avoid any miscalculations, use `self.log(..., batch_size=batch_size)`.\n",
      "/rds/general/user/cb1319/home/anaconda3/envs/Geom3D/lib/python3.11/site-packages/lightning/pytorch/utilities/data.py:77: Trying to infer the `batch_size` from an ambiguous collection. The batch size we found is 7989. To avoid any miscalculations, use `self.log(..., batch_size=batch_size)`.\n",
      "/rds/general/user/cb1319/home/anaconda3/envs/Geom3D/lib/python3.11/site-packages/lightning/pytorch/utilities/data.py:77: Trying to infer the `batch_size` from an ambiguous collection. The batch size we found is 7852. To avoid any miscalculations, use `self.log(..., batch_size=batch_size)`.\n",
      "/rds/general/user/cb1319/home/anaconda3/envs/Geom3D/lib/python3.11/site-packages/lightning/pytorch/utilities/data.py:77: Trying to infer the `batch_size` from an ambiguous collection. The batch size we found is 7843. To avoid any miscalculations, use `self.log(..., batch_size=batch_size)`.\n",
      "/rds/general/user/cb1319/home/anaconda3/envs/Geom3D/lib/python3.11/site-packages/lightning/pytorch/utilities/data.py:77: Trying to infer the `batch_size` from an ambiguous collection. The batch size we found is 7634. To avoid any miscalculations, use `self.log(..., batch_size=batch_size)`.\n",
      "/rds/general/user/cb1319/home/anaconda3/envs/Geom3D/lib/python3.11/site-packages/lightning/pytorch/utilities/data.py:77: Trying to infer the `batch_size` from an ambiguous collection. The batch size we found is 7547. To avoid any miscalculations, use `self.log(..., batch_size=batch_size)`.\n",
      "/rds/general/user/cb1319/home/anaconda3/envs/Geom3D/lib/python3.11/site-packages/lightning/pytorch/utilities/data.py:77: Trying to infer the `batch_size` from an ambiguous collection. The batch size we found is 7918. To avoid any miscalculations, use `self.log(..., batch_size=batch_size)`.\n",
      "/rds/general/user/cb1319/home/anaconda3/envs/Geom3D/lib/python3.11/site-packages/lightning/pytorch/utilities/data.py:77: Trying to infer the `batch_size` from an ambiguous collection. The batch size we found is 7619. To avoid any miscalculations, use `self.log(..., batch_size=batch_size)`.\n",
      "/rds/general/user/cb1319/home/anaconda3/envs/Geom3D/lib/python3.11/site-packages/lightning/pytorch/utilities/data.py:77: Trying to infer the `batch_size` from an ambiguous collection. The batch size we found is 7835. To avoid any miscalculations, use `self.log(..., batch_size=batch_size)`.\n",
      "/rds/general/user/cb1319/home/anaconda3/envs/Geom3D/lib/python3.11/site-packages/lightning/pytorch/utilities/data.py:77: Trying to infer the `batch_size` from an ambiguous collection. The batch size we found is 7775. To avoid any miscalculations, use `self.log(..., batch_size=batch_size)`.\n",
      "/rds/general/user/cb1319/home/anaconda3/envs/Geom3D/lib/python3.11/site-packages/lightning/pytorch/utilities/data.py:77: Trying to infer the `batch_size` from an ambiguous collection. The batch size we found is 7785. To avoid any miscalculations, use `self.log(..., batch_size=batch_size)`.\n",
      "/rds/general/user/cb1319/home/anaconda3/envs/Geom3D/lib/python3.11/site-packages/lightning/pytorch/utilities/data.py:77: Trying to infer the `batch_size` from an ambiguous collection. The batch size we found is 7695. To avoid any miscalculations, use `self.log(..., batch_size=batch_size)`.\n",
      "/rds/general/user/cb1319/home/anaconda3/envs/Geom3D/lib/python3.11/site-packages/lightning/pytorch/utilities/data.py:77: Trying to infer the `batch_size` from an ambiguous collection. The batch size we found is 7531. To avoid any miscalculations, use `self.log(..., batch_size=batch_size)`.\n",
      "/rds/general/user/cb1319/home/anaconda3/envs/Geom3D/lib/python3.11/site-packages/lightning/pytorch/utilities/data.py:77: Trying to infer the `batch_size` from an ambiguous collection. The batch size we found is 7829. To avoid any miscalculations, use `self.log(..., batch_size=batch_size)`.\n",
      "/rds/general/user/cb1319/home/anaconda3/envs/Geom3D/lib/python3.11/site-packages/lightning/pytorch/utilities/data.py:77: Trying to infer the `batch_size` from an ambiguous collection. The batch size we found is 7777. To avoid any miscalculations, use `self.log(..., batch_size=batch_size)`.\n",
      "/rds/general/user/cb1319/home/anaconda3/envs/Geom3D/lib/python3.11/site-packages/lightning/pytorch/utilities/data.py:77: Trying to infer the `batch_size` from an ambiguous collection. The batch size we found is 7755. To avoid any miscalculations, use `self.log(..., batch_size=batch_size)`.\n",
      "/rds/general/user/cb1319/home/anaconda3/envs/Geom3D/lib/python3.11/site-packages/lightning/pytorch/utilities/data.py:77: Trying to infer the `batch_size` from an ambiguous collection. The batch size we found is 7497. To avoid any miscalculations, use `self.log(..., batch_size=batch_size)`.\n",
      "/rds/general/user/cb1319/home/anaconda3/envs/Geom3D/lib/python3.11/site-packages/lightning/pytorch/utilities/data.py:77: Trying to infer the `batch_size` from an ambiguous collection. The batch size we found is 7901. To avoid any miscalculations, use `self.log(..., batch_size=batch_size)`.\n",
      "/rds/general/user/cb1319/home/anaconda3/envs/Geom3D/lib/python3.11/site-packages/lightning/pytorch/utilities/data.py:77: Trying to infer the `batch_size` from an ambiguous collection. The batch size we found is 7768. To avoid any miscalculations, use `self.log(..., batch_size=batch_size)`.\n",
      "/rds/general/user/cb1319/home/anaconda3/envs/Geom3D/lib/python3.11/site-packages/lightning/pytorch/utilities/data.py:77: Trying to infer the `batch_size` from an ambiguous collection. The batch size we found is 7783. To avoid any miscalculations, use `self.log(..., batch_size=batch_size)`.\n",
      "/rds/general/user/cb1319/home/anaconda3/envs/Geom3D/lib/python3.11/site-packages/lightning/pytorch/utilities/data.py:77: Trying to infer the `batch_size` from an ambiguous collection. The batch size we found is 7538. To avoid any miscalculations, use `self.log(..., batch_size=batch_size)`.\n",
      "/rds/general/user/cb1319/home/anaconda3/envs/Geom3D/lib/python3.11/site-packages/lightning/pytorch/utilities/data.py:77: Trying to infer the `batch_size` from an ambiguous collection. The batch size we found is 7481. To avoid any miscalculations, use `self.log(..., batch_size=batch_size)`.\n",
      "/rds/general/user/cb1319/home/anaconda3/envs/Geom3D/lib/python3.11/site-packages/lightning/pytorch/utilities/data.py:77: Trying to infer the `batch_size` from an ambiguous collection. The batch size we found is 7911. To avoid any miscalculations, use `self.log(..., batch_size=batch_size)`.\n",
      "/rds/general/user/cb1319/home/anaconda3/envs/Geom3D/lib/python3.11/site-packages/lightning/pytorch/utilities/data.py:77: Trying to infer the `batch_size` from an ambiguous collection. The batch size we found is 7734. To avoid any miscalculations, use `self.log(..., batch_size=batch_size)`.\n",
      "/rds/general/user/cb1319/home/anaconda3/envs/Geom3D/lib/python3.11/site-packages/lightning/pytorch/utilities/data.py:77: Trying to infer the `batch_size` from an ambiguous collection. The batch size we found is 7762. To avoid any miscalculations, use `self.log(..., batch_size=batch_size)`.\n",
      "/rds/general/user/cb1319/home/anaconda3/envs/Geom3D/lib/python3.11/site-packages/lightning/pytorch/utilities/data.py:77: Trying to infer the `batch_size` from an ambiguous collection. The batch size we found is 7800. To avoid any miscalculations, use `self.log(..., batch_size=batch_size)`.\n",
      "/rds/general/user/cb1319/home/anaconda3/envs/Geom3D/lib/python3.11/site-packages/lightning/pytorch/utilities/data.py:77: Trying to infer the `batch_size` from an ambiguous collection. The batch size we found is 7626. To avoid any miscalculations, use `self.log(..., batch_size=batch_size)`.\n",
      "/rds/general/user/cb1319/home/anaconda3/envs/Geom3D/lib/python3.11/site-packages/lightning/pytorch/utilities/data.py:77: Trying to infer the `batch_size` from an ambiguous collection. The batch size we found is 7574. To avoid any miscalculations, use `self.log(..., batch_size=batch_size)`.\n",
      "/rds/general/user/cb1319/home/anaconda3/envs/Geom3D/lib/python3.11/site-packages/lightning/pytorch/utilities/data.py:77: Trying to infer the `batch_size` from an ambiguous collection. The batch size we found is 7973. To avoid any miscalculations, use `self.log(..., batch_size=batch_size)`.\n",
      "/rds/general/user/cb1319/home/anaconda3/envs/Geom3D/lib/python3.11/site-packages/lightning/pytorch/utilities/data.py:77: Trying to infer the `batch_size` from an ambiguous collection. The batch size we found is 7451. To avoid any miscalculations, use `self.log(..., batch_size=batch_size)`.\n"
     ]
    },
    {
     "data": {
      "application/vnd.jupyter.widget-view+json": {
       "model_id": "947adeba9f3e45b49c3868530626d35a",
       "version_major": 2,
       "version_minor": 0
      },
      "text/plain": [
       "Validation: |          | 0/? [00:00<?, ?it/s]"
      ]
     },
     "metadata": {},
     "output_type": "display_data"
    },
    {
     "name": "stderr",
     "output_type": "stream",
     "text": [
      "/rds/general/user/cb1319/home/anaconda3/envs/Geom3D/lib/python3.11/site-packages/lightning/pytorch/utilities/data.py:77: Trying to infer the `batch_size` from an ambiguous collection. The batch size we found is 8083. To avoid any miscalculations, use `self.log(..., batch_size=batch_size)`.\n",
      "/rds/general/user/cb1319/home/anaconda3/envs/Geom3D/lib/python3.11/site-packages/lightning/pytorch/utilities/data.py:77: Trying to infer the `batch_size` from an ambiguous collection. The batch size we found is 8052. To avoid any miscalculations, use `self.log(..., batch_size=batch_size)`.\n",
      "/rds/general/user/cb1319/home/anaconda3/envs/Geom3D/lib/python3.11/site-packages/lightning/pytorch/utilities/data.py:77: Trying to infer the `batch_size` from an ambiguous collection. The batch size we found is 8109. To avoid any miscalculations, use `self.log(..., batch_size=batch_size)`.\n",
      "/rds/general/user/cb1319/home/anaconda3/envs/Geom3D/lib/python3.11/site-packages/lightning/pytorch/utilities/data.py:77: Trying to infer the `batch_size` from an ambiguous collection. The batch size we found is 7564. To avoid any miscalculations, use `self.log(..., batch_size=batch_size)`.\n",
      "/rds/general/user/cb1319/home/anaconda3/envs/Geom3D/lib/python3.11/site-packages/lightning/pytorch/utilities/data.py:77: Trying to infer the `batch_size` from an ambiguous collection. The batch size we found is 7642. To avoid any miscalculations, use `self.log(..., batch_size=batch_size)`.\n",
      "/rds/general/user/cb1319/home/anaconda3/envs/Geom3D/lib/python3.11/site-packages/lightning/pytorch/utilities/data.py:77: Trying to infer the `batch_size` from an ambiguous collection. The batch size we found is 7776. To avoid any miscalculations, use `self.log(..., batch_size=batch_size)`.\n",
      "/rds/general/user/cb1319/home/anaconda3/envs/Geom3D/lib/python3.11/site-packages/lightning/pytorch/utilities/data.py:77: Trying to infer the `batch_size` from an ambiguous collection. The batch size we found is 7757. To avoid any miscalculations, use `self.log(..., batch_size=batch_size)`.\n",
      "/rds/general/user/cb1319/home/anaconda3/envs/Geom3D/lib/python3.11/site-packages/lightning/pytorch/utilities/data.py:77: Trying to infer the `batch_size` from an ambiguous collection. The batch size we found is 7842. To avoid any miscalculations, use `self.log(..., batch_size=batch_size)`.\n",
      "/rds/general/user/cb1319/home/anaconda3/envs/Geom3D/lib/python3.11/site-packages/lightning/pytorch/utilities/data.py:77: Trying to infer the `batch_size` from an ambiguous collection. The batch size we found is 7909. To avoid any miscalculations, use `self.log(..., batch_size=batch_size)`.\n",
      "/rds/general/user/cb1319/home/anaconda3/envs/Geom3D/lib/python3.11/site-packages/lightning/pytorch/utilities/data.py:77: Trying to infer the `batch_size` from an ambiguous collection. The batch size we found is 8070. To avoid any miscalculations, use `self.log(..., batch_size=batch_size)`.\n",
      "/rds/general/user/cb1319/home/anaconda3/envs/Geom3D/lib/python3.11/site-packages/lightning/pytorch/utilities/data.py:77: Trying to infer the `batch_size` from an ambiguous collection. The batch size we found is 7907. To avoid any miscalculations, use `self.log(..., batch_size=batch_size)`.\n",
      "/rds/general/user/cb1319/home/anaconda3/envs/Geom3D/lib/python3.11/site-packages/lightning/pytorch/utilities/data.py:77: Trying to infer the `batch_size` from an ambiguous collection. The batch size we found is 7825. To avoid any miscalculations, use `self.log(..., batch_size=batch_size)`.\n",
      "/rds/general/user/cb1319/home/anaconda3/envs/Geom3D/lib/python3.11/site-packages/lightning/pytorch/utilities/data.py:77: Trying to infer the `batch_size` from an ambiguous collection. The batch size we found is 7653. To avoid any miscalculations, use `self.log(..., batch_size=batch_size)`.\n",
      "/rds/general/user/cb1319/home/anaconda3/envs/Geom3D/lib/python3.11/site-packages/lightning/pytorch/utilities/data.py:77: Trying to infer the `batch_size` from an ambiguous collection. The batch size we found is 7891. To avoid any miscalculations, use `self.log(..., batch_size=batch_size)`.\n",
      "/rds/general/user/cb1319/home/anaconda3/envs/Geom3D/lib/python3.11/site-packages/lightning/pytorch/utilities/data.py:77: Trying to infer the `batch_size` from an ambiguous collection. The batch size we found is 7458. To avoid any miscalculations, use `self.log(..., batch_size=batch_size)`.\n",
      "/rds/general/user/cb1319/home/anaconda3/envs/Geom3D/lib/python3.11/site-packages/lightning/pytorch/utilities/data.py:77: Trying to infer the `batch_size` from an ambiguous collection. The batch size we found is 7770. To avoid any miscalculations, use `self.log(..., batch_size=batch_size)`.\n",
      "/rds/general/user/cb1319/home/anaconda3/envs/Geom3D/lib/python3.11/site-packages/lightning/pytorch/utilities/data.py:77: Trying to infer the `batch_size` from an ambiguous collection. The batch size we found is 7702. To avoid any miscalculations, use `self.log(..., batch_size=batch_size)`.\n",
      "/rds/general/user/cb1319/home/anaconda3/envs/Geom3D/lib/python3.11/site-packages/lightning/pytorch/utilities/data.py:77: Trying to infer the `batch_size` from an ambiguous collection. The batch size we found is 7968. To avoid any miscalculations, use `self.log(..., batch_size=batch_size)`.\n",
      "/rds/general/user/cb1319/home/anaconda3/envs/Geom3D/lib/python3.11/site-packages/lightning/pytorch/utilities/data.py:77: Trying to infer the `batch_size` from an ambiguous collection. The batch size we found is 7948. To avoid any miscalculations, use `self.log(..., batch_size=batch_size)`.\n",
      "/rds/general/user/cb1319/home/anaconda3/envs/Geom3D/lib/python3.11/site-packages/lightning/pytorch/utilities/data.py:77: Trying to infer the `batch_size` from an ambiguous collection. The batch size we found is 7854. To avoid any miscalculations, use `self.log(..., batch_size=batch_size)`.\n",
      "/rds/general/user/cb1319/home/anaconda3/envs/Geom3D/lib/python3.11/site-packages/lightning/pytorch/utilities/data.py:77: Trying to infer the `batch_size` from an ambiguous collection. The batch size we found is 7645. To avoid any miscalculations, use `self.log(..., batch_size=batch_size)`.\n",
      "/rds/general/user/cb1319/home/anaconda3/envs/Geom3D/lib/python3.11/site-packages/lightning/pytorch/utilities/data.py:77: Trying to infer the `batch_size` from an ambiguous collection. The batch size we found is 7844. To avoid any miscalculations, use `self.log(..., batch_size=batch_size)`.\n",
      "/rds/general/user/cb1319/home/anaconda3/envs/Geom3D/lib/python3.11/site-packages/lightning/pytorch/utilities/data.py:77: Trying to infer the `batch_size` from an ambiguous collection. The batch size we found is 7560. To avoid any miscalculations, use `self.log(..., batch_size=batch_size)`.\n",
      "/rds/general/user/cb1319/home/anaconda3/envs/Geom3D/lib/python3.11/site-packages/lightning/pytorch/utilities/data.py:77: Trying to infer the `batch_size` from an ambiguous collection. The batch size we found is 7929. To avoid any miscalculations, use `self.log(..., batch_size=batch_size)`.\n",
      "/rds/general/user/cb1319/home/anaconda3/envs/Geom3D/lib/python3.11/site-packages/lightning/pytorch/utilities/data.py:77: Trying to infer the `batch_size` from an ambiguous collection. The batch size we found is 7759. To avoid any miscalculations, use `self.log(..., batch_size=batch_size)`.\n",
      "/rds/general/user/cb1319/home/anaconda3/envs/Geom3D/lib/python3.11/site-packages/lightning/pytorch/utilities/data.py:77: Trying to infer the `batch_size` from an ambiguous collection. The batch size we found is 7692. To avoid any miscalculations, use `self.log(..., batch_size=batch_size)`.\n",
      "/rds/general/user/cb1319/home/anaconda3/envs/Geom3D/lib/python3.11/site-packages/lightning/pytorch/utilities/data.py:77: Trying to infer the `batch_size` from an ambiguous collection. The batch size we found is 8102. To avoid any miscalculations, use `self.log(..., batch_size=batch_size)`.\n",
      "/rds/general/user/cb1319/home/anaconda3/envs/Geom3D/lib/python3.11/site-packages/lightning/pytorch/utilities/data.py:77: Trying to infer the `batch_size` from an ambiguous collection. The batch size we found is 7639. To avoid any miscalculations, use `self.log(..., batch_size=batch_size)`.\n",
      "/rds/general/user/cb1319/home/anaconda3/envs/Geom3D/lib/python3.11/site-packages/lightning/pytorch/utilities/data.py:77: Trying to infer the `batch_size` from an ambiguous collection. The batch size we found is 7814. To avoid any miscalculations, use `self.log(..., batch_size=batch_size)`.\n",
      "/rds/general/user/cb1319/home/anaconda3/envs/Geom3D/lib/python3.11/site-packages/lightning/pytorch/utilities/data.py:77: Trying to infer the `batch_size` from an ambiguous collection. The batch size we found is 7727. To avoid any miscalculations, use `self.log(..., batch_size=batch_size)`.\n",
      "/rds/general/user/cb1319/home/anaconda3/envs/Geom3D/lib/python3.11/site-packages/lightning/pytorch/utilities/data.py:77: Trying to infer the `batch_size` from an ambiguous collection. The batch size we found is 7756. To avoid any miscalculations, use `self.log(..., batch_size=batch_size)`.\n",
      "/rds/general/user/cb1319/home/anaconda3/envs/Geom3D/lib/python3.11/site-packages/lightning/pytorch/utilities/data.py:77: Trying to infer the `batch_size` from an ambiguous collection. The batch size we found is 7943. To avoid any miscalculations, use `self.log(..., batch_size=batch_size)`.\n",
      "/rds/general/user/cb1319/home/anaconda3/envs/Geom3D/lib/python3.11/site-packages/lightning/pytorch/utilities/data.py:77: Trying to infer the `batch_size` from an ambiguous collection. The batch size we found is 7915. To avoid any miscalculations, use `self.log(..., batch_size=batch_size)`.\n",
      "/rds/general/user/cb1319/home/anaconda3/envs/Geom3D/lib/python3.11/site-packages/lightning/pytorch/utilities/data.py:77: Trying to infer the `batch_size` from an ambiguous collection. The batch size we found is 7444. To avoid any miscalculations, use `self.log(..., batch_size=batch_size)`.\n",
      "/rds/general/user/cb1319/home/anaconda3/envs/Geom3D/lib/python3.11/site-packages/lightning/pytorch/utilities/data.py:77: Trying to infer the `batch_size` from an ambiguous collection. The batch size we found is 7640. To avoid any miscalculations, use `self.log(..., batch_size=batch_size)`.\n",
      "/rds/general/user/cb1319/home/anaconda3/envs/Geom3D/lib/python3.11/site-packages/lightning/pytorch/utilities/data.py:77: Trying to infer the `batch_size` from an ambiguous collection. The batch size we found is 7566. To avoid any miscalculations, use `self.log(..., batch_size=batch_size)`.\n",
      "/rds/general/user/cb1319/home/anaconda3/envs/Geom3D/lib/python3.11/site-packages/lightning/pytorch/utilities/data.py:77: Trying to infer the `batch_size` from an ambiguous collection. The batch size we found is 7878. To avoid any miscalculations, use `self.log(..., batch_size=batch_size)`.\n",
      "/rds/general/user/cb1319/home/anaconda3/envs/Geom3D/lib/python3.11/site-packages/lightning/pytorch/utilities/data.py:77: Trying to infer the `batch_size` from an ambiguous collection. The batch size we found is 7709. To avoid any miscalculations, use `self.log(..., batch_size=batch_size)`.\n",
      "/rds/general/user/cb1319/home/anaconda3/envs/Geom3D/lib/python3.11/site-packages/lightning/pytorch/utilities/data.py:77: Trying to infer the `batch_size` from an ambiguous collection. The batch size we found is 8197. To avoid any miscalculations, use `self.log(..., batch_size=batch_size)`.\n",
      "/rds/general/user/cb1319/home/anaconda3/envs/Geom3D/lib/python3.11/site-packages/lightning/pytorch/utilities/data.py:77: Trying to infer the `batch_size` from an ambiguous collection. The batch size we found is 7718. To avoid any miscalculations, use `self.log(..., batch_size=batch_size)`.\n",
      "/rds/general/user/cb1319/home/anaconda3/envs/Geom3D/lib/python3.11/site-packages/lightning/pytorch/utilities/data.py:77: Trying to infer the `batch_size` from an ambiguous collection. The batch size we found is 7927. To avoid any miscalculations, use `self.log(..., batch_size=batch_size)`.\n",
      "/rds/general/user/cb1319/home/anaconda3/envs/Geom3D/lib/python3.11/site-packages/lightning/pytorch/utilities/data.py:77: Trying to infer the `batch_size` from an ambiguous collection. The batch size we found is 8224. To avoid any miscalculations, use `self.log(..., batch_size=batch_size)`.\n",
      "/rds/general/user/cb1319/home/anaconda3/envs/Geom3D/lib/python3.11/site-packages/lightning/pytorch/utilities/data.py:77: Trying to infer the `batch_size` from an ambiguous collection. The batch size we found is 8324. To avoid any miscalculations, use `self.log(..., batch_size=batch_size)`.\n",
      "/rds/general/user/cb1319/home/anaconda3/envs/Geom3D/lib/python3.11/site-packages/lightning/pytorch/utilities/data.py:77: Trying to infer the `batch_size` from an ambiguous collection. The batch size we found is 7831. To avoid any miscalculations, use `self.log(..., batch_size=batch_size)`.\n",
      "/rds/general/user/cb1319/home/anaconda3/envs/Geom3D/lib/python3.11/site-packages/lightning/pytorch/utilities/data.py:77: Trying to infer the `batch_size` from an ambiguous collection. The batch size we found is 7851. To avoid any miscalculations, use `self.log(..., batch_size=batch_size)`.\n",
      "/rds/general/user/cb1319/home/anaconda3/envs/Geom3D/lib/python3.11/site-packages/lightning/pytorch/utilities/data.py:77: Trying to infer the `batch_size` from an ambiguous collection. The batch size we found is 7886. To avoid any miscalculations, use `self.log(..., batch_size=batch_size)`.\n",
      "/rds/general/user/cb1319/home/anaconda3/envs/Geom3D/lib/python3.11/site-packages/lightning/pytorch/utilities/data.py:77: Trying to infer the `batch_size` from an ambiguous collection. The batch size we found is 7873. To avoid any miscalculations, use `self.log(..., batch_size=batch_size)`.\n",
      "/rds/general/user/cb1319/home/anaconda3/envs/Geom3D/lib/python3.11/site-packages/lightning/pytorch/utilities/data.py:77: Trying to infer the `batch_size` from an ambiguous collection. The batch size we found is 7919. To avoid any miscalculations, use `self.log(..., batch_size=batch_size)`.\n",
      "/rds/general/user/cb1319/home/anaconda3/envs/Geom3D/lib/python3.11/site-packages/lightning/pytorch/utilities/data.py:77: Trying to infer the `batch_size` from an ambiguous collection. The batch size we found is 7610. To avoid any miscalculations, use `self.log(..., batch_size=batch_size)`.\n",
      "/rds/general/user/cb1319/home/anaconda3/envs/Geom3D/lib/python3.11/site-packages/lightning/pytorch/utilities/data.py:77: Trying to infer the `batch_size` from an ambiguous collection. The batch size we found is 7883. To avoid any miscalculations, use `self.log(..., batch_size=batch_size)`.\n",
      "/rds/general/user/cb1319/home/anaconda3/envs/Geom3D/lib/python3.11/site-packages/lightning/pytorch/utilities/data.py:77: Trying to infer the `batch_size` from an ambiguous collection. The batch size we found is 7890. To avoid any miscalculations, use `self.log(..., batch_size=batch_size)`.\n",
      "/rds/general/user/cb1319/home/anaconda3/envs/Geom3D/lib/python3.11/site-packages/lightning/pytorch/utilities/data.py:77: Trying to infer the `batch_size` from an ambiguous collection. The batch size we found is 7906. To avoid any miscalculations, use `self.log(..., batch_size=batch_size)`.\n",
      "/rds/general/user/cb1319/home/anaconda3/envs/Geom3D/lib/python3.11/site-packages/lightning/pytorch/utilities/data.py:77: Trying to infer the `batch_size` from an ambiguous collection. The batch size we found is 7550. To avoid any miscalculations, use `self.log(..., batch_size=batch_size)`.\n",
      "/rds/general/user/cb1319/home/anaconda3/envs/Geom3D/lib/python3.11/site-packages/lightning/pytorch/utilities/data.py:77: Trying to infer the `batch_size` from an ambiguous collection. The batch size we found is 7781. To avoid any miscalculations, use `self.log(..., batch_size=batch_size)`.\n",
      "/rds/general/user/cb1319/home/anaconda3/envs/Geom3D/lib/python3.11/site-packages/lightning/pytorch/utilities/data.py:77: Trying to infer the `batch_size` from an ambiguous collection. The batch size we found is 7522. To avoid any miscalculations, use `self.log(..., batch_size=batch_size)`.\n",
      "/rds/general/user/cb1319/home/anaconda3/envs/Geom3D/lib/python3.11/site-packages/lightning/pytorch/utilities/data.py:77: Trying to infer the `batch_size` from an ambiguous collection. The batch size we found is 7638. To avoid any miscalculations, use `self.log(..., batch_size=batch_size)`.\n",
      "/rds/general/user/cb1319/home/anaconda3/envs/Geom3D/lib/python3.11/site-packages/lightning/pytorch/utilities/data.py:77: Trying to infer the `batch_size` from an ambiguous collection. The batch size we found is 7760. To avoid any miscalculations, use `self.log(..., batch_size=batch_size)`.\n",
      "/rds/general/user/cb1319/home/anaconda3/envs/Geom3D/lib/python3.11/site-packages/lightning/pytorch/utilities/data.py:77: Trying to infer the `batch_size` from an ambiguous collection. The batch size we found is 7938. To avoid any miscalculations, use `self.log(..., batch_size=batch_size)`.\n",
      "/rds/general/user/cb1319/home/anaconda3/envs/Geom3D/lib/python3.11/site-packages/lightning/pytorch/utilities/data.py:77: Trying to infer the `batch_size` from an ambiguous collection. The batch size we found is 8267. To avoid any miscalculations, use `self.log(..., batch_size=batch_size)`.\n",
      "/rds/general/user/cb1319/home/anaconda3/envs/Geom3D/lib/python3.11/site-packages/lightning/pytorch/utilities/data.py:77: Trying to infer the `batch_size` from an ambiguous collection. The batch size we found is 7699. To avoid any miscalculations, use `self.log(..., batch_size=batch_size)`.\n",
      "/rds/general/user/cb1319/home/anaconda3/envs/Geom3D/lib/python3.11/site-packages/lightning/pytorch/utilities/data.py:77: Trying to infer the `batch_size` from an ambiguous collection. The batch size we found is 7856. To avoid any miscalculations, use `self.log(..., batch_size=batch_size)`.\n",
      "/rds/general/user/cb1319/home/anaconda3/envs/Geom3D/lib/python3.11/site-packages/lightning/pytorch/utilities/data.py:77: Trying to infer the `batch_size` from an ambiguous collection. The batch size we found is 7908. To avoid any miscalculations, use `self.log(..., batch_size=batch_size)`.\n",
      "/rds/general/user/cb1319/home/anaconda3/envs/Geom3D/lib/python3.11/site-packages/lightning/pytorch/utilities/data.py:77: Trying to infer the `batch_size` from an ambiguous collection. The batch size we found is 7889. To avoid any miscalculations, use `self.log(..., batch_size=batch_size)`.\n",
      "/rds/general/user/cb1319/home/anaconda3/envs/Geom3D/lib/python3.11/site-packages/lightning/pytorch/utilities/data.py:77: Trying to infer the `batch_size` from an ambiguous collection. The batch size we found is 8161. To avoid any miscalculations, use `self.log(..., batch_size=batch_size)`.\n",
      "/rds/general/user/cb1319/home/anaconda3/envs/Geom3D/lib/python3.11/site-packages/lightning/pytorch/utilities/data.py:77: Trying to infer the `batch_size` from an ambiguous collection. The batch size we found is 7723. To avoid any miscalculations, use `self.log(..., batch_size=batch_size)`.\n",
      "/rds/general/user/cb1319/home/anaconda3/envs/Geom3D/lib/python3.11/site-packages/lightning/pytorch/utilities/data.py:77: Trying to infer the `batch_size` from an ambiguous collection. The batch size we found is 8123. To avoid any miscalculations, use `self.log(..., batch_size=batch_size)`.\n",
      "/rds/general/user/cb1319/home/anaconda3/envs/Geom3D/lib/python3.11/site-packages/lightning/pytorch/utilities/data.py:77: Trying to infer the `batch_size` from an ambiguous collection. The batch size we found is 8374. To avoid any miscalculations, use `self.log(..., batch_size=batch_size)`.\n",
      "/rds/general/user/cb1319/home/anaconda3/envs/Geom3D/lib/python3.11/site-packages/lightning/pytorch/utilities/data.py:77: Trying to infer the `batch_size` from an ambiguous collection. The batch size we found is 7677. To avoid any miscalculations, use `self.log(..., batch_size=batch_size)`.\n",
      "/rds/general/user/cb1319/home/anaconda3/envs/Geom3D/lib/python3.11/site-packages/lightning/pytorch/utilities/data.py:77: Trying to infer the `batch_size` from an ambiguous collection. The batch size we found is 7725. To avoid any miscalculations, use `self.log(..., batch_size=batch_size)`.\n",
      "/rds/general/user/cb1319/home/anaconda3/envs/Geom3D/lib/python3.11/site-packages/lightning/pytorch/utilities/data.py:77: Trying to infer the `batch_size` from an ambiguous collection. The batch size we found is 7790. To avoid any miscalculations, use `self.log(..., batch_size=batch_size)`.\n",
      "/rds/general/user/cb1319/home/anaconda3/envs/Geom3D/lib/python3.11/site-packages/lightning/pytorch/utilities/data.py:77: Trying to infer the `batch_size` from an ambiguous collection. The batch size we found is 7601. To avoid any miscalculations, use `self.log(..., batch_size=batch_size)`.\n",
      "/rds/general/user/cb1319/home/anaconda3/envs/Geom3D/lib/python3.11/site-packages/lightning/pytorch/utilities/data.py:77: Trying to infer the `batch_size` from an ambiguous collection. The batch size we found is 7398. To avoid any miscalculations, use `self.log(..., batch_size=batch_size)`.\n",
      "/rds/general/user/cb1319/home/anaconda3/envs/Geom3D/lib/python3.11/site-packages/lightning/pytorch/utilities/data.py:77: Trying to infer the `batch_size` from an ambiguous collection. The batch size we found is 7516. To avoid any miscalculations, use `self.log(..., batch_size=batch_size)`.\n",
      "/rds/general/user/cb1319/home/anaconda3/envs/Geom3D/lib/python3.11/site-packages/lightning/pytorch/utilities/data.py:77: Trying to infer the `batch_size` from an ambiguous collection. The batch size we found is 7962. To avoid any miscalculations, use `self.log(..., batch_size=batch_size)`.\n",
      "/rds/general/user/cb1319/home/anaconda3/envs/Geom3D/lib/python3.11/site-packages/lightning/pytorch/utilities/data.py:77: Trying to infer the `batch_size` from an ambiguous collection. The batch size we found is 7490. To avoid any miscalculations, use `self.log(..., batch_size=batch_size)`.\n",
      "/rds/general/user/cb1319/home/anaconda3/envs/Geom3D/lib/python3.11/site-packages/lightning/pytorch/utilities/data.py:77: Trying to infer the `batch_size` from an ambiguous collection. The batch size we found is 7925. To avoid any miscalculations, use `self.log(..., batch_size=batch_size)`.\n",
      "/rds/general/user/cb1319/home/anaconda3/envs/Geom3D/lib/python3.11/site-packages/lightning/pytorch/utilities/data.py:77: Trying to infer the `batch_size` from an ambiguous collection. The batch size we found is 7525. To avoid any miscalculations, use `self.log(..., batch_size=batch_size)`.\n",
      "/rds/general/user/cb1319/home/anaconda3/envs/Geom3D/lib/python3.11/site-packages/lightning/pytorch/utilities/data.py:77: Trying to infer the `batch_size` from an ambiguous collection. The batch size we found is 7663. To avoid any miscalculations, use `self.log(..., batch_size=batch_size)`.\n",
      "/rds/general/user/cb1319/home/anaconda3/envs/Geom3D/lib/python3.11/site-packages/lightning/pytorch/utilities/data.py:77: Trying to infer the `batch_size` from an ambiguous collection. The batch size we found is 7511. To avoid any miscalculations, use `self.log(..., batch_size=batch_size)`.\n",
      "/rds/general/user/cb1319/home/anaconda3/envs/Geom3D/lib/python3.11/site-packages/lightning/pytorch/utilities/data.py:77: Trying to infer the `batch_size` from an ambiguous collection. The batch size we found is 7704. To avoid any miscalculations, use `self.log(..., batch_size=batch_size)`.\n",
      "/rds/general/user/cb1319/home/anaconda3/envs/Geom3D/lib/python3.11/site-packages/lightning/pytorch/utilities/data.py:77: Trying to infer the `batch_size` from an ambiguous collection. The batch size we found is 7923. To avoid any miscalculations, use `self.log(..., batch_size=batch_size)`.\n",
      "/rds/general/user/cb1319/home/anaconda3/envs/Geom3D/lib/python3.11/site-packages/lightning/pytorch/utilities/data.py:77: Trying to infer the `batch_size` from an ambiguous collection. The batch size we found is 7681. To avoid any miscalculations, use `self.log(..., batch_size=batch_size)`.\n",
      "/rds/general/user/cb1319/home/anaconda3/envs/Geom3D/lib/python3.11/site-packages/lightning/pytorch/utilities/data.py:77: Trying to infer the `batch_size` from an ambiguous collection. The batch size we found is 7920. To avoid any miscalculations, use `self.log(..., batch_size=batch_size)`.\n",
      "/rds/general/user/cb1319/home/anaconda3/envs/Geom3D/lib/python3.11/site-packages/lightning/pytorch/utilities/data.py:77: Trying to infer the `batch_size` from an ambiguous collection. The batch size we found is 7356. To avoid any miscalculations, use `self.log(..., batch_size=batch_size)`.\n",
      "/rds/general/user/cb1319/home/anaconda3/envs/Geom3D/lib/python3.11/site-packages/lightning/pytorch/utilities/data.py:77: Trying to infer the `batch_size` from an ambiguous collection. The batch size we found is 7604. To avoid any miscalculations, use `self.log(..., batch_size=batch_size)`.\n",
      "/rds/general/user/cb1319/home/anaconda3/envs/Geom3D/lib/python3.11/site-packages/lightning/pytorch/utilities/data.py:77: Trying to infer the `batch_size` from an ambiguous collection. The batch size we found is 7740. To avoid any miscalculations, use `self.log(..., batch_size=batch_size)`.\n",
      "/rds/general/user/cb1319/home/anaconda3/envs/Geom3D/lib/python3.11/site-packages/lightning/pytorch/utilities/data.py:77: Trying to infer the `batch_size` from an ambiguous collection. The batch size we found is 8147. To avoid any miscalculations, use `self.log(..., batch_size=batch_size)`.\n",
      "/rds/general/user/cb1319/home/anaconda3/envs/Geom3D/lib/python3.11/site-packages/lightning/pytorch/utilities/data.py:77: Trying to infer the `batch_size` from an ambiguous collection. The batch size we found is 7450. To avoid any miscalculations, use `self.log(..., batch_size=batch_size)`.\n",
      "/rds/general/user/cb1319/home/anaconda3/envs/Geom3D/lib/python3.11/site-packages/lightning/pytorch/utilities/data.py:77: Trying to infer the `batch_size` from an ambiguous collection. The batch size we found is 7833. To avoid any miscalculations, use `self.log(..., batch_size=batch_size)`.\n",
      "/rds/general/user/cb1319/home/anaconda3/envs/Geom3D/lib/python3.11/site-packages/lightning/pytorch/utilities/data.py:77: Trying to infer the `batch_size` from an ambiguous collection. The batch size we found is 7963. To avoid any miscalculations, use `self.log(..., batch_size=batch_size)`.\n",
      "/rds/general/user/cb1319/home/anaconda3/envs/Geom3D/lib/python3.11/site-packages/lightning/pytorch/utilities/data.py:77: Trying to infer the `batch_size` from an ambiguous collection. The batch size we found is 7822. To avoid any miscalculations, use `self.log(..., batch_size=batch_size)`.\n",
      "/rds/general/user/cb1319/home/anaconda3/envs/Geom3D/lib/python3.11/site-packages/lightning/pytorch/utilities/data.py:77: Trying to infer the `batch_size` from an ambiguous collection. The batch size we found is 7786. To avoid any miscalculations, use `self.log(..., batch_size=batch_size)`.\n",
      "/rds/general/user/cb1319/home/anaconda3/envs/Geom3D/lib/python3.11/site-packages/lightning/pytorch/utilities/data.py:77: Trying to infer the `batch_size` from an ambiguous collection. The batch size we found is 7794. To avoid any miscalculations, use `self.log(..., batch_size=batch_size)`.\n",
      "/rds/general/user/cb1319/home/anaconda3/envs/Geom3D/lib/python3.11/site-packages/lightning/pytorch/utilities/data.py:77: Trying to infer the `batch_size` from an ambiguous collection. The batch size we found is 7654. To avoid any miscalculations, use `self.log(..., batch_size=batch_size)`.\n"
     ]
    },
    {
     "data": {
      "application/vnd.jupyter.widget-view+json": {
       "model_id": "780ee516c6ac48b5ba3b7af25e0acd4e",
       "version_major": 2,
       "version_minor": 0
      },
      "text/plain": [
       "Validation: |          | 0/? [00:00<?, ?it/s]"
      ]
     },
     "metadata": {},
     "output_type": "display_data"
    },
    {
     "name": "stderr",
     "output_type": "stream",
     "text": [
      "/rds/general/user/cb1319/home/anaconda3/envs/Geom3D/lib/python3.11/site-packages/lightning/pytorch/utilities/data.py:77: Trying to infer the `batch_size` from an ambiguous collection. The batch size we found is 7500. To avoid any miscalculations, use `self.log(..., batch_size=batch_size)`.\n",
      "/rds/general/user/cb1319/home/anaconda3/envs/Geom3D/lib/python3.11/site-packages/lightning/pytorch/utilities/data.py:77: Trying to infer the `batch_size` from an ambiguous collection. The batch size we found is 7895. To avoid any miscalculations, use `self.log(..., batch_size=batch_size)`.\n",
      "/rds/general/user/cb1319/home/anaconda3/envs/Geom3D/lib/python3.11/site-packages/lightning/pytorch/utilities/data.py:77: Trying to infer the `batch_size` from an ambiguous collection. The batch size we found is 7932. To avoid any miscalculations, use `self.log(..., batch_size=batch_size)`.\n",
      "/rds/general/user/cb1319/home/anaconda3/envs/Geom3D/lib/python3.11/site-packages/lightning/pytorch/utilities/data.py:77: Trying to infer the `batch_size` from an ambiguous collection. The batch size we found is 8100. To avoid any miscalculations, use `self.log(..., batch_size=batch_size)`.\n",
      "/rds/general/user/cb1319/home/anaconda3/envs/Geom3D/lib/python3.11/site-packages/lightning/pytorch/utilities/data.py:77: Trying to infer the `batch_size` from an ambiguous collection. The batch size we found is 7871. To avoid any miscalculations, use `self.log(..., batch_size=batch_size)`.\n",
      "/rds/general/user/cb1319/home/anaconda3/envs/Geom3D/lib/python3.11/site-packages/lightning/pytorch/utilities/data.py:77: Trying to infer the `batch_size` from an ambiguous collection. The batch size we found is 7791. To avoid any miscalculations, use `self.log(..., batch_size=batch_size)`.\n",
      "/rds/general/user/cb1319/home/anaconda3/envs/Geom3D/lib/python3.11/site-packages/lightning/pytorch/utilities/data.py:77: Trying to infer the `batch_size` from an ambiguous collection. The batch size we found is 7949. To avoid any miscalculations, use `self.log(..., batch_size=batch_size)`.\n",
      "/rds/general/user/cb1319/home/anaconda3/envs/Geom3D/lib/python3.11/site-packages/lightning/pytorch/utilities/data.py:77: Trying to infer the `batch_size` from an ambiguous collection. The batch size we found is 7693. To avoid any miscalculations, use `self.log(..., batch_size=batch_size)`.\n",
      "/rds/general/user/cb1319/home/anaconda3/envs/Geom3D/lib/python3.11/site-packages/lightning/pytorch/utilities/data.py:77: Trying to infer the `batch_size` from an ambiguous collection. The batch size we found is 7729. To avoid any miscalculations, use `self.log(..., batch_size=batch_size)`.\n",
      "/rds/general/user/cb1319/home/anaconda3/envs/Geom3D/lib/python3.11/site-packages/lightning/pytorch/utilities/data.py:77: Trying to infer the `batch_size` from an ambiguous collection. The batch size we found is 7864. To avoid any miscalculations, use `self.log(..., batch_size=batch_size)`.\n",
      "/rds/general/user/cb1319/home/anaconda3/envs/Geom3D/lib/python3.11/site-packages/lightning/pytorch/utilities/data.py:77: Trying to infer the `batch_size` from an ambiguous collection. The batch size we found is 7553. To avoid any miscalculations, use `self.log(..., batch_size=batch_size)`.\n",
      "/rds/general/user/cb1319/home/anaconda3/envs/Geom3D/lib/python3.11/site-packages/lightning/pytorch/utilities/data.py:77: Trying to infer the `batch_size` from an ambiguous collection. The batch size we found is 7343. To avoid any miscalculations, use `self.log(..., batch_size=batch_size)`.\n",
      "/rds/general/user/cb1319/home/anaconda3/envs/Geom3D/lib/python3.11/site-packages/lightning/pytorch/utilities/data.py:77: Trying to infer the `batch_size` from an ambiguous collection. The batch size we found is 7478. To avoid any miscalculations, use `self.log(..., batch_size=batch_size)`.\n",
      "/rds/general/user/cb1319/home/anaconda3/envs/Geom3D/lib/python3.11/site-packages/lightning/pytorch/utilities/data.py:77: Trying to infer the `batch_size` from an ambiguous collection. The batch size we found is 8005. To avoid any miscalculations, use `self.log(..., batch_size=batch_size)`.\n",
      "/rds/general/user/cb1319/home/anaconda3/envs/Geom3D/lib/python3.11/site-packages/lightning/pytorch/utilities/data.py:77: Trying to infer the `batch_size` from an ambiguous collection. The batch size we found is 7571. To avoid any miscalculations, use `self.log(..., batch_size=batch_size)`.\n",
      "/rds/general/user/cb1319/home/anaconda3/envs/Geom3D/lib/python3.11/site-packages/lightning/pytorch/utilities/data.py:77: Trying to infer the `batch_size` from an ambiguous collection. The batch size we found is 7475. To avoid any miscalculations, use `self.log(..., batch_size=batch_size)`.\n",
      "/rds/general/user/cb1319/home/anaconda3/envs/Geom3D/lib/python3.11/site-packages/lightning/pytorch/utilities/data.py:77: Trying to infer the `batch_size` from an ambiguous collection. The batch size we found is 7810. To avoid any miscalculations, use `self.log(..., batch_size=batch_size)`.\n",
      "/rds/general/user/cb1319/home/anaconda3/envs/Geom3D/lib/python3.11/site-packages/lightning/pytorch/utilities/data.py:77: Trying to infer the `batch_size` from an ambiguous collection. The batch size we found is 7616. To avoid any miscalculations, use `self.log(..., batch_size=batch_size)`.\n",
      "/rds/general/user/cb1319/home/anaconda3/envs/Geom3D/lib/python3.11/site-packages/lightning/pytorch/utilities/data.py:77: Trying to infer the `batch_size` from an ambiguous collection. The batch size we found is 7582. To avoid any miscalculations, use `self.log(..., batch_size=batch_size)`.\n",
      "/rds/general/user/cb1319/home/anaconda3/envs/Geom3D/lib/python3.11/site-packages/lightning/pytorch/utilities/data.py:77: Trying to infer the `batch_size` from an ambiguous collection. The batch size we found is 7700. To avoid any miscalculations, use `self.log(..., batch_size=batch_size)`.\n",
      "/rds/general/user/cb1319/home/anaconda3/envs/Geom3D/lib/python3.11/site-packages/lightning/pytorch/utilities/data.py:77: Trying to infer the `batch_size` from an ambiguous collection. The batch size we found is 8014. To avoid any miscalculations, use `self.log(..., batch_size=batch_size)`.\n",
      "/rds/general/user/cb1319/home/anaconda3/envs/Geom3D/lib/python3.11/site-packages/lightning/pytorch/utilities/data.py:77: Trying to infer the `batch_size` from an ambiguous collection. The batch size we found is 8040. To avoid any miscalculations, use `self.log(..., batch_size=batch_size)`.\n",
      "/rds/general/user/cb1319/home/anaconda3/envs/Geom3D/lib/python3.11/site-packages/lightning/pytorch/utilities/data.py:77: Trying to infer the `batch_size` from an ambiguous collection. The batch size we found is 7701. To avoid any miscalculations, use `self.log(..., batch_size=batch_size)`.\n",
      "/rds/general/user/cb1319/home/anaconda3/envs/Geom3D/lib/python3.11/site-packages/lightning/pytorch/utilities/data.py:77: Trying to infer the `batch_size` from an ambiguous collection. The batch size we found is 7862. To avoid any miscalculations, use `self.log(..., batch_size=batch_size)`.\n",
      "/rds/general/user/cb1319/home/anaconda3/envs/Geom3D/lib/python3.11/site-packages/lightning/pytorch/utilities/data.py:77: Trying to infer the `batch_size` from an ambiguous collection. The batch size we found is 8053. To avoid any miscalculations, use `self.log(..., batch_size=batch_size)`.\n",
      "/rds/general/user/cb1319/home/anaconda3/envs/Geom3D/lib/python3.11/site-packages/lightning/pytorch/utilities/data.py:77: Trying to infer the `batch_size` from an ambiguous collection. The batch size we found is 7766. To avoid any miscalculations, use `self.log(..., batch_size=batch_size)`.\n",
      "/rds/general/user/cb1319/home/anaconda3/envs/Geom3D/lib/python3.11/site-packages/lightning/pytorch/utilities/data.py:77: Trying to infer the `batch_size` from an ambiguous collection. The batch size we found is 7778. To avoid any miscalculations, use `self.log(..., batch_size=batch_size)`.\n",
      "/rds/general/user/cb1319/home/anaconda3/envs/Geom3D/lib/python3.11/site-packages/lightning/pytorch/utilities/data.py:77: Trying to infer the `batch_size` from an ambiguous collection. The batch size we found is 7876. To avoid any miscalculations, use `self.log(..., batch_size=batch_size)`.\n",
      "/rds/general/user/cb1319/home/anaconda3/envs/Geom3D/lib/python3.11/site-packages/lightning/pytorch/utilities/data.py:77: Trying to infer the `batch_size` from an ambiguous collection. The batch size we found is 8121. To avoid any miscalculations, use `self.log(..., batch_size=batch_size)`.\n",
      "/rds/general/user/cb1319/home/anaconda3/envs/Geom3D/lib/python3.11/site-packages/lightning/pytorch/utilities/data.py:77: Trying to infer the `batch_size` from an ambiguous collection. The batch size we found is 7748. To avoid any miscalculations, use `self.log(..., batch_size=batch_size)`.\n",
      "/rds/general/user/cb1319/home/anaconda3/envs/Geom3D/lib/python3.11/site-packages/lightning/pytorch/utilities/data.py:77: Trying to infer the `batch_size` from an ambiguous collection. The batch size we found is 7666. To avoid any miscalculations, use `self.log(..., batch_size=batch_size)`.\n",
      "/rds/general/user/cb1319/home/anaconda3/envs/Geom3D/lib/python3.11/site-packages/lightning/pytorch/utilities/data.py:77: Trying to infer the `batch_size` from an ambiguous collection. The batch size we found is 7809. To avoid any miscalculations, use `self.log(..., batch_size=batch_size)`.\n",
      "/rds/general/user/cb1319/home/anaconda3/envs/Geom3D/lib/python3.11/site-packages/lightning/pytorch/utilities/data.py:77: Trying to infer the `batch_size` from an ambiguous collection. The batch size we found is 7858. To avoid any miscalculations, use `self.log(..., batch_size=batch_size)`.\n",
      "/rds/general/user/cb1319/home/anaconda3/envs/Geom3D/lib/python3.11/site-packages/lightning/pytorch/utilities/data.py:77: Trying to infer the `batch_size` from an ambiguous collection. The batch size we found is 7859. To avoid any miscalculations, use `self.log(..., batch_size=batch_size)`.\n",
      "/rds/general/user/cb1319/home/anaconda3/envs/Geom3D/lib/python3.11/site-packages/lightning/pytorch/utilities/data.py:77: Trying to infer the `batch_size` from an ambiguous collection. The batch size we found is 7798. To avoid any miscalculations, use `self.log(..., batch_size=batch_size)`.\n",
      "/rds/general/user/cb1319/home/anaconda3/envs/Geom3D/lib/python3.11/site-packages/lightning/pytorch/utilities/data.py:77: Trying to infer the `batch_size` from an ambiguous collection. The batch size we found is 7904. To avoid any miscalculations, use `self.log(..., batch_size=batch_size)`.\n",
      "/rds/general/user/cb1319/home/anaconda3/envs/Geom3D/lib/python3.11/site-packages/lightning/pytorch/utilities/data.py:77: Trying to infer the `batch_size` from an ambiguous collection. The batch size we found is 8018. To avoid any miscalculations, use `self.log(..., batch_size=batch_size)`.\n",
      "/rds/general/user/cb1319/home/anaconda3/envs/Geom3D/lib/python3.11/site-packages/lightning/pytorch/utilities/data.py:77: Trying to infer the `batch_size` from an ambiguous collection. The batch size we found is 7618. To avoid any miscalculations, use `self.log(..., batch_size=batch_size)`.\n",
      "/rds/general/user/cb1319/home/anaconda3/envs/Geom3D/lib/python3.11/site-packages/lightning/pytorch/utilities/data.py:77: Trying to infer the `batch_size` from an ambiguous collection. The batch size we found is 7675. To avoid any miscalculations, use `self.log(..., batch_size=batch_size)`.\n",
      "/rds/general/user/cb1319/home/anaconda3/envs/Geom3D/lib/python3.11/site-packages/lightning/pytorch/utilities/data.py:77: Trying to infer the `batch_size` from an ambiguous collection. The batch size we found is 8222. To avoid any miscalculations, use `self.log(..., batch_size=batch_size)`.\n",
      "/rds/general/user/cb1319/home/anaconda3/envs/Geom3D/lib/python3.11/site-packages/lightning/pytorch/utilities/data.py:77: Trying to infer the `batch_size` from an ambiguous collection. The batch size we found is 8006. To avoid any miscalculations, use `self.log(..., batch_size=batch_size)`.\n",
      "/rds/general/user/cb1319/home/anaconda3/envs/Geom3D/lib/python3.11/site-packages/lightning/pytorch/utilities/data.py:77: Trying to infer the `batch_size` from an ambiguous collection. The batch size we found is 7902. To avoid any miscalculations, use `self.log(..., batch_size=batch_size)`.\n",
      "/rds/general/user/cb1319/home/anaconda3/envs/Geom3D/lib/python3.11/site-packages/lightning/pytorch/utilities/data.py:77: Trying to infer the `batch_size` from an ambiguous collection. The batch size we found is 7719. To avoid any miscalculations, use `self.log(..., batch_size=batch_size)`.\n",
      "/rds/general/user/cb1319/home/anaconda3/envs/Geom3D/lib/python3.11/site-packages/lightning/pytorch/utilities/data.py:77: Trying to infer the `batch_size` from an ambiguous collection. The batch size we found is 8001. To avoid any miscalculations, use `self.log(..., batch_size=batch_size)`.\n",
      "/rds/general/user/cb1319/home/anaconda3/envs/Geom3D/lib/python3.11/site-packages/lightning/pytorch/utilities/data.py:77: Trying to infer the `batch_size` from an ambiguous collection. The batch size we found is 7807. To avoid any miscalculations, use `self.log(..., batch_size=batch_size)`.\n",
      "/rds/general/user/cb1319/home/anaconda3/envs/Geom3D/lib/python3.11/site-packages/lightning/pytorch/utilities/data.py:77: Trying to infer the `batch_size` from an ambiguous collection. The batch size we found is 7437. To avoid any miscalculations, use `self.log(..., batch_size=batch_size)`.\n",
      "/rds/general/user/cb1319/home/anaconda3/envs/Geom3D/lib/python3.11/site-packages/lightning/pytorch/utilities/data.py:77: Trying to infer the `batch_size` from an ambiguous collection. The batch size we found is 7714. To avoid any miscalculations, use `self.log(..., batch_size=batch_size)`.\n",
      "/rds/general/user/cb1319/home/anaconda3/envs/Geom3D/lib/python3.11/site-packages/lightning/pytorch/utilities/data.py:77: Trying to infer the `batch_size` from an ambiguous collection. The batch size we found is 7787. To avoid any miscalculations, use `self.log(..., batch_size=batch_size)`.\n",
      "/rds/general/user/cb1319/home/anaconda3/envs/Geom3D/lib/python3.11/site-packages/lightning/pytorch/utilities/data.py:77: Trying to infer the `batch_size` from an ambiguous collection. The batch size we found is 7730. To avoid any miscalculations, use `self.log(..., batch_size=batch_size)`.\n",
      "/rds/general/user/cb1319/home/anaconda3/envs/Geom3D/lib/python3.11/site-packages/lightning/pytorch/utilities/data.py:77: Trying to infer the `batch_size` from an ambiguous collection. The batch size we found is 7905. To avoid any miscalculations, use `self.log(..., batch_size=batch_size)`.\n",
      "/rds/general/user/cb1319/home/anaconda3/envs/Geom3D/lib/python3.11/site-packages/lightning/pytorch/utilities/data.py:77: Trying to infer the `batch_size` from an ambiguous collection. The batch size we found is 7979. To avoid any miscalculations, use `self.log(..., batch_size=batch_size)`.\n",
      "/rds/general/user/cb1319/home/anaconda3/envs/Geom3D/lib/python3.11/site-packages/lightning/pytorch/utilities/data.py:77: Trying to infer the `batch_size` from an ambiguous collection. The batch size we found is 7836. To avoid any miscalculations, use `self.log(..., batch_size=batch_size)`.\n",
      "/rds/general/user/cb1319/home/anaconda3/envs/Geom3D/lib/python3.11/site-packages/lightning/pytorch/utilities/data.py:77: Trying to infer the `batch_size` from an ambiguous collection. The batch size we found is 8073. To avoid any miscalculations, use `self.log(..., batch_size=batch_size)`.\n",
      "/rds/general/user/cb1319/home/anaconda3/envs/Geom3D/lib/python3.11/site-packages/lightning/pytorch/utilities/data.py:77: Trying to infer the `batch_size` from an ambiguous collection. The batch size we found is 7884. To avoid any miscalculations, use `self.log(..., batch_size=batch_size)`.\n",
      "/rds/general/user/cb1319/home/anaconda3/envs/Geom3D/lib/python3.11/site-packages/lightning/pytorch/utilities/data.py:77: Trying to infer the `batch_size` from an ambiguous collection. The batch size we found is 7855. To avoid any miscalculations, use `self.log(..., batch_size=batch_size)`.\n",
      "/rds/general/user/cb1319/home/anaconda3/envs/Geom3D/lib/python3.11/site-packages/lightning/pytorch/utilities/data.py:77: Trying to infer the `batch_size` from an ambiguous collection. The batch size we found is 7476. To avoid any miscalculations, use `self.log(..., batch_size=batch_size)`.\n",
      "/rds/general/user/cb1319/home/anaconda3/envs/Geom3D/lib/python3.11/site-packages/lightning/pytorch/utilities/data.py:77: Trying to infer the `batch_size` from an ambiguous collection. The batch size we found is 7857. To avoid any miscalculations, use `self.log(..., batch_size=batch_size)`.\n",
      "/rds/general/user/cb1319/home/anaconda3/envs/Geom3D/lib/python3.11/site-packages/lightning/pytorch/utilities/data.py:77: Trying to infer the `batch_size` from an ambiguous collection. The batch size we found is 7504. To avoid any miscalculations, use `self.log(..., batch_size=batch_size)`.\n",
      "/rds/general/user/cb1319/home/anaconda3/envs/Geom3D/lib/python3.11/site-packages/lightning/pytorch/utilities/data.py:77: Trying to infer the `batch_size` from an ambiguous collection. The batch size we found is 7988. To avoid any miscalculations, use `self.log(..., batch_size=batch_size)`.\n",
      "/rds/general/user/cb1319/home/anaconda3/envs/Geom3D/lib/python3.11/site-packages/lightning/pytorch/utilities/data.py:77: Trying to infer the `batch_size` from an ambiguous collection. The batch size we found is 8212. To avoid any miscalculations, use `self.log(..., batch_size=batch_size)`.\n",
      "/rds/general/user/cb1319/home/anaconda3/envs/Geom3D/lib/python3.11/site-packages/lightning/pytorch/utilities/data.py:77: Trying to infer the `batch_size` from an ambiguous collection. The batch size we found is 7793. To avoid any miscalculations, use `self.log(..., batch_size=batch_size)`.\n",
      "/rds/general/user/cb1319/home/anaconda3/envs/Geom3D/lib/python3.11/site-packages/lightning/pytorch/utilities/data.py:77: Trying to infer the `batch_size` from an ambiguous collection. The batch size we found is 7900. To avoid any miscalculations, use `self.log(..., batch_size=batch_size)`.\n",
      "/rds/general/user/cb1319/home/anaconda3/envs/Geom3D/lib/python3.11/site-packages/lightning/pytorch/utilities/data.py:77: Trying to infer the `batch_size` from an ambiguous collection. The batch size we found is 7802. To avoid any miscalculations, use `self.log(..., batch_size=batch_size)`.\n",
      "/rds/general/user/cb1319/home/anaconda3/envs/Geom3D/lib/python3.11/site-packages/lightning/pytorch/utilities/data.py:77: Trying to infer the `batch_size` from an ambiguous collection. The batch size we found is 7523. To avoid any miscalculations, use `self.log(..., batch_size=batch_size)`.\n",
      "/rds/general/user/cb1319/home/anaconda3/envs/Geom3D/lib/python3.11/site-packages/lightning/pytorch/utilities/data.py:77: Trying to infer the `batch_size` from an ambiguous collection. The batch size we found is 7507. To avoid any miscalculations, use `self.log(..., batch_size=batch_size)`.\n",
      "/rds/general/user/cb1319/home/anaconda3/envs/Geom3D/lib/python3.11/site-packages/lightning/pytorch/utilities/data.py:77: Trying to infer the `batch_size` from an ambiguous collection. The batch size we found is 8273. To avoid any miscalculations, use `self.log(..., batch_size=batch_size)`.\n",
      "/rds/general/user/cb1319/home/anaconda3/envs/Geom3D/lib/python3.11/site-packages/lightning/pytorch/utilities/data.py:77: Trying to infer the `batch_size` from an ambiguous collection. The batch size we found is 7936. To avoid any miscalculations, use `self.log(..., batch_size=batch_size)`.\n",
      "/rds/general/user/cb1319/home/anaconda3/envs/Geom3D/lib/python3.11/site-packages/lightning/pytorch/utilities/data.py:77: Trying to infer the `batch_size` from an ambiguous collection. The batch size we found is 7743. To avoid any miscalculations, use `self.log(..., batch_size=batch_size)`.\n",
      "/rds/general/user/cb1319/home/anaconda3/envs/Geom3D/lib/python3.11/site-packages/lightning/pytorch/utilities/data.py:77: Trying to infer the `batch_size` from an ambiguous collection. The batch size we found is 7751. To avoid any miscalculations, use `self.log(..., batch_size=batch_size)`.\n",
      "/rds/general/user/cb1319/home/anaconda3/envs/Geom3D/lib/python3.11/site-packages/lightning/pytorch/utilities/data.py:77: Trying to infer the `batch_size` from an ambiguous collection. The batch size we found is 7722. To avoid any miscalculations, use `self.log(..., batch_size=batch_size)`.\n",
      "/rds/general/user/cb1319/home/anaconda3/envs/Geom3D/lib/python3.11/site-packages/lightning/pytorch/utilities/data.py:77: Trying to infer the `batch_size` from an ambiguous collection. The batch size we found is 8049. To avoid any miscalculations, use `self.log(..., batch_size=batch_size)`.\n",
      "/rds/general/user/cb1319/home/anaconda3/envs/Geom3D/lib/python3.11/site-packages/lightning/pytorch/utilities/data.py:77: Trying to infer the `batch_size` from an ambiguous collection. The batch size we found is 7607. To avoid any miscalculations, use `self.log(..., batch_size=batch_size)`.\n"
     ]
    },
    {
     "data": {
      "application/vnd.jupyter.widget-view+json": {
       "model_id": "6eb336d9e0a943ccbc2332ee00277bd9",
       "version_major": 2,
       "version_minor": 0
      },
      "text/plain": [
       "Validation: |          | 0/? [00:00<?, ?it/s]"
      ]
     },
     "metadata": {},
     "output_type": "display_data"
    },
    {
     "name": "stderr",
     "output_type": "stream",
     "text": [
      "/rds/general/user/cb1319/home/anaconda3/envs/Geom3D/lib/python3.11/site-packages/lightning/pytorch/utilities/data.py:77: Trying to infer the `batch_size` from an ambiguous collection. The batch size we found is 7710. To avoid any miscalculations, use `self.log(..., batch_size=batch_size)`.\n",
      "/rds/general/user/cb1319/home/anaconda3/envs/Geom3D/lib/python3.11/site-packages/lightning/pytorch/utilities/data.py:77: Trying to infer the `batch_size` from an ambiguous collection. The batch size we found is 7670. To avoid any miscalculations, use `self.log(..., batch_size=batch_size)`.\n",
      "/rds/general/user/cb1319/home/anaconda3/envs/Geom3D/lib/python3.11/site-packages/lightning/pytorch/utilities/data.py:77: Trying to infer the `batch_size` from an ambiguous collection. The batch size we found is 8154. To avoid any miscalculations, use `self.log(..., batch_size=batch_size)`.\n",
      "/rds/general/user/cb1319/home/anaconda3/envs/Geom3D/lib/python3.11/site-packages/lightning/pytorch/utilities/data.py:77: Trying to infer the `batch_size` from an ambiguous collection. The batch size we found is 8011. To avoid any miscalculations, use `self.log(..., batch_size=batch_size)`.\n",
      "/rds/general/user/cb1319/home/anaconda3/envs/Geom3D/lib/python3.11/site-packages/lightning/pytorch/utilities/data.py:77: Trying to infer the `batch_size` from an ambiguous collection. The batch size we found is 7847. To avoid any miscalculations, use `self.log(..., batch_size=batch_size)`.\n",
      "/rds/general/user/cb1319/home/anaconda3/envs/Geom3D/lib/python3.11/site-packages/lightning/pytorch/utilities/data.py:77: Trying to infer the `batch_size` from an ambiguous collection. The batch size we found is 8271. To avoid any miscalculations, use `self.log(..., batch_size=batch_size)`.\n",
      "/rds/general/user/cb1319/home/anaconda3/envs/Geom3D/lib/python3.11/site-packages/lightning/pytorch/utilities/data.py:77: Trying to infer the `batch_size` from an ambiguous collection. The batch size we found is 7752. To avoid any miscalculations, use `self.log(..., batch_size=batch_size)`.\n",
      "/rds/general/user/cb1319/home/anaconda3/envs/Geom3D/lib/python3.11/site-packages/lightning/pytorch/utilities/data.py:77: Trying to infer the `batch_size` from an ambiguous collection. The batch size we found is 7631. To avoid any miscalculations, use `self.log(..., batch_size=batch_size)`.\n",
      "/rds/general/user/cb1319/home/anaconda3/envs/Geom3D/lib/python3.11/site-packages/lightning/pytorch/utilities/data.py:77: Trying to infer the `batch_size` from an ambiguous collection. The batch size we found is 7946. To avoid any miscalculations, use `self.log(..., batch_size=batch_size)`.\n",
      "/rds/general/user/cb1319/home/anaconda3/envs/Geom3D/lib/python3.11/site-packages/lightning/pytorch/utilities/data.py:77: Trying to infer the `batch_size` from an ambiguous collection. The batch size we found is 8035. To avoid any miscalculations, use `self.log(..., batch_size=batch_size)`.\n",
      "/rds/general/user/cb1319/home/anaconda3/envs/Geom3D/lib/python3.11/site-packages/lightning/pytorch/utilities/data.py:77: Trying to infer the `batch_size` from an ambiguous collection. The batch size we found is 7896. To avoid any miscalculations, use `self.log(..., batch_size=batch_size)`.\n",
      "/rds/general/user/cb1319/home/anaconda3/envs/Geom3D/lib/python3.11/site-packages/lightning/pytorch/utilities/data.py:77: Trying to infer the `batch_size` from an ambiguous collection. The batch size we found is 7721. To avoid any miscalculations, use `self.log(..., batch_size=batch_size)`.\n",
      "/rds/general/user/cb1319/home/anaconda3/envs/Geom3D/lib/python3.11/site-packages/lightning/pytorch/utilities/data.py:77: Trying to infer the `batch_size` from an ambiguous collection. The batch size we found is 7454. To avoid any miscalculations, use `self.log(..., batch_size=batch_size)`.\n",
      "/rds/general/user/cb1319/home/anaconda3/envs/Geom3D/lib/python3.11/site-packages/lightning/pytorch/utilities/data.py:77: Trying to infer the `batch_size` from an ambiguous collection. The batch size we found is 7749. To avoid any miscalculations, use `self.log(..., batch_size=batch_size)`.\n",
      "/rds/general/user/cb1319/home/anaconda3/envs/Geom3D/lib/python3.11/site-packages/lightning/pytorch/utilities/data.py:77: Trying to infer the `batch_size` from an ambiguous collection. The batch size we found is 7661. To avoid any miscalculations, use `self.log(..., batch_size=batch_size)`.\n",
      "/rds/general/user/cb1319/home/anaconda3/envs/Geom3D/lib/python3.11/site-packages/lightning/pytorch/utilities/data.py:77: Trying to infer the `batch_size` from an ambiguous collection. The batch size we found is 7659. To avoid any miscalculations, use `self.log(..., batch_size=batch_size)`.\n",
      "/rds/general/user/cb1319/home/anaconda3/envs/Geom3D/lib/python3.11/site-packages/lightning/pytorch/utilities/data.py:77: Trying to infer the `batch_size` from an ambiguous collection. The batch size we found is 7712. To avoid any miscalculations, use `self.log(..., batch_size=batch_size)`.\n",
      "/rds/general/user/cb1319/home/anaconda3/envs/Geom3D/lib/python3.11/site-packages/lightning/pytorch/utilities/data.py:77: Trying to infer the `batch_size` from an ambiguous collection. The batch size we found is 7765. To avoid any miscalculations, use `self.log(..., batch_size=batch_size)`.\n",
      "/rds/general/user/cb1319/home/anaconda3/envs/Geom3D/lib/python3.11/site-packages/lightning/pytorch/utilities/data.py:77: Trying to infer the `batch_size` from an ambiguous collection. The batch size we found is 7554. To avoid any miscalculations, use `self.log(..., batch_size=batch_size)`.\n",
      "/rds/general/user/cb1319/home/anaconda3/envs/Geom3D/lib/python3.11/site-packages/lightning/pytorch/utilities/data.py:77: Trying to infer the `batch_size` from an ambiguous collection. The batch size we found is 7611. To avoid any miscalculations, use `self.log(..., batch_size=batch_size)`.\n",
      "/rds/general/user/cb1319/home/anaconda3/envs/Geom3D/lib/python3.11/site-packages/lightning/pytorch/utilities/data.py:77: Trying to infer the `batch_size` from an ambiguous collection. The batch size we found is 8150. To avoid any miscalculations, use `self.log(..., batch_size=batch_size)`.\n",
      "/rds/general/user/cb1319/home/anaconda3/envs/Geom3D/lib/python3.11/site-packages/lightning/pytorch/utilities/data.py:77: Trying to infer the `batch_size` from an ambiguous collection. The batch size we found is 7562. To avoid any miscalculations, use `self.log(..., batch_size=batch_size)`.\n",
      "/rds/general/user/cb1319/home/anaconda3/envs/Geom3D/lib/python3.11/site-packages/lightning/pytorch/utilities/data.py:77: Trying to infer the `batch_size` from an ambiguous collection. The batch size we found is 7953. To avoid any miscalculations, use `self.log(..., batch_size=batch_size)`.\n",
      "/rds/general/user/cb1319/home/anaconda3/envs/Geom3D/lib/python3.11/site-packages/lightning/pytorch/utilities/data.py:77: Trying to infer the `batch_size` from an ambiguous collection. The batch size we found is 7276. To avoid any miscalculations, use `self.log(..., batch_size=batch_size)`.\n",
      "/rds/general/user/cb1319/home/anaconda3/envs/Geom3D/lib/python3.11/site-packages/lightning/pytorch/utilities/data.py:77: Trying to infer the `batch_size` from an ambiguous collection. The batch size we found is 7950. To avoid any miscalculations, use `self.log(..., batch_size=batch_size)`.\n",
      "/rds/general/user/cb1319/home/anaconda3/envs/Geom3D/lib/python3.11/site-packages/lightning/pytorch/utilities/data.py:77: Trying to infer the `batch_size` from an ambiguous collection. The batch size we found is 7803. To avoid any miscalculations, use `self.log(..., batch_size=batch_size)`.\n",
      "/rds/general/user/cb1319/home/anaconda3/envs/Geom3D/lib/python3.11/site-packages/lightning/pytorch/utilities/data.py:77: Trying to infer the `batch_size` from an ambiguous collection. The batch size we found is 7995. To avoid any miscalculations, use `self.log(..., batch_size=batch_size)`.\n",
      "/rds/general/user/cb1319/home/anaconda3/envs/Geom3D/lib/python3.11/site-packages/lightning/pytorch/utilities/data.py:77: Trying to infer the `batch_size` from an ambiguous collection. The batch size we found is 7423. To avoid any miscalculations, use `self.log(..., batch_size=batch_size)`.\n",
      "/rds/general/user/cb1319/home/anaconda3/envs/Geom3D/lib/python3.11/site-packages/lightning/pytorch/utilities/data.py:77: Trying to infer the `batch_size` from an ambiguous collection. The batch size we found is 7449. To avoid any miscalculations, use `self.log(..., batch_size=batch_size)`.\n",
      "/rds/general/user/cb1319/home/anaconda3/envs/Geom3D/lib/python3.11/site-packages/lightning/pytorch/utilities/data.py:77: Trying to infer the `batch_size` from an ambiguous collection. The batch size we found is 7824. To avoid any miscalculations, use `self.log(..., batch_size=batch_size)`.\n",
      "/rds/general/user/cb1319/home/anaconda3/envs/Geom3D/lib/python3.11/site-packages/lightning/pytorch/utilities/data.py:77: Trying to infer the `batch_size` from an ambiguous collection. The batch size we found is 7799. To avoid any miscalculations, use `self.log(..., batch_size=batch_size)`.\n",
      "/rds/general/user/cb1319/home/anaconda3/envs/Geom3D/lib/python3.11/site-packages/lightning/pytorch/utilities/data.py:77: Trying to infer the `batch_size` from an ambiguous collection. The batch size we found is 7872. To avoid any miscalculations, use `self.log(..., batch_size=batch_size)`.\n",
      "/rds/general/user/cb1319/home/anaconda3/envs/Geom3D/lib/python3.11/site-packages/lightning/pytorch/utilities/data.py:77: Trying to infer the `batch_size` from an ambiguous collection. The batch size we found is 8229. To avoid any miscalculations, use `self.log(..., batch_size=batch_size)`.\n",
      "/rds/general/user/cb1319/home/anaconda3/envs/Geom3D/lib/python3.11/site-packages/lightning/pytorch/utilities/data.py:77: Trying to infer the `batch_size` from an ambiguous collection. The batch size we found is 7578. To avoid any miscalculations, use `self.log(..., batch_size=batch_size)`.\n",
      "/rds/general/user/cb1319/home/anaconda3/envs/Geom3D/lib/python3.11/site-packages/lightning/pytorch/utilities/data.py:77: Trying to infer the `batch_size` from an ambiguous collection. The batch size we found is 8032. To avoid any miscalculations, use `self.log(..., batch_size=batch_size)`.\n",
      "/rds/general/user/cb1319/home/anaconda3/envs/Geom3D/lib/python3.11/site-packages/lightning/pytorch/utilities/data.py:77: Trying to infer the `batch_size` from an ambiguous collection. The batch size we found is 7548. To avoid any miscalculations, use `self.log(..., batch_size=batch_size)`.\n",
      "/rds/general/user/cb1319/home/anaconda3/envs/Geom3D/lib/python3.11/site-packages/lightning/pytorch/utilities/data.py:77: Trying to infer the `batch_size` from an ambiguous collection. The batch size we found is 7350. To avoid any miscalculations, use `self.log(..., batch_size=batch_size)`.\n",
      "/rds/general/user/cb1319/home/anaconda3/envs/Geom3D/lib/python3.11/site-packages/lightning/pytorch/utilities/data.py:77: Trying to infer the `batch_size` from an ambiguous collection. The batch size we found is 8033. To avoid any miscalculations, use `self.log(..., batch_size=batch_size)`.\n",
      "/rds/general/user/cb1319/home/anaconda3/envs/Geom3D/lib/python3.11/site-packages/lightning/pytorch/utilities/data.py:77: Trying to infer the `batch_size` from an ambiguous collection. The batch size we found is 7676. To avoid any miscalculations, use `self.log(..., batch_size=batch_size)`.\n",
      "/rds/general/user/cb1319/home/anaconda3/envs/Geom3D/lib/python3.11/site-packages/lightning/pytorch/utilities/data.py:77: Trying to infer the `batch_size` from an ambiguous collection. The batch size we found is 7588. To avoid any miscalculations, use `self.log(..., batch_size=batch_size)`.\n",
      "/rds/general/user/cb1319/home/anaconda3/envs/Geom3D/lib/python3.11/site-packages/lightning/pytorch/utilities/data.py:77: Trying to infer the `batch_size` from an ambiguous collection. The batch size we found is 7888. To avoid any miscalculations, use `self.log(..., batch_size=batch_size)`.\n",
      "/rds/general/user/cb1319/home/anaconda3/envs/Geom3D/lib/python3.11/site-packages/lightning/pytorch/utilities/data.py:77: Trying to infer the `batch_size` from an ambiguous collection. The batch size we found is 8131. To avoid any miscalculations, use `self.log(..., batch_size=batch_size)`.\n",
      "/rds/general/user/cb1319/home/anaconda3/envs/Geom3D/lib/python3.11/site-packages/lightning/pytorch/utilities/data.py:77: Trying to infer the `batch_size` from an ambiguous collection. The batch size we found is 7848. To avoid any miscalculations, use `self.log(..., batch_size=batch_size)`.\n",
      "/rds/general/user/cb1319/home/anaconda3/envs/Geom3D/lib/python3.11/site-packages/lightning/pytorch/utilities/data.py:77: Trying to infer the `batch_size` from an ambiguous collection. The batch size we found is 7717. To avoid any miscalculations, use `self.log(..., batch_size=batch_size)`.\n",
      "/rds/general/user/cb1319/home/anaconda3/envs/Geom3D/lib/python3.11/site-packages/lightning/pytorch/utilities/data.py:77: Trying to infer the `batch_size` from an ambiguous collection. The batch size we found is 7846. To avoid any miscalculations, use `self.log(..., batch_size=batch_size)`.\n",
      "/rds/general/user/cb1319/home/anaconda3/envs/Geom3D/lib/python3.11/site-packages/lightning/pytorch/utilities/data.py:77: Trying to infer the `batch_size` from an ambiguous collection. The batch size we found is 8022. To avoid any miscalculations, use `self.log(..., batch_size=batch_size)`.\n",
      "/rds/general/user/cb1319/home/anaconda3/envs/Geom3D/lib/python3.11/site-packages/lightning/pytorch/utilities/data.py:77: Trying to infer the `batch_size` from an ambiguous collection. The batch size we found is 7644. To avoid any miscalculations, use `self.log(..., batch_size=batch_size)`.\n",
      "/rds/general/user/cb1319/home/anaconda3/envs/Geom3D/lib/python3.11/site-packages/lightning/pytorch/utilities/data.py:77: Trying to infer the `batch_size` from an ambiguous collection. The batch size we found is 7971. To avoid any miscalculations, use `self.log(..., batch_size=batch_size)`.\n",
      "/rds/general/user/cb1319/home/anaconda3/envs/Geom3D/lib/python3.11/site-packages/lightning/pytorch/utilities/data.py:77: Trying to infer the `batch_size` from an ambiguous collection. The batch size we found is 7379. To avoid any miscalculations, use `self.log(..., batch_size=batch_size)`.\n",
      "/rds/general/user/cb1319/home/anaconda3/envs/Geom3D/lib/python3.11/site-packages/lightning/pytorch/utilities/data.py:77: Trying to infer the `batch_size` from an ambiguous collection. The batch size we found is 8015. To avoid any miscalculations, use `self.log(..., batch_size=batch_size)`.\n",
      "/rds/general/user/cb1319/home/anaconda3/envs/Geom3D/lib/python3.11/site-packages/lightning/pytorch/utilities/data.py:77: Trying to infer the `batch_size` from an ambiguous collection. The batch size we found is 8077. To avoid any miscalculations, use `self.log(..., batch_size=batch_size)`.\n",
      "/rds/general/user/cb1319/home/anaconda3/envs/Geom3D/lib/python3.11/site-packages/lightning/pytorch/utilities/data.py:77: Trying to infer the `batch_size` from an ambiguous collection. The batch size we found is 8133. To avoid any miscalculations, use `self.log(..., batch_size=batch_size)`.\n",
      "/rds/general/user/cb1319/home/anaconda3/envs/Geom3D/lib/python3.11/site-packages/lightning/pytorch/utilities/data.py:77: Trying to infer the `batch_size` from an ambiguous collection. The batch size we found is 7992. To avoid any miscalculations, use `self.log(..., batch_size=batch_size)`.\n",
      "/rds/general/user/cb1319/home/anaconda3/envs/Geom3D/lib/python3.11/site-packages/lightning/pytorch/utilities/data.py:77: Trying to infer the `batch_size` from an ambiguous collection. The batch size we found is 7393. To avoid any miscalculations, use `self.log(..., batch_size=batch_size)`.\n",
      "/rds/general/user/cb1319/home/anaconda3/envs/Geom3D/lib/python3.11/site-packages/lightning/pytorch/utilities/data.py:77: Trying to infer the `batch_size` from an ambiguous collection. The batch size we found is 7805. To avoid any miscalculations, use `self.log(..., batch_size=batch_size)`.\n",
      "/rds/general/user/cb1319/home/anaconda3/envs/Geom3D/lib/python3.11/site-packages/lightning/pytorch/utilities/data.py:77: Trying to infer the `batch_size` from an ambiguous collection. The batch size we found is 7697. To avoid any miscalculations, use `self.log(..., batch_size=batch_size)`.\n",
      "/rds/general/user/cb1319/home/anaconda3/envs/Geom3D/lib/python3.11/site-packages/lightning/pytorch/utilities/data.py:77: Trying to infer the `batch_size` from an ambiguous collection. The batch size we found is 7840. To avoid any miscalculations, use `self.log(..., batch_size=batch_size)`.\n",
      "/rds/general/user/cb1319/home/anaconda3/envs/Geom3D/lib/python3.11/site-packages/lightning/pytorch/utilities/data.py:77: Trying to infer the `batch_size` from an ambiguous collection. The batch size we found is 7558. To avoid any miscalculations, use `self.log(..., batch_size=batch_size)`.\n",
      "/rds/general/user/cb1319/home/anaconda3/envs/Geom3D/lib/python3.11/site-packages/lightning/pytorch/utilities/data.py:77: Trying to infer the `batch_size` from an ambiguous collection. The batch size we found is 7615. To avoid any miscalculations, use `self.log(..., batch_size=batch_size)`.\n",
      "/rds/general/user/cb1319/home/anaconda3/envs/Geom3D/lib/python3.11/site-packages/lightning/pytorch/utilities/data.py:77: Trying to infer the `batch_size` from an ambiguous collection. The batch size we found is 8248. To avoid any miscalculations, use `self.log(..., batch_size=batch_size)`.\n",
      "/rds/general/user/cb1319/home/anaconda3/envs/Geom3D/lib/python3.11/site-packages/lightning/pytorch/utilities/data.py:77: Trying to infer the `batch_size` from an ambiguous collection. The batch size we found is 7648. To avoid any miscalculations, use `self.log(..., batch_size=batch_size)`.\n",
      "/rds/general/user/cb1319/home/anaconda3/envs/Geom3D/lib/python3.11/site-packages/lightning/pytorch/utilities/data.py:77: Trying to infer the `batch_size` from an ambiguous collection. The batch size we found is 7830. To avoid any miscalculations, use `self.log(..., batch_size=batch_size)`.\n",
      "/rds/general/user/cb1319/home/anaconda3/envs/Geom3D/lib/python3.11/site-packages/lightning/pytorch/utilities/data.py:77: Trying to infer the `batch_size` from an ambiguous collection. The batch size we found is 7853. To avoid any miscalculations, use `self.log(..., batch_size=batch_size)`.\n",
      "/rds/general/user/cb1319/home/anaconda3/envs/Geom3D/lib/python3.11/site-packages/lightning/pytorch/utilities/data.py:77: Trying to infer the `batch_size` from an ambiguous collection. The batch size we found is 7827. To avoid any miscalculations, use `self.log(..., batch_size=batch_size)`.\n",
      "/rds/general/user/cb1319/home/anaconda3/envs/Geom3D/lib/python3.11/site-packages/lightning/pytorch/utilities/data.py:77: Trying to infer the `batch_size` from an ambiguous collection. The batch size we found is 7682. To avoid any miscalculations, use `self.log(..., batch_size=batch_size)`.\n",
      "/rds/general/user/cb1319/home/anaconda3/envs/Geom3D/lib/python3.11/site-packages/lightning/pytorch/utilities/data.py:77: Trying to infer the `batch_size` from an ambiguous collection. The batch size we found is 8170. To avoid any miscalculations, use `self.log(..., batch_size=batch_size)`.\n",
      "/rds/general/user/cb1319/home/anaconda3/envs/Geom3D/lib/python3.11/site-packages/lightning/pytorch/utilities/data.py:77: Trying to infer the `batch_size` from an ambiguous collection. The batch size we found is 7894. To avoid any miscalculations, use `self.log(..., batch_size=batch_size)`.\n",
      "/rds/general/user/cb1319/home/anaconda3/envs/Geom3D/lib/python3.11/site-packages/lightning/pytorch/utilities/data.py:77: Trying to infer the `batch_size` from an ambiguous collection. The batch size we found is 7627. To avoid any miscalculations, use `self.log(..., batch_size=batch_size)`.\n",
      "/rds/general/user/cb1319/home/anaconda3/envs/Geom3D/lib/python3.11/site-packages/lightning/pytorch/utilities/data.py:77: Trying to infer the `batch_size` from an ambiguous collection. The batch size we found is 7917. To avoid any miscalculations, use `self.log(..., batch_size=batch_size)`.\n",
      "/rds/general/user/cb1319/home/anaconda3/envs/Geom3D/lib/python3.11/site-packages/lightning/pytorch/utilities/data.py:77: Trying to infer the `batch_size` from an ambiguous collection. The batch size we found is 8423. To avoid any miscalculations, use `self.log(..., batch_size=batch_size)`.\n",
      "/rds/general/user/cb1319/home/anaconda3/envs/Geom3D/lib/python3.11/site-packages/lightning/pytorch/utilities/data.py:77: Trying to infer the `batch_size` from an ambiguous collection. The batch size we found is 7754. To avoid any miscalculations, use `self.log(..., batch_size=batch_size)`.\n",
      "/rds/general/user/cb1319/home/anaconda3/envs/Geom3D/lib/python3.11/site-packages/lightning/pytorch/utilities/data.py:77: Trying to infer the `batch_size` from an ambiguous collection. The batch size we found is 7867. To avoid any miscalculations, use `self.log(..., batch_size=batch_size)`.\n"
     ]
    },
    {
     "data": {
      "application/vnd.jupyter.widget-view+json": {
       "model_id": "21461ade23e0494a8c59b26cd66a392a",
       "version_major": 2,
       "version_minor": 0
      },
      "text/plain": [
       "Validation: |          | 0/? [00:00<?, ?it/s]"
      ]
     },
     "metadata": {},
     "output_type": "display_data"
    },
    {
     "name": "stderr",
     "output_type": "stream",
     "text": [
      "/rds/general/user/cb1319/home/anaconda3/envs/Geom3D/lib/python3.11/site-packages/lightning/pytorch/utilities/data.py:77: Trying to infer the `batch_size` from an ambiguous collection. The batch size we found is 7910. To avoid any miscalculations, use `self.log(..., batch_size=batch_size)`.\n",
      "/rds/general/user/cb1319/home/anaconda3/envs/Geom3D/lib/python3.11/site-packages/lightning/pytorch/utilities/data.py:77: Trying to infer the `batch_size` from an ambiguous collection. The batch size we found is 7494. To avoid any miscalculations, use `self.log(..., batch_size=batch_size)`.\n",
      "/rds/general/user/cb1319/home/anaconda3/envs/Geom3D/lib/python3.11/site-packages/lightning/pytorch/utilities/data.py:77: Trying to infer the `batch_size` from an ambiguous collection. The batch size we found is 7464. To avoid any miscalculations, use `self.log(..., batch_size=batch_size)`.\n",
      "/rds/general/user/cb1319/home/anaconda3/envs/Geom3D/lib/python3.11/site-packages/lightning/pytorch/utilities/data.py:77: Trying to infer the `batch_size` from an ambiguous collection. The batch size we found is 7655. To avoid any miscalculations, use `self.log(..., batch_size=batch_size)`.\n",
      "/rds/general/user/cb1319/home/anaconda3/envs/Geom3D/lib/python3.11/site-packages/lightning/pytorch/utilities/data.py:77: Trying to infer the `batch_size` from an ambiguous collection. The batch size we found is 8108. To avoid any miscalculations, use `self.log(..., batch_size=batch_size)`.\n",
      "/rds/general/user/cb1319/home/anaconda3/envs/Geom3D/lib/python3.11/site-packages/lightning/pytorch/utilities/data.py:77: Trying to infer the `batch_size` from an ambiguous collection. The batch size we found is 7724. To avoid any miscalculations, use `self.log(..., batch_size=batch_size)`.\n",
      "/rds/general/user/cb1319/home/anaconda3/envs/Geom3D/lib/python3.11/site-packages/lightning/pytorch/utilities/data.py:77: Trying to infer the `batch_size` from an ambiguous collection. The batch size we found is 7544. To avoid any miscalculations, use `self.log(..., batch_size=batch_size)`.\n",
      "/rds/general/user/cb1319/home/anaconda3/envs/Geom3D/lib/python3.11/site-packages/lightning/pytorch/utilities/data.py:77: Trying to infer the `batch_size` from an ambiguous collection. The batch size we found is 7726. To avoid any miscalculations, use `self.log(..., batch_size=batch_size)`.\n",
      "/rds/general/user/cb1319/home/anaconda3/envs/Geom3D/lib/python3.11/site-packages/lightning/pytorch/utilities/data.py:77: Trying to infer the `batch_size` from an ambiguous collection. The batch size we found is 7964. To avoid any miscalculations, use `self.log(..., batch_size=batch_size)`.\n",
      "/rds/general/user/cb1319/home/anaconda3/envs/Geom3D/lib/python3.11/site-packages/lightning/pytorch/utilities/data.py:77: Trying to infer the `batch_size` from an ambiguous collection. The batch size we found is 8093. To avoid any miscalculations, use `self.log(..., batch_size=batch_size)`.\n",
      "/rds/general/user/cb1319/home/anaconda3/envs/Geom3D/lib/python3.11/site-packages/lightning/pytorch/utilities/data.py:77: Trying to infer the `batch_size` from an ambiguous collection. The batch size we found is 7941. To avoid any miscalculations, use `self.log(..., batch_size=batch_size)`.\n",
      "/rds/general/user/cb1319/home/anaconda3/envs/Geom3D/lib/python3.11/site-packages/lightning/pytorch/utilities/data.py:77: Trying to infer the `batch_size` from an ambiguous collection. The batch size we found is 7804. To avoid any miscalculations, use `self.log(..., batch_size=batch_size)`.\n",
      "/rds/general/user/cb1319/home/anaconda3/envs/Geom3D/lib/python3.11/site-packages/lightning/pytorch/utilities/data.py:77: Trying to infer the `batch_size` from an ambiguous collection. The batch size we found is 7492. To avoid any miscalculations, use `self.log(..., batch_size=batch_size)`.\n",
      "/rds/general/user/cb1319/home/anaconda3/envs/Geom3D/lib/python3.11/site-packages/lightning/pytorch/utilities/data.py:77: Trying to infer the `batch_size` from an ambiguous collection. The batch size we found is 7517. To avoid any miscalculations, use `self.log(..., batch_size=batch_size)`.\n",
      "/rds/general/user/cb1319/home/anaconda3/envs/Geom3D/lib/python3.11/site-packages/lightning/pytorch/utilities/data.py:77: Trying to infer the `batch_size` from an ambiguous collection. The batch size we found is 7747. To avoid any miscalculations, use `self.log(..., batch_size=batch_size)`.\n",
      "/rds/general/user/cb1319/home/anaconda3/envs/Geom3D/lib/python3.11/site-packages/lightning/pytorch/utilities/data.py:77: Trying to infer the `batch_size` from an ambiguous collection. The batch size we found is 8091. To avoid any miscalculations, use `self.log(..., batch_size=batch_size)`.\n",
      "/rds/general/user/cb1319/home/anaconda3/envs/Geom3D/lib/python3.11/site-packages/lightning/pytorch/utilities/data.py:77: Trying to infer the `batch_size` from an ambiguous collection. The batch size we found is 8028. To avoid any miscalculations, use `self.log(..., batch_size=batch_size)`.\n",
      "/rds/general/user/cb1319/home/anaconda3/envs/Geom3D/lib/python3.11/site-packages/lightning/pytorch/utilities/data.py:77: Trying to infer the `batch_size` from an ambiguous collection. The batch size we found is 7955. To avoid any miscalculations, use `self.log(..., batch_size=batch_size)`.\n",
      "/rds/general/user/cb1319/home/anaconda3/envs/Geom3D/lib/python3.11/site-packages/lightning/pytorch/utilities/data.py:77: Trying to infer the `batch_size` from an ambiguous collection. The batch size we found is 7408. To avoid any miscalculations, use `self.log(..., batch_size=batch_size)`.\n",
      "/rds/general/user/cb1319/home/anaconda3/envs/Geom3D/lib/python3.11/site-packages/lightning/pytorch/utilities/data.py:77: Trying to infer the `batch_size` from an ambiguous collection. The batch size we found is 7684. To avoid any miscalculations, use `self.log(..., batch_size=batch_size)`.\n",
      "/rds/general/user/cb1319/home/anaconda3/envs/Geom3D/lib/python3.11/site-packages/lightning/pytorch/utilities/data.py:77: Trying to infer the `batch_size` from an ambiguous collection. The batch size we found is 7583. To avoid any miscalculations, use `self.log(..., batch_size=batch_size)`.\n",
      "/rds/general/user/cb1319/home/anaconda3/envs/Geom3D/lib/python3.11/site-packages/lightning/pytorch/utilities/data.py:77: Trying to infer the `batch_size` from an ambiguous collection. The batch size we found is 7641. To avoid any miscalculations, use `self.log(..., batch_size=batch_size)`.\n",
      "/rds/general/user/cb1319/home/anaconda3/envs/Geom3D/lib/python3.11/site-packages/lightning/pytorch/utilities/data.py:77: Trying to infer the `batch_size` from an ambiguous collection. The batch size we found is 7728. To avoid any miscalculations, use `self.log(..., batch_size=batch_size)`.\n",
      "/rds/general/user/cb1319/home/anaconda3/envs/Geom3D/lib/python3.11/site-packages/lightning/pytorch/utilities/data.py:77: Trying to infer the `batch_size` from an ambiguous collection. The batch size we found is 7570. To avoid any miscalculations, use `self.log(..., batch_size=batch_size)`.\n",
      "/rds/general/user/cb1319/home/anaconda3/envs/Geom3D/lib/python3.11/site-packages/lightning/pytorch/utilities/data.py:77: Trying to infer the `batch_size` from an ambiguous collection. The batch size we found is 7537. To avoid any miscalculations, use `self.log(..., batch_size=batch_size)`.\n",
      "/rds/general/user/cb1319/home/anaconda3/envs/Geom3D/lib/python3.11/site-packages/lightning/pytorch/utilities/data.py:77: Trying to infer the `batch_size` from an ambiguous collection. The batch size we found is 7893. To avoid any miscalculations, use `self.log(..., batch_size=batch_size)`.\n",
      "/rds/general/user/cb1319/home/anaconda3/envs/Geom3D/lib/python3.11/site-packages/lightning/pytorch/utilities/data.py:77: Trying to infer the `batch_size` from an ambiguous collection. The batch size we found is 8142. To avoid any miscalculations, use `self.log(..., batch_size=batch_size)`.\n",
      "/rds/general/user/cb1319/home/anaconda3/envs/Geom3D/lib/python3.11/site-packages/lightning/pytorch/utilities/data.py:77: Trying to infer the `batch_size` from an ambiguous collection. The batch size we found is 8101. To avoid any miscalculations, use `self.log(..., batch_size=batch_size)`.\n",
      "/rds/general/user/cb1319/home/anaconda3/envs/Geom3D/lib/python3.11/site-packages/lightning/pytorch/utilities/data.py:77: Trying to infer the `batch_size` from an ambiguous collection. The batch size we found is 7705. To avoid any miscalculations, use `self.log(..., batch_size=batch_size)`.\n",
      "/rds/general/user/cb1319/home/anaconda3/envs/Geom3D/lib/python3.11/site-packages/lightning/pytorch/utilities/data.py:77: Trying to infer the `batch_size` from an ambiguous collection. The batch size we found is 7828. To avoid any miscalculations, use `self.log(..., batch_size=batch_size)`.\n",
      "/rds/general/user/cb1319/home/anaconda3/envs/Geom3D/lib/python3.11/site-packages/lightning/pytorch/utilities/data.py:77: Trying to infer the `batch_size` from an ambiguous collection. The batch size we found is 8087. To avoid any miscalculations, use `self.log(..., batch_size=batch_size)`.\n",
      "/rds/general/user/cb1319/home/anaconda3/envs/Geom3D/lib/python3.11/site-packages/lightning/pytorch/utilities/data.py:77: Trying to infer the `batch_size` from an ambiguous collection. The batch size we found is 8031. To avoid any miscalculations, use `self.log(..., batch_size=batch_size)`.\n",
      "/rds/general/user/cb1319/home/anaconda3/envs/Geom3D/lib/python3.11/site-packages/lightning/pytorch/utilities/data.py:77: Trying to infer the `batch_size` from an ambiguous collection. The batch size we found is 7780. To avoid any miscalculations, use `self.log(..., batch_size=batch_size)`.\n",
      "/rds/general/user/cb1319/home/anaconda3/envs/Geom3D/lib/python3.11/site-packages/lightning/pytorch/utilities/data.py:77: Trying to infer the `batch_size` from an ambiguous collection. The batch size we found is 7885. To avoid any miscalculations, use `self.log(..., batch_size=batch_size)`.\n",
      "/rds/general/user/cb1319/home/anaconda3/envs/Geom3D/lib/python3.11/site-packages/lightning/pytorch/utilities/data.py:77: Trying to infer the `batch_size` from an ambiguous collection. The batch size we found is 7519. To avoid any miscalculations, use `self.log(..., batch_size=batch_size)`.\n",
      "/rds/general/user/cb1319/home/anaconda3/envs/Geom3D/lib/python3.11/site-packages/lightning/pytorch/utilities/data.py:77: Trying to infer the `batch_size` from an ambiguous collection. The batch size we found is 8029. To avoid any miscalculations, use `self.log(..., batch_size=batch_size)`.\n",
      "/rds/general/user/cb1319/home/anaconda3/envs/Geom3D/lib/python3.11/site-packages/lightning/pytorch/utilities/data.py:77: Trying to infer the `batch_size` from an ambiguous collection. The batch size we found is 7432. To avoid any miscalculations, use `self.log(..., batch_size=batch_size)`.\n",
      "/rds/general/user/cb1319/home/anaconda3/envs/Geom3D/lib/python3.11/site-packages/lightning/pytorch/utilities/data.py:77: Trying to infer the `batch_size` from an ambiguous collection. The batch size we found is 7863. To avoid any miscalculations, use `self.log(..., batch_size=batch_size)`.\n",
      "/rds/general/user/cb1319/home/anaconda3/envs/Geom3D/lib/python3.11/site-packages/lightning/pytorch/utilities/data.py:77: Trying to infer the `batch_size` from an ambiguous collection. The batch size we found is 7674. To avoid any miscalculations, use `self.log(..., batch_size=batch_size)`.\n",
      "/rds/general/user/cb1319/home/anaconda3/envs/Geom3D/lib/python3.11/site-packages/lightning/pytorch/utilities/data.py:77: Trying to infer the `batch_size` from an ambiguous collection. The batch size we found is 7784. To avoid any miscalculations, use `self.log(..., batch_size=batch_size)`.\n",
      "/rds/general/user/cb1319/home/anaconda3/envs/Geom3D/lib/python3.11/site-packages/lightning/pytorch/utilities/data.py:77: Trying to infer the `batch_size` from an ambiguous collection. The batch size we found is 7944. To avoid any miscalculations, use `self.log(..., batch_size=batch_size)`.\n",
      "/rds/general/user/cb1319/home/anaconda3/envs/Geom3D/lib/python3.11/site-packages/lightning/pytorch/utilities/data.py:77: Trying to infer the `batch_size` from an ambiguous collection. The batch size we found is 7761. To avoid any miscalculations, use `self.log(..., batch_size=batch_size)`.\n",
      "/rds/general/user/cb1319/home/anaconda3/envs/Geom3D/lib/python3.11/site-packages/lightning/pytorch/utilities/data.py:77: Trying to infer the `batch_size` from an ambiguous collection. The batch size we found is 7664. To avoid any miscalculations, use `self.log(..., batch_size=batch_size)`.\n",
      "/rds/general/user/cb1319/home/anaconda3/envs/Geom3D/lib/python3.11/site-packages/lightning/pytorch/utilities/data.py:77: Trying to infer the `batch_size` from an ambiguous collection. The batch size we found is 8176. To avoid any miscalculations, use `self.log(..., batch_size=batch_size)`.\n",
      "/rds/general/user/cb1319/home/anaconda3/envs/Geom3D/lib/python3.11/site-packages/lightning/pytorch/utilities/data.py:77: Trying to infer the `batch_size` from an ambiguous collection. The batch size we found is 7658. To avoid any miscalculations, use `self.log(..., batch_size=batch_size)`.\n",
      "/rds/general/user/cb1319/home/anaconda3/envs/Geom3D/lib/python3.11/site-packages/lightning/pytorch/utilities/data.py:77: Trying to infer the `batch_size` from an ambiguous collection. The batch size we found is 8247. To avoid any miscalculations, use `self.log(..., batch_size=batch_size)`.\n",
      "/rds/general/user/cb1319/home/anaconda3/envs/Geom3D/lib/python3.11/site-packages/lightning/pytorch/utilities/data.py:77: Trying to infer the `batch_size` from an ambiguous collection. The batch size we found is 7782. To avoid any miscalculations, use `self.log(..., batch_size=batch_size)`.\n",
      "/rds/general/user/cb1319/home/anaconda3/envs/Geom3D/lib/python3.11/site-packages/lightning/pytorch/utilities/data.py:77: Trying to infer the `batch_size` from an ambiguous collection. The batch size we found is 7898. To avoid any miscalculations, use `self.log(..., batch_size=batch_size)`.\n",
      "/rds/general/user/cb1319/home/anaconda3/envs/Geom3D/lib/python3.11/site-packages/lightning/pytorch/utilities/data.py:77: Trying to infer the `batch_size` from an ambiguous collection. The batch size we found is 8171. To avoid any miscalculations, use `self.log(..., batch_size=batch_size)`.\n",
      "/rds/general/user/cb1319/home/anaconda3/envs/Geom3D/lib/python3.11/site-packages/lightning/pytorch/utilities/data.py:77: Trying to infer the `batch_size` from an ambiguous collection. The batch size we found is 7731. To avoid any miscalculations, use `self.log(..., batch_size=batch_size)`.\n",
      "/rds/general/user/cb1319/home/anaconda3/envs/Geom3D/lib/python3.11/site-packages/lightning/pytorch/utilities/data.py:77: Trying to infer the `batch_size` from an ambiguous collection. The batch size we found is 8010. To avoid any miscalculations, use `self.log(..., batch_size=batch_size)`.\n",
      "/rds/general/user/cb1319/home/anaconda3/envs/Geom3D/lib/python3.11/site-packages/lightning/pytorch/utilities/data.py:77: Trying to infer the `batch_size` from an ambiguous collection. The batch size we found is 7984. To avoid any miscalculations, use `self.log(..., batch_size=batch_size)`.\n",
      "/rds/general/user/cb1319/home/anaconda3/envs/Geom3D/lib/python3.11/site-packages/lightning/pytorch/utilities/data.py:77: Trying to infer the `batch_size` from an ambiguous collection. The batch size we found is 8003. To avoid any miscalculations, use `self.log(..., batch_size=batch_size)`.\n",
      "/rds/general/user/cb1319/home/anaconda3/envs/Geom3D/lib/python3.11/site-packages/lightning/pytorch/utilities/data.py:77: Trying to infer the `batch_size` from an ambiguous collection. The batch size we found is 7416. To avoid any miscalculations, use `self.log(..., batch_size=batch_size)`.\n",
      "/rds/general/user/cb1319/home/anaconda3/envs/Geom3D/lib/python3.11/site-packages/lightning/pytorch/utilities/data.py:77: Trying to infer the `batch_size` from an ambiguous collection. The batch size we found is 7715. To avoid any miscalculations, use `self.log(..., batch_size=batch_size)`.\n",
      "/rds/general/user/cb1319/home/anaconda3/envs/Geom3D/lib/python3.11/site-packages/lightning/pytorch/utilities/data.py:77: Trying to infer the `batch_size` from an ambiguous collection. The batch size we found is 7969. To avoid any miscalculations, use `self.log(..., batch_size=batch_size)`.\n",
      "/rds/general/user/cb1319/home/anaconda3/envs/Geom3D/lib/python3.11/site-packages/lightning/pytorch/utilities/data.py:77: Trying to infer the `batch_size` from an ambiguous collection. The batch size we found is 7875. To avoid any miscalculations, use `self.log(..., batch_size=batch_size)`.\n",
      "/rds/general/user/cb1319/home/anaconda3/envs/Geom3D/lib/python3.11/site-packages/lightning/pytorch/utilities/data.py:77: Trying to infer the `batch_size` from an ambiguous collection. The batch size we found is 8042. To avoid any miscalculations, use `self.log(..., batch_size=batch_size)`.\n",
      "/rds/general/user/cb1319/home/anaconda3/envs/Geom3D/lib/python3.11/site-packages/lightning/pytorch/utilities/data.py:77: Trying to infer the `batch_size` from an ambiguous collection. The batch size we found is 7716. To avoid any miscalculations, use `self.log(..., batch_size=batch_size)`.\n",
      "/rds/general/user/cb1319/home/anaconda3/envs/Geom3D/lib/python3.11/site-packages/lightning/pytorch/utilities/data.py:77: Trying to infer the `batch_size` from an ambiguous collection. The batch size we found is 7921. To avoid any miscalculations, use `self.log(..., batch_size=batch_size)`.\n",
      "/rds/general/user/cb1319/home/anaconda3/envs/Geom3D/lib/python3.11/site-packages/lightning/pytorch/utilities/data.py:77: Trying to infer the `batch_size` from an ambiguous collection. The batch size we found is 7773. To avoid any miscalculations, use `self.log(..., batch_size=batch_size)`.\n",
      "`Trainer.fit` stopped: `max_epochs=5` reached.\n",
      "wandb: WARNING Source type is set to 'repo' but some required information is missing from the environment. A job will not be created from this run. See https://docs.wandb.ai/guides/launch/create-job\n"
     ]
    },
    {
     "data": {
      "application/vnd.jupyter.widget-view+json": {
       "model_id": "f7a54bee90b24410ba5c04ebabab5add",
       "version_major": 2,
       "version_minor": 0
      },
      "text/plain": [
       "VBox(children=(Label(value='11.820 MB of 11.820 MB uploaded\\r'), FloatProgress(value=1.0, max=1.0)))"
      ]
     },
     "metadata": {},
     "output_type": "display_data"
    },
    {
     "data": {
      "text/html": [
       "<style>\n",
       "    table.wandb td:nth-child(1) { padding: 0 10px; text-align: left ; width: auto;} td:nth-child(2) {text-align: left ; width: 100%}\n",
       "    .wandb-row { display: flex; flex-direction: row; flex-wrap: wrap; justify-content: flex-start; width: 100% }\n",
       "    .wandb-col { display: flex; flex-direction: column; flex-basis: 100%; flex: 1; padding: 10px; }\n",
       "    </style>\n",
       "<div class=\"wandb-row\"><div class=\"wandb-col\"><h3>Run history:</h3><br/><table class=\"wandb\"><tr><td>epoch</td><td>▁▁▁▁▁▁▁▁▃▃▃▃▃▃▃▃▅▅▅▅▅▅▅▅▆▆▆▆▆▆▆▆████████</td></tr><tr><td>train_loss</td><td>██▇▄▃▃▄▅▂▂▂▃▃▃▃▂▄▂▃▃▂▂▃▂▃▂▂▂▂▃▂▂▂▁▃▁▁▂▂▄</td></tr><tr><td>trainer/global_step</td><td>▁▁▁▁▂▂▂▂▂▃▃▃▃▃▃▄▄▄▄▄▅▅▅▅▅▅▆▆▆▆▆▇▇▇▇▇▇███</td></tr><tr><td>val_loss</td><td>█▃▁▂▄</td></tr></table><br/></div><div class=\"wandb-col\"><h3>Run summary:</h3><br/><table class=\"wandb\"><tr><td>epoch</td><td>4</td></tr><tr><td>train_loss</td><td>1.28815</td></tr><tr><td>trainer/global_step</td><td>4999</td></tr><tr><td>val_loss</td><td>1.15422</td></tr></table><br/></div></div>"
      ],
      "text/plain": [
       "<IPython.core.display.HTML object>"
      ]
     },
     "metadata": {},
     "output_type": "display_data"
    },
    {
     "data": {
      "text/html": [
       " View run <strong style=\"color:#cdcd00\">DimeNetPlusPlus_target_1K_TEST_5e4lr</strong> at: <a href='https://wandb.ai/cyprienbone/Geom3D/runs/8mm92vbe' target=\"_blank\">https://wandb.ai/cyprienbone/Geom3D/runs/8mm92vbe</a><br/>Synced 6 W&B file(s), 0 media file(s), 3 artifact file(s) and 0 other file(s)"
      ],
      "text/plain": [
       "<IPython.core.display.HTML object>"
      ]
     },
     "metadata": {},
     "output_type": "display_data"
    },
    {
     "data": {
      "text/html": [
       "Find logs at: <code>./wandb/run-20231128_171133-8mm92vbe/logs</code>"
      ],
      "text/plain": [
       "<IPython.core.display.HTML object>"
      ]
     },
     "metadata": {},
     "output_type": "display_data"
    }
   ],
   "source": [
    "import importlib\n",
    "from geom3d import train_DimeNetPlusPlus\n",
    "\n",
    "importlib.reload(train_DimeNetPlusPlus)\n",
    "train_DimeNetPlusPlus.main(\"/rds/general/user/cb1319/home/GEOM3D/Geom3D/training/DimeNetPlusPlus_target_1K_TEST_5e4lr/\")"
   ]
  },
  {
   "cell_type": "code",
   "execution_count": null,
   "metadata": {},
   "outputs": [],
   "source": [
    "os.getcwd()"
   ]
  },
  {
   "cell_type": "code",
   "execution_count": null,
   "metadata": {},
   "outputs": [],
   "source": [
    "import importlib\n",
    "from geom3d import inference_test\n",
    "\n",
    "config_dir = \"/rds/general/user/cb1319/home/GEOM3D/Geom3D/training/SchNet_target_1K_TEST_5e4lr/\"\n",
    "chkpt_path = \"/rds/general/user/cb1319/home/GEOM3D/Geom3D/training/SchNet_target_1K_TEST_5e4lr/epoch=86-val_loss=0.54-other_metric=0.00.ckpt\"\n",
    "\n",
    "importlib.reload(inference_test)\n",
    "inference_test.plot_training_results(chkpt_path, config_dir)"
   ]
  },
  {
   "cell_type": "code",
   "execution_count": null,
   "metadata": {},
   "outputs": [],
   "source": []
  },
  {
   "cell_type": "code",
   "execution_count": null,
   "metadata": {},
   "outputs": [],
   "source": []
  }
 ],
 "metadata": {
  "kernelspec": {
   "display_name": "Python [conda env:Geom3D]",
   "language": "python",
   "name": "conda-env-Geom3D-py"
  }
 },
 "nbformat": 4,
 "nbformat_minor": 2
}
